Workbook

Sheet 5.000 UTM - 2026
A1: N° | B1: Código | C1: Verif | D1: Nombre | E1: Comuna | F1: Provincia | G1: Ingreso Of. Partes | H1: Monto propuesto M$ | I1: Monto RecomendadoM$ | J1: Etapa | K1: Proceso | L1: Sector | M1: Observaciones | N1: Comité | O1: Oficios cargados a bip | P1: Objetivo del Pladeco | Q1: Lineamiento ERD | R1: Plan del Gobernador | S1: H | T1: M | U1: TOT | V1: Unidad Tecnica | W1: Formulador Proyecto | X1: ORD. Ingreso N° | Y1: Fecha Ord. | Z1: N° Exped. | AA1: Ingreso Of. Partes | AB1: Ingreso Of. Planificación | AC1: Fecha Derivado a Evaluador | AD1: Plazo evaluación | AE1: Derivado Unidad Técnica Evaluadora | AF1: Fecha Derivación | AG1: Ev. DIT | AH1: Reingreso Depto. Planif. | AI1: Fecha Evaluación | AJ1: observaciones Ord. Gore N° | AK1: Fecha Ord. | AL1: Fecha Ficha Evaluación | AM1: Informa | AN1: Ord.Resp. Obs. | AO1: Fecha Ord. | AP1: N° EXP. | AQ1: Ingreso Oficina | AR1: ORD. GORE Observaciones | AS1: Fecha Ord. | AT1: Ord. | AU1: Fecha ORD. | AV1: Fecha Recomendación (Evaluación) | AW1: Estado Proyecto | AX1: Dentro de 15 días | AY1: Iteraciones
A2: 1 | B2: 40076838 | C2: 0 | D2: Construcción Garitas Peatonales Purranque y Corte Alto | E2: Purranque | F2: =+IFERROR(VLOOKUP(E2,'Feriados y Comunas'!$C$1:$D$36,2,FALSE),"") -> OSORNO | G2: 45987 | H2: 222616 | I2: 222616 | J2: Ejecución | K2: 2026 | L2: Multisectorial | M2: Ok - Oficio 035 07-01- 26 | O2: ok | Q2: Se encuentra dentro de la ERD en el: Lineamiento: Bienestar Socio Territorial. Ítem: Espacios y Equipamiento Publico. Objetivo: Construir equipamientos públicos y espacios de carácter cívico en la región. Actividad: No Hay. | R2: Se enlaza con el Programa Regional del Gobernador: - Pilar 3. Inclusión Social y Mejoramiento de la Calidad de Vida. | S2: 6388 | T2: 7565 | U2: =SUM(S2:T2) -> 13953 | V2: Municipalidad Purranque | W2: Municipalidad Purranque | X2: 687 | Y2: 45994 | AA2: 45995 | AB2: 45995 | AC2: 45995 | AD2: =WORKDAY(AC2,15,'Feriados y Comunas'!A$2:A$26) -> 46020 | AE2: D Castro | AJ2: 3260 035 | AK2: 09-12-2025 07-01-2026 | AL2: 04-12-2025 30-12-2025 | AM2: OBSERVADO SIN OBS | AN2: 738 | AO2: 46020 | AQ2: 46021 | AV2: 46021 | AW2: Recomendado | AX2: 4 | AY2: 2
A3: 2 | B3: 40077324 | C3: 0 | D3: Mejoramiento Integral Espacio Público Sector Los Canelos, Hornopiren, Hualaihué. | E3: Hualaihué | F3: =+IFERROR(VLOOKUP(E3,'Feriados y Comunas'!$C$1:$D$36,2,FALSE),"") -> PALENA | G3: 46000 | H3: 328738 | I3: 328738 | J3: Ejecución | K3: 2026 | L3: Multisectorial | M3: Ok - Oficio 037 07-01-26 | O3: ok | Q3: Se encuentra dentro de la ERD en: Lineamiento: Bienestar Socio Territorial. Ítem: Espacios y Equipamiento Publico. Objetivo: Construir nuevas áreas verdes de uso publico como herramienta de esparcimiento e integración barrial en las ciudades de la región. Actividad: Programa regional de construcción y reposición de áreas verdes. | R3: Se enlaza con el Programa Regional del Gobernador en el Pilar: 1. Políticas Públicas en Materia de Seguridad Ciudadana Letra: i) Espacios Seguros: Mejorar la iluminación y la seguridad en parques, plazas y áreas públicas para garantizar espacios seguros para todos los habitantes. | S3: 89 | T3: 81 | U3: =SUM(S3:T3) -> 170 | V3: Municipalidad Hualiahue | W3: Municipalidad Hualiahue | X3: 1585 | Y3: 46000 | AA3: 46000 | AB3: 46000 | AC3: 46000 | AD3: =WORKDAY(AC3,15,'Feriados y Comunas'!A$2:A$26) -> 46022 | AE3: D Castro | AJ3: 3354 037 | AK3: 18-12-2025 07-01-2026 | AL3: 18-12-2025 30-12-2025 | AM3: OBSERVADO SIN OBS | AN3: - | AO3: - | AQ3: - | AV3: 46021 | AW3: Recomendado | AX3: 2 | AY3: 2
A4: 3 | B4: 40041153 | C4: 0 | D4: Mejoramiento Cementerio Municipal, Comuna de Queilen | E4: Queilén | F4: CHILOÉ | G4: 46000 | H4: 325000 | I4: 325000 | J4: Ejecución | K4: 2026 | L4: Multisectorial | M4: Ok - Oficio 251 05-02-26 | O4: ok | Q4: Se encuentra dentro de la ERD en: Lineamiento: Bienestar Socio Territorial. Ítem: Espacios y Equipamiento Publico. Objetivo: Construir nuevas áreas verdes de uso publico como herramienta de esparcimiento e integración barrial en las ciudades de la región. Actividad: Programa regional de construcción y reposición de áreas verdes. | R4: Se enlaza con el Programa Regional del Gobernador en el Pilar: 1. Políticas Públicas en Materia de Seguridad Ciudadana Letra: i) Espacios Seguros: Mejorar la iluminación y la seguridad en parques, plazas y áreas públicas para garantizar espacios seguros para todos los habitantes. | S4: 2798 | T4: 2745 | U4: =SUM(S4:T4) -> 5543 | V4: Municipalidad Queilen | W4: Municipalidad Queilen | X4: 1201 | Y4: 45996 | AA4: 45996 | AB4: 45996 | AC4: 46002 | AD4: =WORKDAY(AC4,15,'Feriados y Comunas'!A$2:A$26) -> 46024 | AE4: D Castro | AJ4: 251 | AK4: 46058 | AL4: 46007 | AM4: SIN OBS | AN4: - | AO4: - | AQ4: - | AV4: 46007 | AW4: Recomendado | AY4: 1
A5: 4 | B5: 40055485 | C5: 0 | D5: Mejoramiento Edificio Centro Atención Integral (CAI) | E5: San Pablo | F5: =+IFERROR(VLOOKUP(E5,'Feriados y Comunas'!$C$1:$D$36,2,FALSE),"") -> OSORNO | G5: 45917 | H5: 300000 | I5: 300000 | J5: Ejecución | K5: 2026 | L5: Salud | M5: ok - Oficio 297 10-02-2026 | N5: 46091 | O5: ok | Q5: Se encuentra dentro de la ERD en el - Lineamiento: Bienestar Socio Territorial. - Ítem: Salud. - Objetivo: Aumentar Cobertura de atención primaria en salud en la comunas de la región. - Actividad: | R5: Se enlaza con el programa del Gobernador Regional en el - Pilar: 3. Inclusión Social y Mejoramiento de la Calidad de Vida. - Letra: e) Acceso a Servicios de Salud: Ampliar y mejorar la red de servicios de salud, especialmente en zonas rurales, garantizando atención médica de calidad para todos. | S5: 5345 | T5: 5364 | U5: =SUM(S5:T5) -> 10709 | V5: Municipalidad San Pablo | W5: Municipalidad San Pablo | X5: 656 | Y5: 45915 | AA5: 45917 | AB5: 45917 | AC5: 45917 | AD5: =WORKDAY(AC5,15,'Feriados y Comunas'!A$2:A$26) -> 45940 | AE5: D Castro | AJ5: 2607 3259 ?? 297 | AK5: 08-10-2025 09-12-2025 ?? 10-02-2026 | AL5: 03-10-2025 27-11-2025 15-01-2025 06-02-2026 | AM5: OBSERVADO OBSERVADO OBSERVADO SIN OBS | AN5: 779 63 41 | AO5: 17-11-2025 31-12-2025 26-01-2026 | AQ5: 18-11-2025 05-01-2026 27-01-2026 | AR5: 2607 3259 ?? 297 | AS5: 08-10-2025 09-12-2025 ?? 10-02-2026 | AV5: 46059 | AW5: Recomendado | AX5: 10 | AY5: =IFERROR(__xludf.DUMMYFUNCTION("IFERROR(COUNTA(SPLIT(AK5, "" "")), 0)"),4.0) -> 4
A6: 5 | B6: 40073440 | C6: 0 | D6: Mejoramiento Acceso Poniente | E6: Futaleufú | F6: =+IFERROR(VLOOKUP(E6,'Feriados y Comunas'!$C$1:$D$36,2,FALSE),"") -> PALENA | G6: 45903 | H6: 230000 | I6: 230000 | J6: Ejecución | K6: 2026 | L6: Seguridad | M6: ok - Oficio 125 19-01-2026 | N6: 46091 | O6: ok | Q6: Se encuentra dentro de los lineamientos de la ERD en - Lineamiento: Conectividad y Movilidad Regional Sustentable. - Ítem: Movilidad Sostenible. - Obj.: Extender y Mejorar las aceras peatonales en localidades urbanas. - Actividad: Plan de inversión en infraestructura vialidad menor. | R6: Se enlaza con el Programa Regional del Gobernador en el - Pilar: 2. Desarrollo Económico Sostenible: una Alianza Público-Privada - Letra: c)Inversiones en Infraestructura: Mejorar la conectividad y la infraestructura regional para atraer inversiones y generar empleo. | S6: 1542 | T6: 1520 | U6: =SUM(S6:T6) -> 3062 | V6: Municipalidad Futaleufu | W6: Municipalidad Futaleufu | X6: 406 | Y6: 45902 | AA6: 45903 | AB6: 45903 | AC6: 45903 | AD6: =WORKDAY(AC6,15,'Feriados y Comunas'!A$2:A$26) -> 45926 | AE6: D Castro | AJ6: 2605 3075 125 | AK6: 08-10-2025 14-11-2025 19-01-2026 | AL6: 29-09-2025 10-11-2025 14-11-2025 | AM6: OBSERVADO OBSERVADO SIN OBS | AN6: 530 ??? | AO6: 29-10-2025 ??? | AQ6: 03-11-2025 ??? | AR6: 2605 3075 | AS6: 08-10-2025 14-11-2025 | AV6: 45975 | AW6: Recomendado | AX6: 19 | AY6: =IFERROR(__xludf.DUMMYFUNCTION("IFERROR(COUNTA(SPLIT(AK6, "" "")), 0)"),3.0) -> 3
A7: 6 | B7: 40071265 | C7: 0 | D7: Reposición Sede Social y Camarines Club Deportivo El Bosque | E7: Dalcahue | F7: CHILOÉ | G7: 46104 | H7: 337129 | I7: 337129 | J7: Ejecución | K7: 2026 | L7: Deportes | M7: ok - Oficio 1127 13-05-2026 | N7: 46178 | O7: ok | Q7: Bienestar socioterritorial: "Construir equipamientos públicos y espacios de carácter cívico en la región", fortaleciendo la infraestructura básica en zonas rurales.Fortalecimiento de la organización social: El proyecto responde a la necesidad de espacios para la "articulación entre organizaciones comunitarias rurales", contribuyendo al fortalecimiento del tejido social. | R7: La propuesta se articula con los siguientes pilares programáticos del programa de gobierno, presentados en el orden jerárquico establecido: 3. Inclusión Social y Calidad de Vida "Programas de Apoyo Social: Desarrollar iniciativas para apoyar a los sectores más vulnerables de nuestra comunidad". (Aplica al proveer infraestructura adecuada a organizaciones rurales que carecen de espacios dignos) . "Infraestructura Comunitaria: Fomentar la construcción y mejoramiento de sedes sociales y recintos comunitarios para fortalecer la vida barrial". 4. Participación Ciudadana y Gobernanza "Participación Ciudadana: Fomentar la participación activa de la comunidad en la toma de decisiones". (El proyecto se sustenta en un diagnóstico participativo con diversas agrupaciones locales, incluyendo el Club Deportivo y Juntas de Vecinos) . | S7: 145 | T7: 140 | U7: 285 | V7: MUNICIPALIDAD DE DALCAHUE | W7: MUNICIPALIDAD DE DALCAHUE | X7: 90 | Y7: 46101 | AA7: 46104 | AB7: 46105 | AC7: 46105 | AD7: =WORKDAY(AC7,15,'Feriados y Comunas'!A$2:A$26) -> 46126 | AE7: Dcastro | AJ7: 901 1127 | AK7: 21-042026 13-05-2026 | AL7: 20-04-2026 11-05-2026 | AM7: OBSERVADO SIN OBS | AN7: 143 | AO7: 46140 | AQ7: 46141 | AV7: 46153 | AW7: Recomendado | AY7: =IFERROR(__xludf.DUMMYFUNCTION("IFERROR(COUNTA(SPLIT(AK7, "" "")), 0)"),2.0) -> 2
A8: 7 | B8: 40073338 | C8: 0 | D8: Reposición Estacion Medico Rural Puchilco | E8: Puqueldón | F8: =+IFERROR(VLOOKUP(E8,'Feriados y Comunas'!$C$1:$D$36,2,FALSE),"") -> CHILOÉ | G8: 45813 | H8: 202086 | I8: 203117 | J8: Ejecución | K8: 2026 | L8: Salud | M8: ok - Oficio 327 17-02-2026 | N8: Pendiente | O8: ok | Q8: Se encuentra dentro de la ERD en el - Lineamiento: Bienestar Socio Territorial. - Ítem: Salud. - Objetivo: Aumentar Cobertura de atención primaria en salud en la comunas de la región. - Actividad: Convenio de Programación. | R8: Se enlaza con el programa del Gobernador Regional en el - Pilar: 3. Inclusión Social y Mejoramiento de la Calidad de Vida. - Letra: e) Acceso a Servicios de Salud: Ampliar y mejorar la red de servicios de salud, especialmente en zonas rurales, garantizando atención médica de calidad para todos. | S8: 184 | T8: 190 | U8: =SUM(S8:T8) -> 374 | V8: Municipalidad Puqueldon | W8: Municipalidad Puqueldon | X8: 397 | Y8: 45811 | AA8: 45813 | AB8: 45813 | AC8: 45813 | AD8: =WORKDAY(AC8,15,'Feriados y Comunas'!A$2:A$26) -> 45835 | AE8: Dcastro | AJ8: 1502 327 725 1606 | AK8: 30-06-2025 17-02-2026 08-04-2026 26-06-2026 | AL8: 13-06-2025 17-02-2026 07-04-2026 26-06-2026 | AM8: OBSERVADO OBSERVADO OBSERVADO SIN OBS | AN8: 68 120 377 | AO8: 10-02-2026 11-03-2026 11-06-2026 | AR8: 1502 | AS8: 45838 | AV8: 46199 | AW8: Recomendado | AX8: 6 | AY8: =IFERROR(__xludf.DUMMYFUNCTION("IFERROR(COUNTA(SPLIT(AK8, "" "")), 0)"),4.0) -> 4
A9: 8 | B9: 40070963 | C9: 0 | D9: Mejoramiento Sistema de Alcantarillado y Aguas Superficiales Pescaderia Feria Yumbel. | E9: Castro | F9: =+IFERROR(VLOOKUP(E9,'Feriados y Comunas'!$C$1:$D$36,2,FALSE),"") -> CHILOÉ | G9: 45922 | H9: 313141 | I9: 326592 | J9: Ejecución | K9: 2026 | L9: Turismo | M9: ok - Oficio 1861 22-07-2026 | N9: 46178 | O9: ok | Q9: La iniciativa es plenamente coherente con el lineamiento de "Bienestar socioterritorial", enfocado en la provisión de servicios públicos de calidad: Infraestructura Pública: Contribuye al objetivo de "Lograr que la comunidad cuente con infraestructura y equipamiento necesario para desenvolverse de buena manera, generando las condiciones para mejorar crecientemente la calidad de vida de los habitantes". | R9: La propuesta se articula con los siguientes pilares programáticos del programa de gobierno: Inclusión Social y Calidad de Vida "Programas de Apoyo Social: Desarrollar iniciativas para apoyar a los sectores más vulnerables de nuestra comunidad". (Aplica al apoyo directo a los locatarios de la feria y mejora de sus condiciones laborales). | S9: 1900 | T9: 2001 | U9: =SUM(S9:T9) -> 3901 | V9: Municipalidad Castro | W9: Municipalidad Castro | X9: 946 | Y9: 45909 | AA9: 45922 | AB9: 45922 | AC9: 45922 | AD9: =WORKDAY(AC9,15,'Feriados y Comunas'!A$2:A$26) -> 45943 | AE9: Dcastro | AJ9: 2822 3258 385 1069 1349 1861 | AK9: 27-10-2025 09-12-2025 02-03-2026 11-05-2026 03-06-2026 22-07-2026 | AL9: 27-10-2025 09-12-2026 02-03-2026 08-05-2026 03-06-2026 21-07-2026 | AM9: OBSERVADO OBSERVADO OBSERVADO OBSERVADO OBSERVADO SIN OBS | AN9: 1231 162 332 543 812 | AO9: 14-11-2025 05-02-2026 17-03-2026 15-05-2026 03-06-2026 | AQ9: 17-11-2025 17-02-2026 15-04-2026 15-05-2026 03-06-2026 | AR9: 2822 3258 385 | AS9: 27-10-2025 09-12-2025 02-03-2026 | AV9: 46224 | AW9: Recomendado | AX9: 23 | AY9: =IFERROR(__xludf.DUMMYFUNCTION("IFERROR(COUNTA(SPLIT(AK9, "" "")), 0)"),6.0) -> 6
A10: 9 | B10: 40075634 | C10: 0 | D10: Mejoramiento Plaza Villa Los Rios | E10: Fresia | F10: =+IFERROR(VLOOKUP(E10,'Feriados y Comunas'!$C$1:$D$36,2,FALSE),"") -> LLANQUIHUE | G10: 45930 | H10: 332400 | I10: 269828 | J10: Ejecución | K10: 2026 | L10: Multisectorial | M10: ok - Oficio 1694 02-07-2026 | N10: Pendiente | O10: ok | Q10: Se encuentra dentro de la ERD en: - Lineamiento: Bienestar Socio Territorial. - Ítem: Espacios y Equipamiento Publico. - Objetivo: Construir nuevas áreas verdes de uso publico como herramienta de esparcimiento e integración barrial en las ciudades de la región. - Actividad: Programa regional de construcción y reposición de áreas verdes. | R10: Se enlaza con el Programa Regional del Gobernador en el - Pilar: 1. Políticas Públicas en Materia de Seguridad Ciudadana - Letra: i) Espacios Seguros: Mejorar la iluminación y la seguridad en parques, plazas y áreas públicas para garantizar espacios seguros para todos los habitantes. | S10: 3830 | T10: 4039 | U10: =SUM(S10:T10) -> 7869 | V10: Municipalidad Fresia | W10: Municipalidad Fresia | X10: 786 | Y10: 45929 | AA10: 45930 | AB10: 45930 | AC10: 45930 | AD10: =WORKDAY(AC10,15,'Feriados y Comunas'!A$2:A$26) -> 45951 | AE10: Dcastro | AJ10: 2827 3076 1251 1694 | AK10: 27-10-2025 14-11-2025 25-05-2026 02-07-2026 | AL10: 23-10-2025 14-11-2025 22-05-2026 01-07-2026 | AM10: OBSERVADO OBSERVADO OBSERVADO SIN OBS | AN10: 888 288 377 | AO10: 6-11-2025 11-05-2026 11-06-2026 | AQ10: 6-11-2025 05-05-2026 16-06-2026 | AR10: 2827 3076 | AS10: 27-10-2025 14-11-2025 | AV10: 46204 | AW10: Recomendado | AX10: 17 | AY10: =IFERROR(__xludf.DUMMYFUNCTION("IFERROR(COUNTA(SPLIT(AK10, "" "")), 0)"),4.0) -> 4
A11: 10 | B11: 40073904 | C11: 0 | D11: Mejoramiento Espacio Público Sargento Candelaria Norte, Chonchi. | E11: Chonchi | F11: =+IFERROR(VLOOKUP(E11,'Feriados y Comunas'!$C$1:$D$36,2,FALSE),"") -> CHILOÉ | G11: 45975 | H11: 336000 | I11: 320000 | J11: Ejecución | K11: 2026 | L11: Multisectorial | M11: ok - Oficio 1911 22-07-2026 | N11: Pendiente | O11: ok | Q11: Se encuentra dentro de la ERD en: - Lineamiento: Bienestar Socio Territorial. - Ítem: Espacios y Equipamiento Publico. - Objetivo: Construir nuevas áreas verdes de uso publico como herramienta de esparcimiento e integración barrial en las ciudades de la región. - Actividad: Programa regional de construcción y reposición de áreas verdes. | R11: Se enlaza con el Programa Regional del Gobernador en el - Pilar: 1. Políticas Públicas en Materia de Seguridad Ciudadana - Letra: i) Espacios Seguros: Mejorar la iluminación y la seguridad en parques, plazas y áreas públicas para garantizar espacios seguros para todos los habitantes. | S11: 2865 | T11: 2854 | U11: =SUM(S11:T11) -> 5719 | V11: Municipalidad Chonchi | W11: Municipalidad Chonchi | X11: 1018 | Y11: 45975 | AC11: 45975 | AD11: =WORKDAY(AC11,15,'Feriados y Comunas'!A$2:A$26) -> 45996 | AE11: Dcastro | AJ11: 3355 1103 1491 1911 | AK11: 18-12-2025 12-05-2026 17-06-2026 22-07-2026 | AL11: 18-12-2025 11-05-2026 16-06-2026 21-07-2026 | AM11: OBSERVADO OBSERVADO OBSERVADO SIN OBS | AN11: 348 475 559 | AO11: 04-05-2026 12-06-2026 09-07-2026 | AQ11: 04-05-2026 15-06-2026 09-07-2026 | AR11: 3355 | AS11: 46009 | AV11: 46224 | AW11: Recomendado | AX11: 20 | AY11: =IFERROR(__xludf.DUMMYFUNCTION("IFERROR(COUNTA(SPLIT(AK11, "" "")), 0)"),4.0) -> 4
A12: 11 | B12: 40078509 | C12: 0 | D12: CONSTRUCCION INFRAESTRUCTURA RECREATIVA Y AREA VERDE SECTOR PILMAIQUEN, COMUNA DE PUYEHUE | E12: Puyehue | F12: =+IFERROR(VLOOKUP(E12,'Feriados y Comunas'!$C$1:$D$36,2,FALSE),"") -> OSORNO | G12: 46231 | H12: 163832 | I12: 193063 | J12: Ejecución | K12: 2026 | L12: Vivienda | M12: ok - Oficio 2613 01-09-2026 | N12: Pendiente | O12: ok | S12: 330 | T12: 340 | U12: 670 | V12: MUNICIPALIDAD DE PUYEHUE | W12: MUNICIPALIDAD DE PUYEHUE | X12: 880 | Y12: 46230 | AA12: 46231 | AB12: 46231 | AC12: 46231 | AD12: =WORKDAY(AC12,15,'Feriados y Comunas'!A$2:A$26) -> 46252 | AE12: HSolervicens DCastro HSolervicens DCastro Dcastro Dcastro | AJ12: 1996 2152 2291 2375 2485 2613 | AK12: 29-07-2026 05-08-2026 17-08-2026 19-08-2026 24-08-2026 01-09-2026 | AL12: 29-07-2026 05-08-2026 17-08-2026 19-08-2026 24-08-2026 28-08-2026 | AM12: OBSERVADO OBSERVADO OBSERVADO OBSERVADO OBSERVADO SIN OBS | AN12: 915 939 963 979 1000 | AO12: 4-08-2026 11-08-2026 18-08-2026 19-08-2026 25-08-2026 | AQ12: 5-08-2026 11-08-2026 18-08-2026 19-08-2026 26-08-2026 | AV12: 46262 | AW12: Recomendado | AY12: =IFERROR(__xludf.DUMMYFUNCTION("IFERROR(COUNTA(SPLIT(AK12, "" "")), 0)"),6.0) -> 6
A13: 12 | B13: 40073550 | C13: 0 | D13: Construcción Centro Comunitario el Jardin | E13: Fresia | F13: =+IFERROR(VLOOKUP(E13,'Feriados y Comunas'!$C$1:$D$36,2,FALSE),"") -> LLANQUIHUE | G13: 45923 | H13: 213266 | J13: Ejecución | K13: 2026 | L13: Multisectorial | M13: POSTULADO A FRIL. SE BAJA INICIATIVA EN MENOR A 5000 UTM 1. Revisar costo por metro cuadrado superior al promedio regional. 2. Ajustar Ppto. con Ficha IDI. 3. Anexar Certificación Secplan – DOM. 4. Incorporar Carta de No fraccionamiento Visada por Dpto. Jurídico. 5. Desarrollar análisis de alternativas. 6. Adjuntar documentación al BIP. GENERALES 1. Incorporar pronunciamiento, aprobación o visación de la Dirección de Vialidad del MOP. 2. Carta del alcalde de no fraccionamiento. PLANOS E INGENERÍA 1. Los planos de estructura deben incorporar la firma del profesional responsable, indicando nombre y profesión como mínimo. 2. Memoria de agua potable y aguas servidas deben incorporar firma a mano alzada o digital. ANEXOS 1. Incorporar lo señalado en 5.8. b) Ficha IDI 2. Incorporar lo señalado en 5.8. m) Certificado Compromiso de Absorción de Costos de operación y mantención. - Certificado de factibilidad eléctrica adjunto perdió validez. El plazo es muy acotado. TERRENO Y OTROS 1. Se solicita incorporar Resolución de Destinación o Contrato de Comodato vigente emitido por Bienes Nacionales. Certificado adjunto menciona que proyecto será presentado al fondo regional de iniciativa local. Corregir. | N13: 45953 | Q13: Se encuentra dentro de la ERD en el: Lineamiento: Bienestar Socio Territorial. Ítem: Espacios y Equipamiento Publico. Objetivo: Construir equipamientos públicos y espacios de carácter cívico en la región. Actividad: No Hay. | R13: Se enlaza con el Programa Regional del Gobernador: Pilar 3. Inclusión Social y Mejoramiento de la Calidad de Vida. Letra c) Programas de Apoyo Social: Desarrollar iniciativas para apoyar a los sectores más vulnerables de nuestra comunidad. | S13: 128 | T13: 110 | U13: =SUM(S13:T13) -> 238 | V13: Municipalidad Fresia | W13: Municipalidad Fresia | X13: 756 | Y13: 45915 | AA13: 45923 | AB13: 45923 | AC13: 45923 | AD13: =WORKDAY(AC13,15,'Feriados y Comunas'!A$2:A$26) -> 45944 | AE13: Dcastro | AJ13: 2828 3257 | AK13: 27-10-2025 09-12-2025 | AL13: 23/10/2025 09-12-2025 | AM13: OBSERVADO OBSERVADO | AN13: 899 | AO13: 45972 | AQ13: 45972 | AR13: 2828 | AS13: 45957 | AW13: Dado de baja | AX13: 22 | AY13: =IFERROR(__xludf.DUMMYFUNCTION("IFERROR(COUNTA(SPLIT(AK13, "" "")), 0)"),2.0) -> 2
A14: 13 | B14: 40073716 | C14: 0 | D14: Mejoramiento Multicanchas ST Michelle Bachelet | E14: Puerto Varas | F14: =+IFERROR(VLOOKUP(E14,'Feriados y Comunas'!$C$1:$D$36,2,FALSE),"") -> LLANQUIHUE | G14: 45960 | H14: 140909 | J14: Ejecución | K14: 2026 | L14: Deportes | M14: POSTULADO A FRIL. SE BAJA INICIATIVA EN MENOR A 5000 UTM 1. A nivel de alternativas describir con mayor detalle la intervención de la infraestructura. 2. Adjuntar Certificado de Informes previos. 3. Anexas Informe Técnico situación actual por profesional del área. 4. Incorporar factibilidad. 5. Adjuntar carta de no fraccionamiento firmado por el alcalde y visado por depto. jurídico. 6. Anexar Certificado de BNUP. 7. Incorporar KMZ. 8. Adjuntar documentación al BIP. GENERALES 1. Incluir carta de no fraccionamiento firmada por alcalde. ESTUDIO PREINVERSIONAL 2. Documento debe estar firmado por unidad formuladora y en formato PDF. TTR y,o EETT 3. Partida 2.5.3. señalada en EETT no se encuentra incluida en Carta Gantt PLANOS E INGENERÍA 4. Para el correcto y adecuado desarrollo de las actividades deportivas, el diseño de la multicancha deberá estar acorde a las disposiciones del Instituto Nacional de Deporte (IND), en cuanto a las dimensiones y requerimientos de las disciplinas consideradas en el proyecto. El diseño actual no cumple con las dimensiones mínimas. Se recomienda revisar “Manual de construcción y requisitos mínimos para parques, plazas, áreas verdes y áreas deportivas, MINVU, 2017”- 5. EL muro de escalada sobre la estructura de cierro de la multicancha debe ser estructuralmente validado. ANEXOS 6. Adjuntar b) Ficha IDI 7. Adjuntar h) Factibilidad eléctrica. | N14: 45975 | Q14: La iniciativa se orienta dentro de la ERD en el: - Lineamiento: Bienestar Socio Territorial. - Ítem: Espacios y Equipamiento Público - Objetivo: Aumentar el Nro. De espacios polideportivos en la región con criterios de genero e inclusividad. - Actividad: No hay. | R14: Se enlaza con el Programa Regional del Gobernador: - Pilar: 3. Inclusión Social y Mejoramiento de la Calidad de Vida. - Letra: c) Programas de Apoyo Social: Desarrollar iniciativas para apoyar a los sectores más vulnerables de nuestra comunidad. | S14: 1059 | T14: 1159 | U14: =SUM(S14:T14) -> 2218 | V14: Municipalidad Puerto Varas | W14: Municipalidad Puerto Varas | X14: 72 | Y14: 45960 | AA14: 45964 | AB14: 45964 | AC14: 45964 | AD14: =WORKDAY(AC14,15,'Feriados y Comunas'!A$2:A$26) -> 45985 | AE14: Dcastro | AJ14: 3077 | AL14: 45975 | AM14: OBSERVADO | AR14: 3077 | AS14: 45975 | AW14: Dado de baja | AX14: 10 | AY14: =IFERROR(__xludf.DUMMYFUNCTION("IFERROR(COUNTA(SPLIT(AK14, "" "")), 0)"),1.0) -> 1
A15: 14 | B15: 40066308 | C15: 0 | D15: Construcción Centro Comunitario ST Pureo | E15: Queilén | F15: =+IFERROR(VLOOKUP(E15,'Feriados y Comunas'!$C$1:$D$36,2,FALSE),"") -> CHILOÉ | G15: 45749 | H15: 212093 | J15: Ejecución | K15: 2026 | L15: Multisectorial | M15: 1. Ajustar la Demanda. 2. Incorporar estratificación social. 3. Anexar Ppto. AITO. 4. Adjuntar Mecánica de Suelos. 5. Incorporar Revisores independiente. 6. Anexar Modelo de Gestión. 7. Adjuntar documentación al BIP. 1. De acuerdo a lo solicitado por Departamento jurídico del Gobierno Regional, deberá presentar certificado de alcalde y validado por su Departamento jurídico que señale lo siguiente: “El proyecto no considera restricciones técnicas, legales ni administrativas para su posterior ejecución. Por otra parte, se declara que el proyecto en cuestión no corresponde al fraccionamiento de una iniciativa de mayor envergadura”. 2. Los procesos son anuales, por lo tanto, deberá actualizar información del perfil al presente año 2025. 3. Revisar el Perfil del proyecto no cuadra el presupuesto ingresado con el presentado. 4. Revisar punto 5.8 letra d) Informe Técnico de Emplazamiento: 5. Sin Archivo de georreferenciación. 6. Las Especificaciones Técnicas, incluye placa modelo FRIL, Letrero Modelo FRIL, el financiamiento aplica al FRIL. 7. Presupuesto: El presentado no cuadra con el perfil, recordar Tanto el Presupuesto como la Carta Gantt deben tener los mismos elementos que las EETT. 8. Respecto a Planimetría, debe revisar instructivo y considerar lo faltante. 9. Se presenta un certificado de declaración jurada de la propiedad el que corresponde al FRIL. 10. Respecto a certificaciones, en general debe considerar que estas deben contener: fecha, nombre del proyecto y código BIP, así también debe considerar lo siguiente: Revisar instructivo y presentar Certificado del DOM, tal como se solicita. Falta permiso de edificación, revisar instructivo. 11. Informe de Revisores Independientes de Arquitectura e Ingeniería. 12. Falta Plan de Mitigación durante la ejecución de las Obras. 13. Falta Carta Gantt del proyecto. 14. Falta Actualizar factibilidades. | N15: 45806 | Q15: Se encuentra dentro de la ERD en el: Lineamiento: Bienestar Socio Territorial. Ítem: Espacios y Equipamiento Publico. Objetivo: Construir equipamientos públicos y espacios de carácter cívico en la región. Actividad: No Hay. | R15: Se enlaza con el Programa Regional del Gobernador: - Pilar 3. Inclusión Social y Mejoramiento de la Calidad de Vida. - Letra c) Programas de Apoyo Social: Desarrollar iniciativas para apoyar a los sectores más vulnerables de nuestra comunidad. | S15: 175 | T15: 186 | U15: =SUM(S15:T15) -> 361 | V15: Municipalidad Queilen | W15: Municipalidad Queilen | X15: 207 | Y15: 45749 | AC15: 45750 | AD15: =WORKDAY(AC15,15,'Feriados y Comunas'!A$2:A$26) -> 45772 | AE15: D Castro | AJ15: 1165 | AK15: 45811 | AL15: 45806 | AM15: OBSERVADO | AR15: 1165 | AS15: 45811 | AW15: Observado | AX15: 37 | AY15: =IFERROR(__xludf.DUMMYFUNCTION("IFERROR(COUNTA(SPLIT(AK15, "" "")), 0)"),1.0) -> 1
A16: 15 | B16: 40066350 | C16: 0 | D16: Construcción Centro Comunitario Cheuquemo | E16: Río Negro | F16: =+IFERROR(VLOOKUP(E16,'Feriados y Comunas'!$C$1:$D$36,2,FALSE),"") -> OSORNO | G16: 45853 | H16: 164000 | J16: Ejecución | K16: 2026 | L16: Multisectorial | M16: 1. Actualizar certificados de la postulación FRIL 2. Incorporar anexos de acuerdo a instructivo. 3. Anexar Carta del alcalde de no fraccionamiento. 4. Adjuntar documentación al BIP. | N16: 18-07-25. | Q16: Se encuentra dentro de la ERD en el: Lineamiento: Bienestar Socio Territorial. Ítem: Espacios y Equipamiento Publico. Objetivo: Construir equipamientos públicos y espacios de carácter cívico en la región. Actividad: No Hay. | R16: Se enlaza con el Programa Regional del Gobernador: - Pilar 3. Inclusión Social y Mejoramiento de la Calidad de Vida. - Letra c) Programas de Apoyo Social: Desarrollar iniciativas para apoyar a los sectores más vulnerables de nuestra comunidad. | S16: 68 | T16: 80 | U16: =SUM(S16:T16) -> 148 | V16: Municipalidad Rio Negro | W16: Municipalidad Rio Negro | X16: 50 | Y16: 45852 | AA16: 45853 | AB16: 45853 | AC16: 45853 | AD16: =WORKDAY(AC16,15,'Feriados y Comunas'!A$2:A$26) -> 45875 | AJ16: 1669 | AK16: 45860 | AL16: 45856 | AM16: OBSERVADO | AR16: 1669 | AS16: 45860 | AW16: Observado | AX16: 2 | AY16: =IFERROR(__xludf.DUMMYFUNCTION("IFERROR(COUNTA(SPLIT(AK16, "" "")), 0)"),1.0) -> 1
A17: 16 | B17: 40066406 | C17: 0 | D17: Construcción Centro Comunitario Chan Chan | E17: Río Negro | F17: =+IFERROR(VLOOKUP(E17,'Feriados y Comunas'!$C$1:$D$36,2,FALSE),"") -> OSORNO | G17: 45853 | H17: 159000 | J17: Ejecución | K17: 2026 | L17: Multisectorial | M17: 1. Actualizar certificados de la postulación FRIL 2. Incorporar anexos de acuerdo a instructivo. 3. Anexar Carta del alcalde de no fraccionamiento. 4. Adjuntar documentación al BIP. | N17: 45856 | Q17: Se encuentra dentro de la ERD en el: Lineamiento: Bienestar Socio Territorial. Ítem: Espacios y Equipamiento Publico. Objetivo: Construir equipamientos públicos y espacios de carácter cívico en la región. Actividad: No Hay. | R17: Se enlaza con el Programa Regional del Gobernador: - Pilar 3. Inclusión Social y Mejoramiento de la Calidad de Vida. - Letra c) Programas de Apoyo Social: Desarrollar iniciativas para apoyar a los sectores más vulnerables de nuestra comunidad. | S17: 197 | T17: 204 | U17: =SUM(S17:T17) -> 401 | V17: Municipalidad Rio Negro | W17: Municipalidad Rio Negro | X17: 51 | Y17: 45853 | AA17: 45853 | AB17: 45853 | AC17: 45853 | AD17: =WORKDAY(AC17,15,'Feriados y Comunas'!A$2:A$26) -> 45875 | AJ17: 1670 | AK17: 45860 | AL17: 45856 | AM17: OBSERVADO | AR17: 1670 | AS17: 45860 | AW17: Observado | AX17: 2 | AY17: =IFERROR(__xludf.DUMMYFUNCTION("IFERROR(COUNTA(SPLIT(AK17, "" "")), 0)"),1.0) -> 1
A18: 17 | B18: 40074807 | C18: 0 | D18: Reposición Centro Comunitario Pob. Flor Naciente N°1 ST Changue | E18: Maullín | F18: =+IFERROR(VLOOKUP(E18,'Feriados y Comunas'!$C$1:$D$36,2,FALSE),"") -> LLANQUIHUE | G18: 45873 | H18: 160000 | J18: Ejecución | K18: 2026 | L18: Vivienda | M18: 1. Crear Ficha 2026. 2. Adjuntar Planta Emplazamiento. 3. Anexar Participación Ciudadana. 4. Incorporar Permiso de edificación. 5. Adjuntar Memoria. 6. Anexar Mecánica. 7. Incorporar Revisores independientes. 8. Adjuntar Cronograma. 9. Anexar Plan de Mitigación. 10. Incorporar Modelo de Gestión. 11. Adjuntar Informe Técnico Estado Actual. 12. Anexar IMIV si corresponde. 13. Incorporar Dominio Vigente. 14. Adjuntar Hipotecas y Gravámenes. 15. Anexar Informes Previos. 16. Incorporar Factibilidades. 17. Adjuntar Costos Operacionales. 18. Anexar Carta del alcalde de no fraccionamiento. 19. Incorporar análisis de alternativas y descripción detallada de la solución. 20. Los antecedentes no son suficientes para realizar análisis técnico. 21. Adjuntar documentación al BIP. | N18: 45877 | Q18: Se encuentra dentro de la ERD en el: Lineamiento: Bienestar Socio Territorial. Ítem: Espacios y Equipamiento Publico. Objetivo: Construir equipamientos públicos y espacios de carácter cívico en la región. Actividad: No Hay. | R18: Se enlaza con el Programa Regional del Gobernador: - Pilar 3. Inclusión Social y Mejoramiento de la Calidad de Vida. - Letra c) Programas de Apoyo Social: Desarrollar iniciativas para apoyar a los sectores más vulnerables de nuestra comunidad. | V18: Municipalidad Maullín | W18: Municipalidad Maullín | X18: 691 | Y18: 45869 | AA18: 45873 | AB18: 45873 | AC18: 45873 | AD18: =WORKDAY(AC18,15,'Feriados y Comunas'!A$2:A$26) -> 45895 | AJ18: 1968 | AK18: 45881 | AL18: 45877 | AM18: OBSERVADO | AR18: 1968 | AS18: 45881 | AW18: Observado | AX18: 4 | AY18: =IFERROR(__xludf.DUMMYFUNCTION("IFERROR(COUNTA(SPLIT(AK18, "" "")), 0)"),1.0) -> 1
A19: 18 | B19: 40073344 | C19: 0 | D19: Construcción Calle Fuente Bellavista | E19: Ancud | F19: =+IFERROR(VLOOKUP(E19,'Feriados y Comunas'!$C$1:$D$36,2,FALSE),"") -> CHILOÉ | G19: 45876 | H19: 215349 | J19: Ejecución | K19: 2026 | L19: Vivienda | M19: 1. Adjuntar Carta de no fraccionamiento alcalde. 2. Incorporar Certificado de Conexiones domiciliarias. 3. Adjuntar documentación al BIP. 1. Debe retirar del proyecto todo lo relacionado a fuente de financiamiento que no corresponde. Recordar que el financiamiento es FNDR del Gobierno Regional. 2. Al finalizar correcciones debe corregir la ficha IDI (actualmente tiene errores). Corregir beneficiarios directos que no coinciden con el perfil o la institución técnica, que debe ser el municipio.3. Respecto al perfil del proyecto, Identificar gráficamente (confinar con polígono) el Barrio Caicumeo, dentro de este polígono identificar la calle con pavimento de ripio a mejorar, así como también debe graficar todas las otras calles que cuentan con pavimento granular o ripio. 4. Respecto a certificaciones: a) Certificado de emplazamiento en bien de uso público, le falta el BIP b) Ver instructivo 2025 y presentar ANEXO 1 (para casos donde no hay permiso de edificación) c) Compromiso de absorción de costos de operación y mantención, le falta el BIP d) Respecto a participación ciudadana, revisar instructivo y presentar anexos propuestos, según corresponda e) Ver instructivo y presentar copia de certificado de título de los profesionales patrocinantes, responsables ante la ley que subscriben el proyecto. f) Presentar certificado firmada por alcalde más asesor jurídico, garantizando que no existen restricciones técnicas, legales ni administrativas para su posterior ejecución, y declarando que el proyecto en cuestión no corresponde al fraccionamiento de una iniciativa de mayor envergadura. (Es requerimiento del Departamento jurídico del Gobierno Regional) | N19: 45898 | Q19: Se encuentra dentro de la ERD en el: Lineamiento: Conectividad y Movilidad Regional Sustentable. Ítem: Movilidad Sostenible. Objetivo: Extender y Mejorar las aceras peatonales en localidades urbanas. Actividad: Plan de Mejoramiento de aceras de ata estándar con criterios de accesibilidad universal en ciudades intermedias de la región. | R19: Se enlaza con el Programa Regional del Gobernador: Pilar 1. Políticas Públicas en Materia de Seguridad Ciudadana. Letra i) Espacios Seguros: Mejorar la iluminación y la seguridad en parques, plazas y áreas públicas para garantizar espacios seguros para todos los habitantes. | S19: 288 | T19: 312 | U19: =SUM(S19:T19) -> 600 | V19: Municipalidad Ancud | W19: Municipalidad Ancud | X19: 1079 | Y19: 45874 | AA19: 45876 | AB19: 45876 | AC19: 45876 | AD19: =WORKDAY(AC19,15,'Feriados y Comunas'!A$2:A$26) -> 45898 | AJ19: 2276 | AK19: 45902 | AL19: 45898 | AM19: OBSERVADO | AR19: 2276 | AS19: 45902 | AW19: Observado | AX19: 15 | AY19: =IFERROR(__xludf.DUMMYFUNCTION("IFERROR(COUNTA(SPLIT(AK19, "" "")), 0)"),1.0) -> 1
A20: 19 | B20: 40070936 | C20: 0 | D20: Mejoramiento Escuela Rural San Javier | E20: Curaco de Vélez | F20: =+IFERROR(VLOOKUP(E20,'Feriados y Comunas'!$C$1:$D$36,2,FALSE),"") -> CHILOÉ | G20: 45883 | H20: 326436 | J20: Ejecución | K20: 2026 | L20: Educación | M20: 1. Adjuntar Carta de no fraccionamiento alcalde. 2. Certificado de Hipotecas y Gravámenes. 3. Se sugiere analizar Ppto. Hasta M$300. 4. Aclarar administración del establecimiento. 5. Adjuntar documentación al BIP.GENERALES 1. Aprobación de Dirección de Vialidad. 2. Estacionamiento universal debe incorporar acceso. 3. Oficio o certificado de “Visación Técnica del MINEDUC” o “Conformidad de Intervención” emitido por la SEREMI de Educación. 4. Adjuntar carta de no fraccionamiento. TTR y,o EETT 1. Hay partidas que son señaladas en el índice y no aparecen en el documento (desde página 64 a la 69). Incorporar partidas faltantes. Incorporar imagen esquemática de placa recordatoria. 2. Página 12 repetida. 3. Valor de presupuesto no es el mismo que el señalado en imagen del letrero de obras. PLANOS E INGENERÍA 1. En firmas de planos de arquitectura, figuran dos directores de SECPLAN. 2. Pl-A.01.2.12v1: Diseño estructural de la rampa no corresponde. Se señala capa vegetal de 0,30m como componente de la estructura del pavimento. Además, esta partida no se encuentra en EETT ni presupuesto. ANEXOS 1. Respecto al a 5.8. Antecedentes, j) Propiedad del terreno: Según el Certificado de Hipotecas y Gravámenes, el terreno donde se emplaza laEscuela Rural presenta una prohibición inscrita a fojas 212 a favor del Instituto Nacional de Deportes de Chile. Se solicita al municipio acreditar la naturaleza de dicha prohibición y, en caso de corresponder, adjuntar autorización expresa del IND que permita la ejecución del proyecto en el inmueble, a fin de verificar la disponibilidad jurídica del terreno. 2. Incorporar firma arquitecto en Carta Gantt. | N20: 45898 | Q20: Se encuentra dentro de la ERD en, - Lineamiento: Bienestar Socio Territorial. - Ítem: Educación. - Objetivo: Mejorar el desempeño de los establecimientos educacionales públicos y subvencionados de la Región . - Actividad: No hay. | R20: Se enlaza con el Programa Regional del Gobernador en el lineamiento - Pilar: 3. Inclusión Social y Mejoramiento de la Calidad de Vida. -Letra: i) Infraestructura Educativa: Renovar y construir nuevas instalaciones educativas para garantizar ambientes de aprendizaje adecuados. | S20: 20 | T20: 28 | U20: =SUM(S20:T20) -> 48 | V20: Municipalidad Curaco de Velez | W20: Municipalidad Curaco de Velez | X20: 329 | Y20: 45859 | AA20: 45883 | AB20: 45883 | AC20: 45883 | AD20: =WORKDAY(AC20,15,'Feriados y Comunas'!A$2:A$26) -> 45905 | AE20: Dcastro | AJ20: 2271 | AK20: 45902 | AL20: 45898 | AM20: OBSERVADO | AR20: 2271 | AS20: 45902 | AW20: Observado | AX20: 12 | AY20: =IFERROR(__xludf.DUMMYFUNCTION("IFERROR(COUNTA(SPLIT(AK20, "" "")), 0)"),1.0) -> 1
A21: 20 | B21: 40071284 | C21: 0 | D21: Mejoramiento Patinodromo, Parque Los Molinos | E21: Curaco de Vélez | F21: =+IFERROR(VLOOKUP(E21,'Feriados y Comunas'!$C$1:$D$36,2,FALSE),"") -> CHILOÉ | G21: 45901 | H21: 323060 | J21: Ejecución | K21: 2026 | L21: Deportes | M21: 1. Se sugiere postular proyecto integral de Mejoramiento Parque Los Molinos al FNDR tradicional. 2. Iniciativa actual corresponde a un fraccionamiento más cuando existe un FRIL asociado al mismo Rol. 3. Adjuntar documentación al BIP. | N21: 45926 | Q21: La iniciativa se orienta dentro de la ERD en el: - Lineamiento: Bienestar Socio Territorial. - Ítem: Espacios y Equipamiento Público - Objetivo: Aumentar el Nro. De espacios polideportivos en la región con criterios de genero e inclusividad. - Actividad: No hay. | R21: Se enlaza con el Programa Regional del Gobernador: - Pilar: 3. Inclusión Social y Mejoramiento de la Calidad de Vida. - Letra: c) Programas de Apoyo Social: Desarrollar iniciativas para apoyar a los sectores más vulnerables de nuestra comunidad. | S21: 180 | T21: 220 | U21: =SUM(S21:T21) -> 400 | V21: Municipalidad Curaco de Velez | W21: Municipalidad Curaco de Velez | X21: 328 | Y21: 45859 | AA21: 45901 | AB21: 45901 | AC21: 45901 | AD21: =WORKDAY(AC21,15,'Feriados y Comunas'!A$2:A$26) -> 45924 | AE21: Dcastro | AJ21: 2519 | AK21: 45930 | AL21: 45926 | AM21: OBSERVADO | AR21: 2519 | AS21: 45930 | AW21: Observado | AX21: 17 | AY21: =IFERROR(__xludf.DUMMYFUNCTION("IFERROR(COUNTA(SPLIT(AK21, "" "")), 0)"),1.0) -> 1
A22: 21 | B22: 40072776 | C22: 0 | D22: Conservación Veredas ST Almirante Latorre | E22: Calbuco | F22: =+IFERROR(VLOOKUP(E22,'Feriados y Comunas'!$C$1:$D$36,2,FALSE),"") -> LLANQUIHUE | G22: 45901 | H22: 303000 | J22: Ejecución | K22: 2026 | L22: seguridad | M22: GENERALES 1. Se debe adjuntar minuta de respuesta a observaciones respecto de la evaluación anterior (23-09-2025). Al responder nuevas observaciones, se debe incluir minuta de respuestas. 2. Se recomienda revisar accesibilidad universal, puesto que: a) Radios de giro inferior a normativa en múltiples lugares. b) No se cumple el ancho mínimo de ruta en múltiples lugares. 3. Discordancia en valor total del proyecto entre valor señalado en BIP, Presupuesto y Ficha IDI. 4. Respecto al estudio de mecánica de suelos: Se señala en el ítem 1.2 Alcances del mismo, que no aplica para el presente proyecto. 5. Respecto a archivos cargados en el BIP: Eliminar archivos que no son definitivos o están disgregados, respecto a presupuesto y EETT. Se debe adjuntar solo un archivo de presupuesto y un archivo de EETT. 6. Se recomienda que el proyecto sea abordado con una perspectiva de desarrollo urbano más integral y estratégica. Actualmente, la iniciativa se limita a la conservación de veredas; sin embargo, considerando la relevancia de la vía, que cumple una función troncal en la distribución de los flujos vehiculares y peatonales de la comuna, y la disponibilidad de un ancho de 5 metros entre línea oficial y solera en ambos costados de la calzada, resultaría pertinente proyectar una intervención más integral del espacio urbano. Asimismo, al continuar el desarrollo de esta iniciativa bajo el presente mecanismo de financiamiento, se deben tener en cuenta las restricciones establecidas en el Instructivo 5.000 UTM respecto de la postulación de futuros proyectos complementarios o asociados que interactúen directa o indirectamente con el actual proyecto. PLANOS E INGENERÍA 1. Se debe cumplir con lo señalado en OGUC en Artículo 2.2.8. punto 1., en los lugares donde sea necesario. Por ejemplo, sobre el muro de contención. ANEXOS 1. Certificado DOM BNUP debe señalar el tipo de vía según Art. 2.3.2. OGUC. 2. Incluir memoria de accesibilidad. 3. Incluir plan de mitigación. | N22: 45933 | Q22: Se encuentra dentro de los lineamientos de la ERD en - Lineamiento: Conectividad y Movilidad Regional Sustentable. - Ítem: Movilidad Sostenible. - Obj.: Extender y Mejorar las aceras peatonales en localidades urbanas. - Actividad: Plan de Mejoramiento de aceras de alto estándar con criterios de accesibilidad universal en ciudades intermedias de la región. | R22: Se enlaza con el Programa Regional del Gobernador: - Pilar: 1. Políticas Públicas en Materia de Seguridad Ciudadana. - Letra: i) Espacios Seguros: Mejorar la iluminación y la seguridad en parques, plazas y áreas públicas para garantizar espacios seguros para todos los habitantes. | S22: 1537 | T22: 1742 | U22: =SUM(S22:T22) -> 3279 | V22: Municipalidad Calbuco | W22: Municipalidad Calbuco | X22: 562 | Y22: 45897 | AA22: 45901 | AB22: 45901 | AC22: 45901 | AD22: =WORKDAY(AC22,15,'Feriados y Comunas'!A$2:A$26) -> 45924 | AE22: Dcastro | AJ22: 2408 2896 | AK22: 23-09-2025 03-11-2025 | AL22: 23-09-2025 30-10-2025 | AM22: OBSERVADO OBSERVADO | AN22: 764 | AO22: 45930 | AQ22: 45932 | AR22: 2408 2896 | AS22: 23-09-2025 03-11-2025 | AW22: Observado | AX22: 17 | AY22: =IFERROR(__xludf.DUMMYFUNCTION("IFERROR(COUNTA(SPLIT(AK22, "" "")), 0)"),2.0) -> 2
A23: 22 | B23: 40072916 | C23: 0 | D23: Mejoramiento Calles Padre Nicanor y Sor Teresa | E23: Puerto Varas | F23: =+IFERROR(VLOOKUP(E23,'Feriados y Comunas'!$C$1:$D$36,2,FALSE),"") -> LLANQUIHUE | G23: 45903 | H23: 201000 | J23: Ejecución | K23: 2026 | L23: Multisectorial | M23: Generales 1. Mecánica de suelos adjunta está incompleta. Debe incorporar memoria del informe. Informe de laboratorio adjunto no señala ensayo de infiltración necesario para la solución de aguas drenaje. 2. Memoria de cálculo debe señalar de donde se obtienen los valores asumidos para el diseño del drenaje. | N23: 45975 | Q23: Se encuentra dentro de los lineamientos de la ERD en - Lineamiento: Conectividad y Movilidad Regional Sustentable. - Ítem: Movilidad Sostenible. - Obj.: Extender y Mejorar las aceras peatonales en localidades urbanas. - Actividad: Plan de inversión en infraestructura vialidad menor. | R23: Se enlaza con el Programa Regional del Gobernador en el - Pilar: 2. Desarrollo Económico Sostenible: una Alianza Público-Privada - Letra: c)Inversiones en Infraestructura: Mejorar la conectividad y la infraestructura regional para atraer inversiones y generar empleo. | S23: 254 | T23: 332 | U23: =SUM(S23:T23) -> 586 | V23: Municipalidad Puerto Varas | X23: 1144 | Y23: 45898 | AA23: 45903 | AB23: 45903 | AC23: 45903 | AD23: =WORKDAY(AC23,15,'Feriados y Comunas'!A$2:A$26) -> 45926 | AE23: Dcastro | AJ23: 2518 2907 3086 | AK23: 30-09-2025 03-11-2025 14-11-2025 | AL23: 26-09-2025 30-11-2025 14-11-2025 | AM23: OBSERVADO OBSERVADO OBSERVADO | AN23: 65 | AO23: 45953 | AQ23: 45953 | AR23: 2518 2907 3086 | AS23: 30-09-2025 03-11-2025 14-11-2025 | AW23: Observado | AX23: 15 | AY23: =IFERROR(__xludf.DUMMYFUNCTION("IFERROR(COUNTA(SPLIT(AK23, "" "")), 0)"),3.0) -> 3
A24: 23 | B24: 40075003 | C24: 0 | D24: Mejoramiento Plaza Villa El Trebol | E24: Fresia | F24: =+IFERROR(VLOOKUP(E24,'Feriados y Comunas'!$C$1:$D$36,2,FALSE),"") -> LLANQUIHUE | G24: 45904 | H24: 180000 | J24: Ejecución | K24: 2026 | L24: Multisectorial | M24: 1. Adjuntar documentación de acuerdo a los instructivos del Gobierno Regional. 2. Adjuntar documentación al BIP. 1. El proyecto no cuenta con archivos cargados en la plataforma | N24: Pendiente | Q24: Se encuentra dentro de la ERD en: - Lineamiento: Bienestar Socio Territorial. - Ítem: Espacios y Equipamiento Publico. - Objetivo: Construir nuevas áreas verdes de uso publico como herramienta de esparcimiento e integración barrial en las ciudades de la región. - Actividad: Programa regional de construcción y reposición de áreas verdes. | R24: Se enlaza con el Programa Regional del Gobernador en el - Pilar: 1. Políticas Públicas en Materia de Seguridad Ciudadana - Letra: i) Espacios Seguros: Mejorar la iluminación y la seguridad en parques, plazas y áreas públicas para garantizar espacios seguros para todos los habitantes. | S24: 3504 | T24: 3824 | U24: =SUM(S24:T24) -> 7328 | V24: Municipalidad Fresia | W24: Municipalidad Fresia | X24: 728 | Y24: 45904 | AA24: 45904 | AB24: 45904 | AC24: 45904 | AD24: =WORKDAY(AC24,15,'Feriados y Comunas'!A$2:A$26) -> 45929 | AE24: Dcastro | AJ24: 2608 2362 | AK24: 08-10-2025 19-08-2026 | AL24: 03-10-2025 18-08-2026 | AM24: OBSERVADO OBSERVADO | AN24: 503 | AO24: 46225 | AQ24: 46239 | AR24: 2608 | AS24: 45938 | AW24: Observado | AX24: 14 | AY24: =IFERROR(__xludf.DUMMYFUNCTION("IFERROR(COUNTA(SPLIT(AK24, "" "")), 0)"),2.0) -> 2
A25: 24 | B25: 40072891 | C25: 0 | D25: Mejoramiento Multicanchas ST Borde Lago | E25: Puerto Varas | F25: =+IFERROR(VLOOKUP(E25,'Feriados y Comunas'!$C$1:$D$36,2,FALSE),"") -> LLANQUIHUE | G25: 45911 | H25: 300000 | J25: Ejecución | K25: 2026 | L25: Multisectorial | M25: 1. A nivel de alternativas describir con mayor detalle la intervención de la infraestructura. 2. Adjuntar Certificado de Informes previos. 3. Anexas Informe Técnico situación actual por profesional del área. 4. Incorporar factibilidad. 5. Adjuntar carta de no fraccionamiento firmado por el alcalde y visado por depto. jurídico. 6. Anexar Certificado de BNUP. 7. Adjuntar documentación al BIP. GENERALES 1. Incluir carta de no fraccionamiento firmada por alcalde. 2. Justificación de la IDI no corresponde al actual proyecto. ESTUDIO PREINVERSIONAL 1. Documento debe estar firmado por unidad formuladora y en formato PDF. TTR y,o EETT 1. Partida 2.5.3. señalada en EETT no se encuentra incluida en Carta Gantt PLANOS E INGENERÍA 1. Para el correcto y adecuado desarrollo de las actividades deportivas, el diseño de la multicancha deberá estar acorde a las disposiciones del Instituto Nacional de Deporte (IND), en cuanto a las dimensiones y requerimientos de las disciplinas consideradas en el proyecto. El diseño actual no cumple con las dimensiones mínimas. Se recomienda revisar “Manual de construcción y requisitos mínimos para parques, plazas, áreas verdes y áreas deportivas, MINVU, 2017” 2. EL muro de escalada sobre la estructura de cierro de la multicancha debe ser estructuralmente validado. ANEXOS 1. Adjuntar b) Ficha IDI 2. Adjuntar h) Factibilidad eléctrica. 3. Adjuntar j) Propiedad del terreno. 4. Adjuntar m) Certificado compromiso de absorción de costos de operación y mantención. El nombre del proyecto señalado en el archivo adjunto no corresponde al actual proyecto. | N25: 45975 | Q25: La iniciativa se orienta dentro de la ERD en el: - Lineamiento: Bienestar Socio Territorial. - Ítem: Espacios y Equipamiento Público - Objetivo: Aumentar el Nro. De espacios polideportivos en la región con criterios de genero e inclusividad. - Actividad: No hay. | R25: Se enlaza con el Programa Regional del Gobernador: - Pilar: 3. Inclusión Social y Mejoramiento de la Calidad de Vida. - Letra: c) Programas de Apoyo Social: Desarrollar iniciativas para apoyar a los sectores más vulnerables de nuestra comunidad. | S25: 885 | T25: 562 | U25: =SUM(S25:T25) -> 1447 | V25: Municipalidad Puerto Varas | W25: Municipalidad Puerto Varas | X25: 1197 | Y25: 45909 | AA25: 45912 | AB25: 45912 | AC25: 45912 | AD25: =WORKDAY(AC25,15,'Feriados y Comunas'!A$2:A$26) -> 45937 | AE25: Dcastro | AJ25: 2609 3079 | AK25: 08-10-2025 14-11-2025 | AL25: 03-10-2025 14-11-2025 | AM25: OBSERVADO OBSERVADO | AN25: 71 | AO25: 45960 | AQ25: 45964 | AR25: 2609 3079 | AS25: 08-10-2025 14-11-2025 | AW25: Observado | AX25: 13 | AY25: =IFERROR(__xludf.DUMMYFUNCTION("IFERROR(COUNTA(SPLIT(AK25, "" "")), 0)"),2.0) -> 2
A26: 25 | B26: 40031582 | C26: 0 | D26: Construcción Casa Cuesta Arriba | E26: Puerto Varas | F26: =+IFERROR(VLOOKUP(E26,'Feriados y Comunas'!$C$1:$D$36,2,FALSE),"") -> LLANQUIHUE | G26: 45911 | H26: 220000 | J26: Ejecución | K26: 2026 | L26: Multisectorial | M26: 1. Debe existir concordancia de ítems entre EETT, Presupuesto y Carta Gantt. 2. Adjuntar anexo q) Proyectos de especialidades, según lo allí indicado; incorporar mecánica de suelo | N26: 45960 | Q26: Se encuentra dentro de la ERD en el: Lineamiento: Bienestar Socio Territorial. Ítem: Espacios y Equipamiento Publico. Objetivo: Construir equipamientos públicos y espacios de carácter cívico en la región. Actividad: No Hay | R26: Se enlaza con el Programa Regional del Gobernador: Pilar 3. Inclusión Social y Mejoramiento de la Calidad de Vida. Letra c) Programas de Apoyo Social: Desarrollar iniciativas para apoyar a los sectores más vulnerables de nuestra comunidad. | S26: 42 | T26: 63 | U26: =SUM(S26:T26) -> 105 | V26: Municipalidad Puerto Varas | W26: Municipalidad Puerto Varas | X26: 1198 | Y26: 45909 | AA26: 45912 | AB26: 45912 | AC26: 45912 | AD26: =WORKDAY(AC26,15,'Feriados y Comunas'!A$2:A$26) -> 45937 | AE26: Dcastro | AJ26: 2610 2931 | AK26: 08-10-2025 04-11-2025 | AL26: 03-10-2025 30-10-2025 | AM26: OBSERVADO OBSERVADO | AN26: 66 | AO26: 45954 | AQ26: 45958 | AR26: 2610 2931 | AS26: 08-10-2025 04-11-2025 | AW26: Observado | AX26: 13 | AY26: =IFERROR(__xludf.DUMMYFUNCTION("IFERROR(COUNTA(SPLIT(AK26, "" "")), 0)"),2.0) -> 2
A27: 26 | B27: 40072914 | C27: 0 | D27: Mejoramiento Plaza Pob. Digna Campesina de Nueva Braunau | E27: Puerto Varas | F27: =+IFERROR(VLOOKUP(E27,'Feriados y Comunas'!$C$1:$D$36,2,FALSE),"") -> LLANQUIHUE | G27: 45911 | H27: 300000 | J27: Ejecución | K27: 2026 | L27: Multisectorial | M27: Adjuntar EETT firmados por UT. 2. Anexar Ppto. Desglosado. 3. Incorporar APUS 4. Adjuntar Permiso de obra menor. 5. Anexar Memoria. 6. Incorporar Mecánica si corresponde. 7. Adjuntar Cronograma. 8. Anexar Factibilidades. 9. Incorporar Carta de no fraccionamiento, visada por Depto. juridico. 10. Se solicita especificar y caracterizar el área de influencia, cantidad de áreas verdes, multicanchas, etc. 11. Especificar la población objetivo. Ajustar esta con la población total de la localidad. 12. Desarrollar y especificar análisis de alternativas. 13. Adjuntar documentación al BIP. GENERALES Proyecto incompleto: No presenta presupuesto y especificaciones técnicas. | N27: 45933 | Q27: Se encuentra dentro de la ERD en: - Lineamiento: Bienestar Socio Territorial. - Ítem: Espacios y Equipamiento Publico. - Objetivo: Construir nuevas áreas verdes de uso publico como herramienta de esparcimiento e integración barrial en las ciudades de la región. - Actividad: Programa regional de construcción y reposición de áreas verdes. | R27: Se enlaza con el Programa Regional del Gobernador en el - Pilar: 1. Políticas Públicas en Materia de Seguridad Ciudadana - Letra: i) Espacios Seguros: Mejorar la iluminación y la seguridad en parques, plazas y áreas públicas para garantizar espacios seguros para todos los habitantes. | S27: 248 | T27: 324 | U27: =SUM(S27:T27) -> 572 | V27: Municipalidad Puerto Varas | W27: Municipalidad Puerto Varas | X27: 1195 | Y27: 45909 | AA27: 45912 | AB27: 45912 | AC27: 45912 | AD27: =WORKDAY(AC27,15,'Feriados y Comunas'!A$2:A$26) -> 45937 | AJ27: 2611 | AK27: 45938 | AL27: 45933 | AM27: OBSERVADO | AR27: 2611 | AS27: 45938 | AW27: Observado | AX27: 13 | AY27: =IFERROR(__xludf.DUMMYFUNCTION("IFERROR(COUNTA(SPLIT(AK27, "" "")), 0)"),1.0) -> 1
A28: 27 | B28: 40072880 | C28: 0 | D28: Mejoramiento Multicanchas ST Monte Alegre | E28: Puerto Varas | F28: =+IFERROR(VLOOKUP(E28,'Feriados y Comunas'!$C$1:$D$36,2,FALSE),"") -> LLANQUIHUE | G28: 45911 | H28: 300000 | J28: Ejecución | K28: 2026 | L28: Multisectorial | M28: 1. Crear Ficha 2026. 2. Iniciativa debe ser separada, ya que correspondería a un fraccionamiento al presentar otras 2 en la misma área de influencia. 3. La demanda no se ajusta para ambas infraestructuras. 4. Desarrollar el análisis de alternativas, especificar y describir la alternativa seleccionada. 5. Inconsistencia entre justificación ficha IDI y perfil. 6. Adjuntar documentación al BIP. | N28: 45933 | Q28: La iniciativa se orienta dentro de la ERD en el: - Lineamiento: Bienestar Socio Territorial. - Ítem: Espacios y Equipamiento Público - Objetivo: Aumentar el Nro. De espacios polideportivos en la región con criterios de genero e inclusividad. - Actividad: No hay. | R28: Se enlaza con el Programa Regional del Gobernador: - Pilar: 3. Inclusión Social y Mejoramiento de la Calidad de Vida. - Letra: c) Programas de Apoyo Social: Desarrollar iniciativas para apoyar a los sectores más vulnerables de nuestra comunidad. | S28: 645 | T28: 387 | U28: =SUM(S28:T28) -> 1032 | V28: Municipalidad Puerto Varas | W28: Municipalidad Puerto Varas | X28: 1196 | Y28: 45909 | AA28: 45912 | AB28: 45912 | AC28: 45912 | AD28: =WORKDAY(AC28,15,'Feriados y Comunas'!A$2:A$26) -> 45937 | AE28: Dcastro | AJ28: 2612 | AK28: 45938 | AL28: 45933 | AM28: OBSERVADO | AR28: 2612 | AS28: 45938 | AW28: Observado | AX28: 13 | AY28: =IFERROR(__xludf.DUMMYFUNCTION("IFERROR(COUNTA(SPLIT(AK28, "" "")), 0)"),1.0) -> 1
A29: 28 | B29: 40071625 | C29: 0 | D29: Mejoramiento Camarines y Servicios Higienicos Estadio Municipal | E29: San Pablo | F29: =+IFERROR(VLOOKUP(E29,'Feriados y Comunas'!$C$1:$D$36,2,FALSE),"") -> OSORNO | G29: 45917 | H29: 312894 | J29: Ejecución | K29: 2026 | L29: Deportes | M29: 1. Faltan antecedentes mínimos para un análisis completo. 2. Adicionalmente el proyecto corresponde a un fraccionamiento, ya que solo el proyecto mejora solo una parte del recinto, y no un mejoramiento integral. 3. Adjuntar documentación al BIP. | N29: 45953 | Q29: La iniciativa se orienta dentro de la ERD en el: - Lineamiento: Bienestar Socio Territorial. - Ítem: Espacios y Equipamiento Público - Objetivo: Aumentar el Nro. De espacios polideportivos en la región con criterios de genero e inclusividad. - Actividad: No hay. | R29: Se enlaza con el Programa Regional del Gobernador: - Pilar: 3. Inclusión Social y Mejoramiento de la Calidad de Vida. - Letra: c) Programas de Apoyo Social: Desarrollar iniciativas para apoyar a los sectores más vulnerables de nuestra comunidad. | S29: 154 | T29: 205 | U29: =SUM(S29:T29) -> 359 | V29: Municipalidad San Pablo | W29: Municipalidad San Pablo | X29: 657 | Y29: 45915 | AA29: 45917 | AB29: 45917 | AC29: 45917 | AD29: =WORKDAY(AC29,15,'Feriados y Comunas'!A$2:A$26) -> 45940 | AJ29: 2825 | AK29: 45957 | AL29: 45953 | AM29: OBSERVADO | AR29: 2825 | AS29: 45957 | AW29: Observado | AX29: 24 | AY29: =IFERROR(__xludf.DUMMYFUNCTION("IFERROR(COUNTA(SPLIT(AK29, "" "")), 0)"),1.0) -> 1
A30: 29 | B30: 40075706 | C30: 0 | D30: Construcción Centro Comunitario Multiproposito Trumao | E30: San Pablo | F30: =+IFERROR(VLOOKUP(E30,'Feriados y Comunas'!$C$1:$D$36,2,FALSE),"") -> OSORNO | G30: 45917 | H30: 295000 | J30: Ejecución | K30: 2026 | L30: Salud | M30: 1. Crear Ficha 2026, Corregir m2. 2. Ppto. No concuerda con ficha IDI. 3. Adjuntar Participación ciudadana anexo 2. 4. Anexar Permiso. 5. Incorporar Memoria. 6. Adjuntar Mecánica. 7. Anexar Cronograma. 8. Incorporar Modelo de Gestión. 9. Adjuntar Certificado de Hipotecas y Gravámenes. 10. Anexar Costos Operacionales Firmado por el Consejo. 11. Incorporar Certificado Secplan – DOM. 12. Adjuntar Carta de no Fraccionamiento visado por Depto. Jurídico. 13. Anexar Informes Previos. 14. Incorporar Plan de Mitigación. 15. Adjuntar documentación al BIP. EVALUACIÓN TÉCNICA - PRESUPUESTO 1. No está presupuestada la demolición de la edificación existente. 2. Se debe señalar bajo cada firma de documento y plano de los proyectos de especialidades, a lo menos el nombre y profesión del proyectista. 3. Valor total de presupuesto no coincide con Ficha IDI en BIP. TTR y,o EETT 1. Incorporar imagen final Letrero de Obras, ajustada al manual de normas gráficas GORE 2025 2. Incorporar imagen final Placa Recordatoria, ajustada al manual de normas gráficas GORE 2025. PLANOS E INGENERÍA 1. Pl-eléctrico: En Baño 1 y Baño 2 se debe incorporar dispositivo de iluminación. 2. Incorporar plano de demoliciones. ANEXOS 1. Incorporar lo señalado en 5.8. b) Ficha IDI 2. Incorporar lo señalado en 5.8. h) Factibilidad sanitaria 3. Incorporar lo señalado en 5.8. j) Propiedades del terreno: Certificado de hipotecas y gravámenes. 4. Incorporar lo señalado en 5.8. k) Certificado del DOM 5. Incorporar lo señalado en 5.8. l) Permiso de edificación 6. Incorporar lo señalado en 5.8. n) Participación ciudadana 7. Incorporar lo señalado en 5.8. q) Proyectos de Especialidades, tales como Ingeniería, Estudios Hidráulicos, Mecánica de Suelo, etc. 8. Incorporar lo señalado en 5.8. r) Copia de certificado de título. 9. Incorporar lo señalado en 5.8. u) Plan de mitigación durante la ejecución de las obras. Esto, respecto a la programación que dé continuidad a la asistencia médica que se presta en una de las edificaciones. | N30: 45953 | Q30: Se encuentra dentro de la ERD en el - Lineamiento: Bienestar Socio Territorial. - Ítem: Salud. - Objetivo: Aumentar Cobertura de atención primaria en salud en la comunas de la región. - Actividad: | R30: Se enlaza con el programa del Gobernador Regional en el - Pilar: 3. Inclusión Social y Mejoramiento de la Calidad de Vida. - Letra: e) Acceso a Servicios de Salud: Ampliar y mejorar la red de servicios de salud, especialmente en zonas rurales, garantizando atención médica de calidad para todos. | S30: 120 | T30: 158 | U30: =SUM(S30:T30) -> 278 | V30: Municipalidad San Pablo | W30: Municipalidad San Pablo | X30: 655 | Y30: 45910 | AA30: 45917 | AB30: 45917 | AC30: 45917 | AD30: =WORKDAY(AC30,15,'Feriados y Comunas'!A$2:A$26) -> 45940 | AE30: Dcastro | AJ30: 2824 | AK30: 45957 | AL30: 45953 | AM30: OBSERVADO | AR30: 2824 | AS30: 45957 | AW30: Observado | AX30: 24 | AY30: =IFERROR(__xludf.DUMMYFUNCTION("IFERROR(COUNTA(SPLIT(AK30, "" "")), 0)"),1.0) -> 1
