Workbook
Name BIP: '2022'!#REF!
Name BIP: '2023'!#REF!
Name BIP: '2024'!#REF!
Name BIP: '2025'!#REF!
Name BIP: '2026'!#REF!
Name BIP: #REF!

Sheet 2026
A1: CANT | B1: SUBT. | C1: ARI 2023 | D1: PPTO 2025 | E1: ARI 2027 | F1: PROVINCIA | G1: COMUNA | H1: FORMULADOR | I1: BIP | J1: NOMBRE DE LA INICIATIVA | K1: COSTO | L1: EVALUADOR | M1: ESTADO | N1: FECHA 1er INGRESO | O1: FECHA 1er Respuesta | P1: DÍAS 1° Evaluación | Q1: FECHA INGRESO | R1: PLAZO PARA INFORMAR (15 DIAS) | S1: FECHA EVALUACION | T1: DIAS EVALUAR | U1: FECHA (REAL) ENTREGA | V1: DIAS EN EVALUACION | W1: DIAS HAB. EN EVALUACION | X1: DIAS RESTANTES | Y1: ORD GR N°/ FECHA | Z1: CLASIFICACION | AA1: BENEFICIARIOS DIRECTOS | AB1: ¿ES REEVALUACION? | AC1: SECTOR (SNI)
A2: 1 | B2: 29 | C2: =IF(ISERROR(VLOOKUP(I2,[1]DEP!$B$3:$E$583,1,FALSE)),"NO","SI") -> NO | D2: =IF(ISERROR(VLOOKUP(I2,[2]FRG!$S$19:$U$288,1,FALSE)),"NO","SI") -> SI | E2: =IF(ISERROR(VLOOKUP(I2,[3]DATOS_PREINVERSION!$O$3:$R$475,1,FALSE)),"NO","SI") -> NO | F2: OSORNO | G2: PROV. OSORNO | H2: DIRECCION DE VIALIDAD | I2: 40044996 | J2: REEV REPOSICION VEHICULOS Y ADQUISICION MAQUINARIA DE ASFALTO PARA LA D.V. REGIÓN DE LOS LAGOS | K2: 1392180000 | L2: Fabián Rutte | M2: CUMPLE RT | P2: =IF(NETWORKDAYS(N2,O2,Feriados!$J$2:$J$22)-1>=0,NETWORKDAYS(N2,O2,Feriados!$J$2:$J$22)-1,"NO APLICA") -> NO APLICA | Q2: 46028 | R2: =+Q2+T2 -> 46038 | S2: 46038 | T2: 10 | U2: =WORKDAY(Q2,T2,Feriados!$J$2:$J$22) -> 46042 | V2: =+S2-Q2 -> 10 | W2: =IF(NETWORKDAYS(Q2,S2,Feriados!$J$2:$J$22)-1>=0,NETWORKDAYS(Q2,S2,Feriados!$J$2:$J$22)-1,"NO APLICA") -> 8 | X2: =SUM(U2-TODAY()) -> -254 | Y2: 737/16-03-2023 | Z2: MAQ. CNOS | AA2: 234122 | AB2: SI | AC2: TRANSPORTE
A3: 2 | B3: 31 | C3: =IF(ISERROR(VLOOKUP(I3,[1]DEP!$B$3:$E$583,1,FALSE)),"NO","SI") -> NO | D3: =IF(ISERROR(VLOOKUP(I3,[2]FRG!$S$19:$U$288,1,FALSE)),"NO","SI") -> NO | E3: =IF(ISERROR(VLOOKUP(I3,[3]DATOS_PREINVERSION!$O$3:$R$475,1,FALSE)),"NO","SI") -> NO | F3: LLANQUIHUE | G3: FRUTILLAR | H3: MUNICIPALIDAD FRUTILLAR | I3: 40055335 | J3: CONSERVACION CAMINOS NO ENROLADOS DIVERSOS SECTORES DE FRUTILLAR, ETAPA III | K3: 277023000 | L3: Fabián Rutte | M3: OBSERVADO | N3: 46031 | O3: 46056 | P3: =IF(NETWORKDAYS(N3,O3,Feriados!$J$2:$J$22)-1>=0,NETWORKDAYS(N3,O3,Feriados!$J$2:$J$22)-1,"NO APLICA") -> 17 | Q3: 46031 | R3: =+Q3+T3 -> 46046 | S3: 46056 | T3: 15 | U3: =WORKDAY(Q3,T3,Feriados!$J$2:$J$22) -> 46052 | V3: =+S3-Q3 -> 25 | W3: =IF(NETWORKDAYS(Q3,S3,Feriados!$J$2:$J$22)-1>=0,NETWORKDAYS(Q3,S3,Feriados!$J$2:$J$22)-1,"NO APLICA") -> 17 | X3: =SUM(U3-TODAY()) -> -244 | Z3: CNOS NO ENROLADOS | AB3: NO | AC3: TRANSPORTE
A4: 3 | B4: 29 | C4: =IF(ISERROR(VLOOKUP(I4,[1]DEP!$B$3:$E$583,1,FALSE)),"NO","SI") -> NO | D4: =IF(ISERROR(VLOOKUP(I4,[2]FRG!$S$19:$U$288,1,FALSE)),"NO","SI") -> NO | E4: =IF(ISERROR(VLOOKUP(I4,[3]DATOS_PREINVERSION!$O$3:$R$475,1,FALSE)),"NO","SI") -> NO | F4: CHILOÉ | G4: DALCAHUE | H4: MUNICIPALIDAD DALCAHUE | I4: 50000224 | J4: ADQUISICIÓN CLINICA MOVIL GINECOLOGICA, COMUNA DE DALCAHUE | K4: 291785000 | L4: Fabián Rutte | M4: OBSERVADO | N4: 46028 | O4: 46045 | P4: =IF(NETWORKDAYS(N4,O4,Feriados!$J$2:$J$22)-1>=0,NETWORKDAYS(N4,O4,Feriados!$J$2:$J$22)-1,"NO APLICA") -> 13 | Q4: 46028 | R4: =+Q4+T4 -> 46043 | S4: 46045 | T4: 15 | U4: =WORKDAY(Q4,T4,Feriados!$J$2:$J$22) -> 46049 | V4: =+S4-Q4 -> 17 | W4: =IF(NETWORKDAYS(Q4,S4,Feriados!$J$2:$J$22)-1>=0,NETWORKDAYS(Q4,S4,Feriados!$J$2:$J$22)-1,"NO APLICA") -> 13 | X4: =SUM(U4-TODAY()) -> -247 | Z4: CLÍNICA MÓVIL | AB4: NO | AC4: SALUD
A5: 4 | B5: 31 | C5: =IF(ISERROR(VLOOKUP(I5,[1]DEP!$B$3:$E$583,1,FALSE)),"NO","SI") -> NO | D5: =IF(ISERROR(VLOOKUP(I5,[2]FRG!$S$19:$U$288,1,FALSE)),"NO","SI") -> NO | E5: =IF(ISERROR(VLOOKUP(I5,[3]DATOS_PREINVERSION!$O$3:$R$475,1,FALSE)),"NO","SI") -> SI | F5: OSORNO | G5: PUYEHUE | H5: MUNICIPALIDAD PUYEHUE | I5: 40064446 | J5: CONSTRUCCION CONSERVACION CAMINOS NO ENROLADOS EN 9 SECTORES DE LA COMUNA DE PUYEHUE | K5: 611628000 | L5: Fabián Rutte | M5: OBSERVADO | N5: 46034 | O5: 46049 | P5: =IF(NETWORKDAYS(N5,O5,Feriados!$J$2:$J$22)-1>=0,NETWORKDAYS(N5,O5,Feriados!$J$2:$J$22)-1,"NO APLICA") -> 11 | Q5: 46034 | R5: =+Q5+T5 -> 46049 | S5: 46049 | T5: 15 | U5: =WORKDAY(Q5,T5,Feriados!$J$2:$J$22) -> 46055 | V5: =+S5-Q5 -> 15 | W5: =IF(NETWORKDAYS(Q5,S5,Feriados!$J$2:$J$22)-1>=0,NETWORKDAYS(Q5,S5,Feriados!$J$2:$J$22)-1,"NO APLICA") -> 11 | X5: =SUM(U5-TODAY()) -> -241 | Z5: CNOS NO ENROLADOS | AB5: NO | AC5: TRANSPORTE
A6: 5 | B6: 31 | C6: =IF(ISERROR(VLOOKUP(I6,[1]DEP!$B$3:$E$583,1,FALSE)),"NO","SI") -> NO | D6: =IF(ISERROR(VLOOKUP(I6,[2]FRG!$S$19:$U$288,1,FALSE)),"NO","SI") -> NO | E6: =IF(ISERROR(VLOOKUP(I6,[3]DATOS_PREINVERSION!$O$3:$R$475,1,FALSE)),"NO","SI") -> SI | F6: OSORNO | G6: OSORNO | H6: MUNICIPALIDAD OSORNO | I6: 40077644 | J6: CONSERVACION CALZADAS RAHUE ALTO SUR, UNIDAD VECINAL N.5, OSORNO | K6: 1434719000 | L6: Fabián Rutte | M6: OBSERVADO | N6: 46031 | P6: =IF(NETWORKDAYS(N6,O6,Feriados!$J$2:$J$22)-1>=0,NETWORKDAYS(N6,O6,Feriados!$J$2:$J$22)-1,"NO APLICA") -> NO APLICA | Q6: 46031 | R6: =+Q6+T6 -> 46046 | T6: 15 | U6: =WORKDAY(Q6,T6,Feriados!$J$2:$J$22) -> 46052 | V6: =+S6-Q6 -> -46031 | W6: =IF(NETWORKDAYS(Q6,S6,Feriados!$J$2:$J$22)-1>=0,NETWORKDAYS(Q6,S6,Feriados!$J$2:$J$22)-1,"NO APLICA") -> NO APLICA | X6: =SUM(U6-TODAY()) -> -244 | Z6: PAV. URBANOS | AB6: NO | AC6: TRANSPORTE
A7: 6 | B7: 31 | C7: =IF(ISERROR(VLOOKUP(I7,[1]DEP!$B$3:$E$583,1,FALSE)),"NO","SI") -> NO | D7: =IF(ISERROR(VLOOKUP(I7,[2]FRG!$S$19:$U$288,1,FALSE)),"NO","SI") -> NO | E7: =IF(ISERROR(VLOOKUP(I7,[3]DATOS_PREINVERSION!$O$3:$R$475,1,FALSE)),"NO","SI") -> SI | F7: OSORNO | G7: OSORNO | H7: MUNICIPALIDAD OSORNO | I7: 40077647 | J7: CONSERVACION CALZADAS RAHUE ALTO SUR, UNIDADES VECINALES N.8, N.20 Y N.23, OSORNO | K7: 1062940000 | L7: Fabián Rutte | M7: OBSERVADO | N7: 46031 | P7: =IF(NETWORKDAYS(N7,O7,Feriados!$J$2:$J$22)-1>=0,NETWORKDAYS(N7,O7,Feriados!$J$2:$J$22)-1,"NO APLICA") -> NO APLICA | Q7: 46031 | R7: =+Q7+T7 -> 46046 | T7: 15 | U7: =WORKDAY(Q7,T7,Feriados!$J$2:$J$22) -> 46052 | V7: =+S7-Q7 -> -46031 | W7: =IF(NETWORKDAYS(Q7,S7,Feriados!$J$2:$J$22)-1>=0,NETWORKDAYS(Q7,S7,Feriados!$J$2:$J$22)-1,"NO APLICA") -> NO APLICA | X7: =SUM(U7-TODAY()) -> -244 | Z7: PAV. URBANOS | AB7: NO | AC7: TRANSPORTE
A8: 7 | B8: 31 | C8: =IF(ISERROR(VLOOKUP(I8,[1]DEP!$B$3:$E$583,1,FALSE)),"NO","SI") -> NO | D8: =IF(ISERROR(VLOOKUP(I8,[2]FRG!$S$19:$U$288,1,FALSE)),"NO","SI") -> NO | E8: =IF(ISERROR(VLOOKUP(I8,[3]DATOS_PREINVERSION!$O$3:$R$475,1,FALSE)),"NO","SI") -> SI | F8: OSORNO | G8: OSORNO | H8: MUNICIPALIDAD OSORNO | I8: 40077645 | J8: CONSERVACION CALZADAS RAHUE ALTO SUR, UNIDAD VECINAL N.6, OSORNO | K8: 916023000 | L8: Fabián Rutte | M8: OBSERVADO | N8: 46031 | P8: =IF(NETWORKDAYS(N8,O8,Feriados!$J$2:$J$22)-1>=0,NETWORKDAYS(N8,O8,Feriados!$J$2:$J$22)-1,"NO APLICA") -> NO APLICA | Q8: 46031 | R8: =+Q8+T8 -> 46046 | T8: 15 | U8: =WORKDAY(Q8,T8,Feriados!$J$2:$J$22) -> 46052 | V8: =+S8-Q8 -> -46031 | W8: =IF(NETWORKDAYS(Q8,S8,Feriados!$J$2:$J$22)-1>=0,NETWORKDAYS(Q8,S8,Feriados!$J$2:$J$22)-1,"NO APLICA") -> NO APLICA | X8: =SUM(U8-TODAY()) -> -244 | Z8: PAV. URBANOS | AB8: NO | AC8: TRANSPORTE
A9: 8 | B9: 31 | C9: =IF(ISERROR(VLOOKUP(I9,[1]DEP!$B$3:$E$583,1,FALSE)),"NO","SI") -> NO | D9: =IF(ISERROR(VLOOKUP(I9,[2]FRG!$S$19:$U$288,1,FALSE)),"NO","SI") -> NO | E9: =IF(ISERROR(VLOOKUP(I9,[3]DATOS_PREINVERSION!$O$3:$R$475,1,FALSE)),"NO","SI") -> SI | F9: OSORNO | G9: OSORNO | H9: MUNICIPALIDAD OSORNO | I9: 40077646 | J9: CONSERVACION CALZADAS RAHUE ALTO SUR, UNIDAD VECINAL N.7, OSORNO | K9: 2071223000 | L9: Fabián Rutte | M9: OBSERVADO | N9: 46029 | O9: 46044 | P9: =IF(NETWORKDAYS(N9,O9,Feriados!$J$2:$J$22)-1>=0,NETWORKDAYS(N9,O9,Feriados!$J$2:$J$22)-1,"NO APLICA") -> 11 | Q9: 46029 | R9: =+Q9+T9 -> 46044 | S9: 46044 | T9: 15 | U9: =WORKDAY(Q9,T9,Feriados!$J$2:$J$22) -> 46050 | V9: =+S9-Q9 -> 15 | W9: =IF(NETWORKDAYS(Q9,S9,Feriados!$J$2:$J$22)-1>=0,NETWORKDAYS(Q9,S9,Feriados!$J$2:$J$22)-1,"NO APLICA") -> 11 | X9: =SUM(U9-TODAY()) -> -246 | Z9: PAV. URBANOS | AB9: NO | AC9: TRANSPORTE
A10: 9 | B10: 29 | C10: =IF(ISERROR(VLOOKUP(I10,[1]DEP!$B$3:$E$583,1,FALSE)),"NO","SI") -> NO | D10: =IF(ISERROR(VLOOKUP(I10,[2]FRG!$S$19:$U$288,1,FALSE)),"NO","SI") -> NO | E10: =IF(ISERROR(VLOOKUP(I10,[3]DATOS_PREINVERSION!$O$3:$R$475,1,FALSE)),"NO","SI") -> NO | F10: PALENA | G10: PALENA | H10: MUNICIPALIDAD PALENA | I10: 40076387 | J10: REPOSICION DE VEHÍCULOS MUNICIPALES PARA LA MOVILIZACIÓN DE FUNCIONARIOS | K10: 187635000 | L10: Fabián Rutte | M10: CUMPLE RT | N10: 46045 | O10: 46048 | P10: =IF(NETWORKDAYS(N10,O10,Feriados!$J$2:$J$22)-1>=0,NETWORKDAYS(N10,O10,Feriados!$J$2:$J$22)-1,"NO APLICA") -> 1 | Q10: 46045 | R10: =+Q10+T10 -> 46060 | S10: 46048 | T10: 15 | U10: =WORKDAY(Q10,T10,Feriados!$J$2:$J$22) -> 46066 | V10: =+S10-Q10 -> 3 | W10: =IF(NETWORKDAYS(Q10,S10,Feriados!$J$2:$J$22)-1>=0,NETWORKDAYS(Q10,S10,Feriados!$J$2:$J$22)-1,"NO APLICA") -> 1 | X10: =SUM(U10-TODAY()) -> -230 | Y10: 202/28-01-2026 | Z10: VEHICULOS | AB10: NO | AC10: MULTISECTORIAL
A11: 10 | B11: 29 | C11: =IF(ISERROR(VLOOKUP(I11,[1]DEP!$B$3:$E$583,1,FALSE)),"NO","SI") -> NO | D11: =IF(ISERROR(VLOOKUP(I11,[2]FRG!$S$19:$U$288,1,FALSE)),"NO","SI") -> NO | E11: =IF(ISERROR(VLOOKUP(I11,[3]DATOS_PREINVERSION!$O$3:$R$475,1,FALSE)),"NO","SI") -> NO | F11: X REGION | G11: X REGION | H11: REGION POLICIAL LOS LAGOS PDI | I11: 40076624 | J11: ADQUISICION VEHÍCULOS TRASLADO Y RESGUARDO DE CANES DETECTORES DE DROGAS-BRIANCO (PMO - ONO) | K11: 259301000 | L11: Fabián Rutte | M11: CUMPLE RT | N11: 46037 | O11: 46057 | P11: =IF(NETWORKDAYS(N11,O11,Feriados!$J$2:$J$22)-1>=0,NETWORKDAYS(N11,O11,Feriados!$J$2:$J$22)-1,"NO APLICA") -> 14 | Q11: 46157 | R11: =+Q11+T11 -> 46172 | S11: 46174 | T11: 15 | U11: =WORKDAY(Q11,T11,Feriados!$J$2:$J$22) -> 46181 | V11: =+S11-Q11 -> 17 | W11: =IF(NETWORKDAYS(Q11,S11,Feriados!$J$2:$J$22)-1>=0,NETWORKDAYS(Q11,S11,Feriados!$J$2:$J$22)-1,"NO APLICA") -> 10 | X11: =SUM(U11-TODAY()) -> -115 | Y11: 1.333/01-06-2026 | Z11: VEHICULOS | AB11: NO | AC11: SEGURIDAD
A12: 11 | B12: 29 | C12: =IF(ISERROR(VLOOKUP(I12,[1]DEP!$B$3:$E$583,1,FALSE)),"NO","SI") -> NO | D12: =IF(ISERROR(VLOOKUP(I12,[2]FRG!$S$19:$U$288,1,FALSE)),"NO","SI") -> NO | E12: =IF(ISERROR(VLOOKUP(I12,[3]DATOS_PREINVERSION!$O$3:$R$475,1,FALSE)),"NO","SI") -> SI | F12: X REGION | G12: X REGION | H12: SERVICIO SALUD RELONCAVI | I12: 40075933 | J12: REPOSICION EQUIPAMIENTO DE PABELLON PARA RESOLUCION GES ONCOLOGICOS HOSPITAL PUERTO MONTT | K12: 532674000 | L12: Fabián Rutte | M12: CUMPLE RT | N12: 46049 | O12: 46059 | P12: =IF(NETWORKDAYS(N12,O12,Feriados!$J$2:$J$22)-1>=0,NETWORKDAYS(N12,O12,Feriados!$J$2:$J$22)-1,"NO APLICA") -> 8 | Q12: 46122 | R12: =+Q12+T12 -> 46137 | S12: 46135 | T12: 15 | U12: =WORKDAY(Q12,T12,Feriados!$J$2:$J$22) -> 46146 | V12: =+S12-Q12 -> 13 | W12: =IF(NETWORKDAYS(Q12,S12,Feriados!$J$2:$J$22)-1>=0,NETWORKDAYS(Q12,S12,Feriados!$J$2:$J$22)-1,"NO APLICA") -> 9 | X12: =SUM(U12-TODAY()) -> -150 | Y12: 916/23-04-2026 | Z12: EQ. SALUD | AB12: NO | AC12: SALUD
A13: 12 | B13: 29 | C13: =IF(ISERROR(VLOOKUP(I13,[1]DEP!$B$3:$E$583,1,FALSE)),"NO","SI") -> NO | D13: =IF(ISERROR(VLOOKUP(I13,[2]FRG!$S$19:$U$288,1,FALSE)),"NO","SI") -> NO | E13: =IF(ISERROR(VLOOKUP(I13,[3]DATOS_PREINVERSION!$O$3:$R$475,1,FALSE)),"NO","SI") -> NO | F13: =+IFERROR(VLOOKUP(G13,Feriados!$M$1:$N$36,2,FALSE),"") -> REGIONAL | G13: REGIONAL | H13: CONAF | I13: 40062961 | J13: REPOSICION EQUIPOS DE RADIO COMUNICACIONES INCENDIOS FORESTALES Y ASP CONAF LOS LAGOS | K13: 825923000 | L13: Fabián Rutte | M13: OBSERVADO | N13: 46024 | O13: 46049 | P13: =IF(NETWORKDAYS(N13,O13,Feriados!$J$2:$J$22)-1>=0,NETWORKDAYS(N13,O13,Feriados!$J$2:$J$22)-1,"NO APLICA") -> 17 | Q13: 46024 | R13: =+Q13+T13 -> 46039 | S13: 46049 | T13: 15 | U13: =WORKDAY(Q13,T13,Feriados!$J$2:$J$22) -> 46045 | V13: =+S13-Q13 -> 25 | W13: =IF(NETWORKDAYS(Q13,S13,Feriados!$J$2:$J$22)-1>=0,NETWORKDAYS(Q13,S13,Feriados!$J$2:$J$22)-1,"NO APLICA") -> 17 | X13: =SUM(U13-TODAY()) -> -251 | Z13: S/C | AB13: NO | AC13: S/C
A14: 13 | B14: 31 | C14: =IF(ISERROR(VLOOKUP(I14,[1]DEP!$B$3:$E$583,1,FALSE)),"NO","SI") -> NO | D14: =IF(ISERROR(VLOOKUP(I14,[2]FRG!$S$19:$U$288,1,FALSE)),"NO","SI") -> NO | E14: =IF(ISERROR(VLOOKUP(I14,[3]DATOS_PREINVERSION!$O$3:$R$475,1,FALSE)),"NO","SI") -> NO | F14: OSORNO | G14: OSORNO | H14: MUNICIPALIDAD OSORNO | I14: 40077488 | J14: CONSERVACION CAMINOS RURALES NO ENROLADOS EN LA COMUNA DE OSORNO | K14: 1454613000 | L14: Fabián Rutte | M14: OBSERVADO | N14: 46045 | O14: 46058 | P14: =IF(NETWORKDAYS(N14,O14,Feriados!$J$2:$J$22)-1>=0,NETWORKDAYS(N14,O14,Feriados!$J$2:$J$22)-1,"NO APLICA") -> 9 | Q14: 46045 | R14: =+Q14+T14 -> 46060 | S14: 46058 | T14: 15 | U14: =WORKDAY(Q14,T14,Feriados!$J$2:$J$22) -> 46066 | V14: =+S14-Q14 -> 13 | W14: =IF(NETWORKDAYS(Q14,S14,Feriados!$J$2:$J$22)-1>=0,NETWORKDAYS(Q14,S14,Feriados!$J$2:$J$22)-1,"NO APLICA") -> 9 | X14: =SUM(U14-TODAY()) -> -230 | Z14: CNOS NO ENROLADOS | AB14: NO | AC14: TRANSPORTE
A15: 14 | B15: 29 | C15: =IF(ISERROR(VLOOKUP(I15,[1]DEP!$B$3:$E$583,1,FALSE)),"NO","SI") -> NO | D15: =IF(ISERROR(VLOOKUP(I15,[2]FRG!$S$19:$U$288,1,FALSE)),"NO","SI") -> SI | E15: =IF(ISERROR(VLOOKUP(I15,[3]DATOS_PREINVERSION!$O$3:$R$475,1,FALSE)),"NO","SI") -> NO | F15: CHILOÉ | G15: PROVINCIAL | H15: DIRECCION DE VIALIDAD | I15: 40057047 | J15: REEV REPOSICION VEHICULOS Y ADQUISICION MAQUINARIA DE ASFALTO PARA LA D. V., PROVINCIA DE CHILOE | K15: 1397278000 | L15: Fabián Rutte | M15: CUMPLE RT | P15: =IF(NETWORKDAYS(N15,O15,Feriados!$J$2:$J$22)-1>=0,NETWORKDAYS(N15,O15,Feriados!$J$2:$J$22)-1,"NO APLICA") -> NO APLICA | Q15: 46050 | R15: =+Q15+T15 -> 46060 | S15: 46055 | T15: 10 | U15: =WORKDAY(Q15,T15,Feriados!$J$2:$J$22) -> 46064 | V15: =+S15-Q15 -> 5 | W15: =IF(NETWORKDAYS(Q15,S15,Feriados!$J$2:$J$22)-1>=0,NETWORKDAYS(Q15,S15,Feriados!$J$2:$J$22)-1,"NO APLICA") -> 3 | X15: =SUM(U15-TODAY()) -> -232 | Y15: 3.646/27-09-2023 | Z15: MAQ. CNOS | AA15: 168185 | AB15: SI | AC15: TRANSPORTE
A16: 15 | B16: 29 | C16: =IF(ISERROR(VLOOKUP(I16,[1]DEP!$B$3:$E$583,1,FALSE)),"NO","SI") -> SI | D16: =IF(ISERROR(VLOOKUP(I16,[2]FRG!$S$19:$U$288,1,FALSE)),"NO","SI") -> SI | E16: =IF(ISERROR(VLOOKUP(I16,[3]DATOS_PREINVERSION!$O$3:$R$475,1,FALSE)),"NO","SI") -> NO | F16: CHILOÉ | G16: PUQUELDÓN | H16: MUNICIPALIDAD PUQUELDÓN | I16: 40013818 | J16: REEV REPOSICION MAQUINARIA PARA MANTENCION DE CAMINOS VECINALES, COMUNA PUQUELDON | K16: 1023216000 | L16: Fabián Rutte | M16: CUMPLE RT | P16: =IF(NETWORKDAYS(N16,O16,Feriados!$J$2:$J$22)-1>=0,NETWORKDAYS(N16,O16,Feriados!$J$2:$J$22)-1,"NO APLICA") -> NO APLICA | Q16: 46055 | R16: =+Q16+T16 -> 46065 | S16: 46059 | T16: 10 | U16: =WORKDAY(Q16,T16,Feriados!$J$2:$J$22) -> 46069 | V16: =+S16-Q16 -> 4 | W16: =IF(NETWORKDAYS(Q16,S16,Feriados!$J$2:$J$22)-1>=0,NETWORKDAYS(Q16,S16,Feriados!$J$2:$J$22)-1,"NO APLICA") -> 4 | X16: =SUM(U16-TODAY()) -> -227 | Y16: 4.067/30-10-2023 | Z16: MAQ. CNOS | AA16: 1190 | AB16: SI | AC16: TRANSPORTE
A17: 16 | B17: 29 | C17: =IF(ISERROR(VLOOKUP(I17,[1]DEP!$B$3:$E$583,1,FALSE)),"NO","SI") -> NO | D17: =IF(ISERROR(VLOOKUP(I17,[2]FRG!$S$19:$U$288,1,FALSE)),"NO","SI") -> NO | E17: =IF(ISERROR(VLOOKUP(I17,[3]DATOS_PREINVERSION!$O$3:$R$475,1,FALSE)),"NO","SI") -> SI | F17: OSORNO | G17: OSORNO | H17: MUNICIPALIDAD OSORNO | I17: 40068124 | J17: REPOSICION EQUIPO DE ENDOSCOPÍA CENTRO DE REFERENCIA DIAGNÓSTICO MUNICIPAL, OSORNO | K17: 354658000 | L17: Fabián Rutte | M17: OBSERVADO | N17: 46056 | O17: 46078 | P17: =IF(NETWORKDAYS(N17,O17,Feriados!$J$2:$J$22)-1>=0,NETWORKDAYS(N17,O17,Feriados!$J$2:$J$22)-1,"NO APLICA") -> 16 | Q17: 46056 | R17: =+Q17+T17 -> 46071 | S17: 46078 | T17: 15 | U17: =WORKDAY(Q17,T17,Feriados!$J$2:$J$22) -> 46077 | V17: =+S17-Q17 -> 22 | W17: =IF(NETWORKDAYS(Q17,S17,Feriados!$J$2:$J$22)-1>=0,NETWORKDAYS(Q17,S17,Feriados!$J$2:$J$22)-1,"NO APLICA") -> 16 | X17: =SUM(U17-TODAY()) -> -219 | Z17: EQ. SALUD | AB17: NO | AC17: SALUD
A18: 17 | B18: 29 | C18: =IF(ISERROR(VLOOKUP(I18,[1]DEP!$B$3:$E$583,1,FALSE)),"NO","SI") -> NO | D18: =IF(ISERROR(VLOOKUP(I18,[2]FRG!$S$19:$U$288,1,FALSE)),"NO","SI") -> NO | E18: =IF(ISERROR(VLOOKUP(I18,[3]DATOS_PREINVERSION!$O$3:$R$475,1,FALSE)),"NO","SI") -> NO | F18: X REGION | G18: X REGION | H18: SERVICIO SALUD RELONCAVI | I18: 40077628 | J18: ADQUISICION 02 CAMIONES MAMOGRAFICOS GINECOLÓGICOS PROVINCIA DE LLANQUIHUE Y PALENA | K18: 1252475000 | L18: Fabián Rutte | M18: EN EVALUACIÓN | N18: 46059 | O18: 46059 | P18: =IF(NETWORKDAYS(N18,O18,Feriados!$J$2:$J$22)-1>=0,NETWORKDAYS(N18,O18,Feriados!$J$2:$J$22)-1,"NO APLICA") -> 0 | Q18: 46265 | R18: =+Q18+T18 -> 46280 | S18: 46059 | T18: 15 | U18: =WORKDAY(Q18,T18,Feriados!$J$2:$J$22) -> 46287 | V18: =+S18-Q18 -> -206 | W18: =IF(NETWORKDAYS(Q18,S18,Feriados!$J$2:$J$22)-1>=0,NETWORKDAYS(Q18,S18,Feriados!$J$2:$J$22)-1,"NO APLICA") -> NO APLICA | X18: =SUM(U18-TODAY()) -> -9 | Z18: CLÍNICA MÓVIL | AB18: NO | AC18: SALUD
A19: 18 | B19: 31 | C19: =IF(ISERROR(VLOOKUP(I19,[1]DEP!$B$3:$E$583,1,FALSE)),"NO","SI") -> NO | D19: =IF(ISERROR(VLOOKUP(I19,[2]FRG!$S$19:$U$288,1,FALSE)),"NO","SI") -> NO | E19: =IF(ISERROR(VLOOKUP(I19,[3]DATOS_PREINVERSION!$O$3:$R$475,1,FALSE)),"NO","SI") -> SI | F19: LLANQUIHUE | G19: FRESIA | H19: MUNICIPALIDAD FRESIA | I19: 40064827 | J19: CONSERVACION CAMINOS NO ENROLADOS SECTORES LA VEGA, BOTIJA, SAN NICOLÁS, EL PATO Y FRESIA | K19: 656020000 | L19: Fabián Rutte | M19: OBSERVADO | N19: 46059 | O19: 46080 | P19: =IF(NETWORKDAYS(N19,O19,Feriados!$J$2:$J$22)-1>=0,NETWORKDAYS(N19,O19,Feriados!$J$2:$J$22)-1,"NO APLICA") -> 15 | Q19: 46059 | R19: =+Q19+T19 -> 46074 | S19: 46080 | T19: 15 | U19: =WORKDAY(Q19,T19,Feriados!$J$2:$J$22) -> 46080 | V19: =+S19-Q19 -> 21 | W19: =IF(NETWORKDAYS(Q19,S19,Feriados!$J$2:$J$22)-1>=0,NETWORKDAYS(Q19,S19,Feriados!$J$2:$J$22)-1,"NO APLICA") -> 15 | X19: =SUM(U19-TODAY()) -> -216 | Z19: CNOS NO ENROLADOS | AB19: NO | AC19: TRANSPORTE
A20: 19 | B20: 31 | C20: =IF(ISERROR(VLOOKUP(I20,[1]DEP!$B$3:$E$583,1,FALSE)),"NO","SI") -> NO | D20: =IF(ISERROR(VLOOKUP(I20,[2]FRG!$S$19:$U$288,1,FALSE)),"NO","SI") -> NO | E20: =IF(ISERROR(VLOOKUP(I20,[3]DATOS_PREINVERSION!$O$3:$R$475,1,FALSE)),"NO","SI") -> SI | F20: CHILOÉ | G20: QUEMCHI | H20: MUNICIPALIDAD QUEMCHI | I20: 40074153 | J20: CONSERVACION PERIÓDICA RUTA W-21 ZONA URBANA COMUNA DE QUEMCHI | K20: 662550000 | L20: Fabián Rutte | M20: OBSERVADO | N20: 46062 | O20: 46080 | P20: =IF(NETWORKDAYS(N20,O20,Feriados!$J$2:$J$22)-1>=0,NETWORKDAYS(N20,O20,Feriados!$J$2:$J$22)-1,"NO APLICA") -> 14 | Q20: 46062 | R20: =+Q20+T20 -> 46077 | S20: 46080 | T20: 15 | U20: =WORKDAY(Q20,T20,Feriados!$J$2:$J$22) -> 46083 | V20: =+S20-Q20 -> 18 | W20: =IF(NETWORKDAYS(Q20,S20,Feriados!$J$2:$J$22)-1>=0,NETWORKDAYS(Q20,S20,Feriados!$J$2:$J$22)-1,"NO APLICA") -> 14 | X20: =SUM(U20-TODAY()) -> -213 | Z20: PAV. URBANOS | AB20: NO | AC20: TRANSPORTE
A21: 20 | B21: 29 | C21: =IF(ISERROR(VLOOKUP(I21,[1]DEP!$B$3:$E$583,1,FALSE)),"NO","SI") -> NO | D21: =IF(ISERROR(VLOOKUP(I21,[2]FRG!$S$19:$U$288,1,FALSE)),"NO","SI") -> NO | E21: =IF(ISERROR(VLOOKUP(I21,[3]DATOS_PREINVERSION!$O$3:$R$475,1,FALSE)),"NO","SI") -> SI | F21: X REGION | G21: X REGION | H21: DIRECTEMAR | I21: 40072933 | J21: REEV ADQUISICION UNIDAD DESPLIEGUE POLICIA MARITIMA PARA GOB MARITIMA DE PTO MONTT | K21: 740660000 | L21: Fabián Rutte | M21: CUMPLE RT | N21: 46070 | O21: 46093 | P21: =IF(NETWORKDAYS(N21,O21,Feriados!$J$2:$J$22)-1>=0,NETWORKDAYS(N21,O21,Feriados!$J$2:$J$22)-1,"NO APLICA") -> 17 | Q21: 46168 | R21: =+Q21+T21 -> 46178 | S21: 46093 | T21: 10 | U21: =WORKDAY(Q21,T21,Feriados!$J$2:$J$22) -> 46182 | V21: =+S21-Q21 -> -75 | W21: =IF(NETWORKDAYS(Q21,S21,Feriados!$J$2:$J$22)-1>=0,NETWORKDAYS(Q21,S21,Feriados!$J$2:$J$22)-1,"NO APLICA") -> NO APLICA | X21: =SUM(U21-TODAY()) -> -114 | Y21: 494/13-03-2026 | Z21: ARMADA | AB21: SI | AC21: SEGURIDAD
A22: 21 | B22: 29 | C22: =IF(ISERROR(VLOOKUP(I22,[1]DEP!$B$3:$E$583,1,FALSE)),"NO","SI") -> NO | D22: =IF(ISERROR(VLOOKUP(I22,[2]FRG!$S$19:$U$288,1,FALSE)),"NO","SI") -> NO | E22: =IF(ISERROR(VLOOKUP(I22,[3]DATOS_PREINVERSION!$O$3:$R$475,1,FALSE)),"NO","SI") -> SI | F22: LLANQUIHUE | G22: LOS MUERMOS | H22: MUNICIPALIDAD LOS MUERMOS | I22: 40059805 | J22: ADQUISICION CAMIÓN ALJIBE, COMUNA DE LOS MUERMOS | K22: 213852000 | L22: Fabián Rutte | M22: RT FIRMA | N22: 46065 | O22: 46084 | P22: =IF(NETWORKDAYS(N22,O22,Feriados!$J$2:$J$22)-1>=0,NETWORKDAYS(N22,O22,Feriados!$J$2:$J$22)-1,"NO APLICA") -> 13 | Q22: 46251 | R22: =+Q22+T22 -> 46266 | S22: 46275 | T22: 15 | U22: =WORKDAY(Q22,T22,Feriados!$J$2:$J$22) -> 46272 | V22: =+S22-Q22 -> 24 | W22: =IF(NETWORKDAYS(Q22,S22,Feriados!$J$2:$J$22)-1>=0,NETWORKDAYS(Q22,S22,Feriados!$J$2:$J$22)-1,"NO APLICA") -> 18 | X22: =SUM(U22-TODAY()) -> -24 | Z22: ALJIBE | AB22: NO | AC22: RECURSOS NATURALES Y MEDIO AMBIENTE / MEDIO AMBIENTE
A23: 22 | B23: 29 | C23: =IF(ISERROR(VLOOKUP(I23,[1]DEP!$B$3:$E$583,1,FALSE)),"NO","SI") -> NO | D23: =IF(ISERROR(VLOOKUP(I23,[2]FRG!$S$19:$U$288,1,FALSE)),"NO","SI") -> NO | E23: =IF(ISERROR(VLOOKUP(I23,[3]DATOS_PREINVERSION!$O$3:$R$475,1,FALSE)),"NO","SI") -> NO | F23: X REGION | G23: X REGION | H23: REGION POLICIAL LOS LAGOS PDI | I23: 40077203 | J23: ADQUISICION DE EQUIPAMIENTO PERICIAL PARA SS, SERCRIM - REPOLAG | K23: 1033592000 | L23: Fabián Rutte | M23: RT FIRMA | N23: 46076 | O23: 46092 | P23: =IF(NETWORKDAYS(N23,O23,Feriados!$J$2:$J$22)-1>=0,NETWORKDAYS(N23,O23,Feriados!$J$2:$J$22)-1,"NO APLICA") -> 12 | Q23: 46216 | R23: =+Q23+T23 -> 46231 | S23: 46244 | T23: 15 | U23: =WORKDAY(Q23,T23,Feriados!$J$2:$J$22) -> 46238 | V23: =+S23-Q23 -> 28 | W23: =IF(NETWORKDAYS(Q23,S23,Feriados!$J$2:$J$22)-1>=0,NETWORKDAYS(Q23,S23,Feriados!$J$2:$J$22)-1,"NO APLICA") -> 19 | X23: =SUM(U23-TODAY()) -> -58 | Z23: EQ. POL | AB23: NO | AC23: SEGURIDAD
A24: 23 | B24: 29 | C24: =IF(ISERROR(VLOOKUP(I24,[1]DEP!$B$3:$E$583,1,FALSE)),"NO","SI") -> NO | D24: =IF(ISERROR(VLOOKUP(I24,[2]FRG!$S$19:$U$288,1,FALSE)),"NO","SI") -> NO | E24: =IF(ISERROR(VLOOKUP(I24,[3]DATOS_PREINVERSION!$O$3:$R$475,1,FALSE)),"NO","SI") -> SI | F24: CHILOÉ | G24: QUELLÓN | H24: MUNICIPALIDAD QUELLÓN | I24: 40078361 | J24: ADQUISICION Y REPOSICIÓN CAMIONES Y CONTENEDORES RSD | K24: 1497000000 | L24: Fabián Rutte | M24: FIRMA OBS | N24: 46064 | O24: 46085 | P24: =IF(NETWORKDAYS(N24,O24,Feriados!$J$2:$J$22)-1>=0,NETWORKDAYS(N24,O24,Feriados!$J$2:$J$22)-1,"NO APLICA") -> 15 | Q24: 46188 | R24: =+Q24+T24 -> 46203 | S24: 46223 | T24: 15 | U24: =WORKDAY(Q24,T24,Feriados!$J$2:$J$22) -> 46210 | V24: =+S24-Q24 -> 35 | W24: =IF(NETWORKDAYS(Q24,S24,Feriados!$J$2:$J$22)-1>=0,NETWORKDAYS(Q24,S24,Feriados!$J$2:$J$22)-1,"NO APLICA") -> 23 | X24: =SUM(U24-TODAY()) -> -86 | Z24: CAMIONES RSD | AB24: NO | AC24: RECURSOS NATURALES Y MEDIO AMBIENTE / MEDIO AMBIENTE
A25: 24 | B25: 22 | C25: =IF(ISERROR(VLOOKUP(I25,[1]DEP!$B$3:$E$583,1,FALSE)),"NO","SI") -> NO | D25: =IF(ISERROR(VLOOKUP(I25,[2]FRG!$S$19:$U$288,1,FALSE)),"NO","SI") -> NO | E25: =IF(ISERROR(VLOOKUP(I25,[3]DATOS_PREINVERSION!$O$3:$R$475,1,FALSE)),"NO","SI") -> NO | F25: X REGION | G25: X REGION | H25: GORE LOS LAGOS | I25: 40078276 | J25: DIAGNOSTICO ECOSISTEMA INTEGRADO TELEVIGILANCIA EN LAS COMUNAS DE LA REGION DE LOS LAGOS | K25: 220000000 | L25: Fabián Rutte | M25: DIPRES | N25: 46059 | O25: 46059 | P25: =IF(NETWORKDAYS(N25,O25,Feriados!$J$2:$J$22)-1>=0,NETWORKDAYS(N25,O25,Feriados!$J$2:$J$22)-1,"NO APLICA") -> 0 | Q25: 46059 | R25: =+Q25+T25 -> 46074 | S25: 46059 | T25: 15 | U25: =WORKDAY(Q25,T25,Feriados!$J$2:$J$22) -> 46080 | V25: =+S25-Q25 -> 0 | W25: =IF(NETWORKDAYS(Q25,S25,Feriados!$J$2:$J$22)-1>=0,NETWORKDAYS(Q25,S25,Feriados!$J$2:$J$22)-1,"NO APLICA") -> 0 | X25: =SUM(U25-TODAY()) -> -216 | Z25: EPG | AB25: NO | AC25: SEGURIDAD
A26: 25 | B26: 22 | C26: =IF(ISERROR(VLOOKUP(I26,[1]DEP!$B$3:$E$583,1,FALSE)),"NO","SI") -> NO | D26: =IF(ISERROR(VLOOKUP(I26,[2]FRG!$S$19:$U$288,1,FALSE)),"NO","SI") -> NO | E26: =IF(ISERROR(VLOOKUP(I26,[3]DATOS_PREINVERSION!$O$3:$R$475,1,FALSE)),"NO","SI") -> NO | F26: X REGION | G26: X REGION | H26: GORE LOS LAGOS | I26: 40076970 | J26: ACTUALIZACION POLITICA DE TURISMO E IMAGEN REGION. | K26: 146000000 | L26: Fabián Rutte | M26: DIPRES | N26: 46077 | O26: 46084 | P26: =IF(NETWORKDAYS(N26,O26,Feriados!$J$2:$J$22)-1>=0,NETWORKDAYS(N26,O26,Feriados!$J$2:$J$22)-1,"NO APLICA") -> 5 | Q26: 46077 | R26: =+Q26+T26 -> 46092 | S26: 46084 | T26: 15 | U26: =WORKDAY(Q26,T26,Feriados!$J$2:$J$22) -> 46098 | V26: =+S26-Q26 -> 7 | W26: =IF(NETWORKDAYS(Q26,S26,Feriados!$J$2:$J$22)-1>=0,NETWORKDAYS(Q26,S26,Feriados!$J$2:$J$22)-1,"NO APLICA") -> 5 | X26: =SUM(U26-TODAY()) -> -198 | Z26: EPG | AB26: NO | AC26: TURISMO
A27: 26 | B27: 29 | C27: =IF(ISERROR(VLOOKUP(I27,[1]DEP!$B$3:$E$583,1,FALSE)),"NO","SI") -> NO | D27: =IF(ISERROR(VLOOKUP(I27,[2]FRG!$S$19:$U$288,1,FALSE)),"NO","SI") -> NO | E27: =IF(ISERROR(VLOOKUP(I27,[3]DATOS_PREINVERSION!$O$3:$R$475,1,FALSE)),"NO","SI") -> NO | F27: PALENA | G27: HUALAIHUÉ | H27: MUNICIPALIDAD HUALAIHUÉ | I27: 40066280 | J27: REPOSICION CAMIONETAS MUNICIPALES PARA TRASLADO DE FUNCIONARIOS, COMUNA DE HUALAIHUÉ | K27: 121569000 | L27: Fabián Rutte | M27: CUMPLE RT | N27: 46080 | O27: 46097 | P27: =IF(NETWORKDAYS(N27,O27,Feriados!$J$2:$J$22)-1>=0,NETWORKDAYS(N27,O27,Feriados!$J$2:$J$22)-1,"NO APLICA") -> 11 | Q27: 46080 | R27: =+Q27+T27 -> 46095 | S27: 46097 | T27: 15 | U27: =WORKDAY(Q27,T27,Feriados!$J$2:$J$22) -> 46101 | V27: =+S27-Q27 -> 17 | W27: =IF(NETWORKDAYS(Q27,S27,Feriados!$J$2:$J$22)-1>=0,NETWORKDAYS(Q27,S27,Feriados!$J$2:$J$22)-1,"NO APLICA") -> 11 | X27: =SUM(U27-TODAY()) -> -195 | Y27: 512/16-03-2026 | Z27: VEHICULOS | AB27: NO | AC27: MULTISECTORIAL
A28: 27 | B28: 29 | C28: =IF(ISERROR(VLOOKUP(I28,[1]DEP!$B$3:$E$583,1,FALSE)),"NO","SI") -> NO | D28: =IF(ISERROR(VLOOKUP(I28,[2]FRG!$S$19:$U$288,1,FALSE)),"NO","SI") -> NO | E28: =IF(ISERROR(VLOOKUP(I28,[3]DATOS_PREINVERSION!$O$3:$R$475,1,FALSE)),"NO","SI") -> SI | F28: OSORNO | G28: OSORNO | H28: SERVICIO SALUD OSORNO | I28: 40076844 | J28: REPOSICION Y ADQUISICION EQUIPOS Y EQUIPAMIENTO URGENCIA PEDIATRICA HBO | K28: 231800000 | L28: Fabián Rutte | M28: RT FIRMA | N28: 46083 | O28: 46094 | P28: =IF(NETWORKDAYS(N28,O28,Feriados!$J$2:$J$22)-1>=0,NETWORKDAYS(N28,O28,Feriados!$J$2:$J$22)-1,"NO APLICA") -> 9 | Q28: 46225 | R28: =+Q28+T28 -> 46240 | S28: 46258 | T28: 15 | U28: =WORKDAY(Q28,T28,Feriados!$J$2:$J$22) -> 46246 | V28: =+S28-Q28 -> 33 | W28: =IF(NETWORKDAYS(Q28,S28,Feriados!$J$2:$J$22)-1>=0,NETWORKDAYS(Q28,S28,Feriados!$J$2:$J$22)-1,"NO APLICA") -> 23 | X28: =SUM(U28-TODAY()) -> -50 | Z28: EQ. SALUD | AB28: NO | AC28: SALUD
A29: 28 | B29: 29 | C29: =IF(ISERROR(VLOOKUP(I29,[1]DEP!$B$3:$E$583,1,FALSE)),"NO","SI") -> NO | D29: =IF(ISERROR(VLOOKUP(I29,[2]FRG!$S$19:$U$288,1,FALSE)),"NO","SI") -> NO | E29: =IF(ISERROR(VLOOKUP(I29,[3]DATOS_PREINVERSION!$O$3:$R$475,1,FALSE)),"NO","SI") -> SI | F29: CHILOÉ | G29: CASTRO | H29: SERVICIO SALUD CHILOÉ | I29: 40075714 | J29: REPOSICION Y ADQUISICIÓN DE EQUIPOS Y EQUIPAMIENTO PLAN DE CÁNCER DEL HOSPITAL DE CASTRO | K29: 2406161000 | L29: Fabián Rutte | M29: CUMPLE RT | N29: 46083 | O29: 46101 | P29: =IF(NETWORKDAYS(N29,O29,Feriados!$J$2:$J$22)-1>=0,NETWORKDAYS(N29,O29,Feriados!$J$2:$J$22)-1,"NO APLICA") -> 14 | Q29: 46140 | R29: =+Q29+T29 -> 46155 | S29: 46153 | T29: 15 | U29: =WORKDAY(Q29,T29,Feriados!$J$2:$J$22) -> 46162 | V29: =+S29-Q29 -> 13 | W29: =IF(NETWORKDAYS(Q29,S29,Feriados!$J$2:$J$22)-1>=0,NETWORKDAYS(Q29,S29,Feriados!$J$2:$J$22)-1,"NO APLICA") -> 8 | X29: =SUM(U29-TODAY()) -> -134 | Y29: 1.070/11-05-2026 | Z29: EQ. SALUD | AB29: NO | AC29: SALUD
A30: 29 | B30: 29 | C30: =IF(ISERROR(VLOOKUP(I30,[1]DEP!$B$3:$E$583,1,FALSE)),"NO","SI") -> SI | D30: =IF(ISERROR(VLOOKUP(I30,[2]FRG!$S$19:$U$288,1,FALSE)),"NO","SI") -> NO | E30: =IF(ISERROR(VLOOKUP(I30,[3]DATOS_PREINVERSION!$O$3:$R$475,1,FALSE)),"NO","SI") -> SI | F30: LLANQUIHUE | G30: LLANQUIHUE | H30: MUNICIPALIDAD LLANQUIHUE | I30: 40032936 | J30: REPOSICION DE DOS CAMIONES RSD Y ADQUISICION DE UN CAMION RSD, COMUNA DE LLANQUIHUE | K30: 611898000 | L30: Fabián Rutte | M30: FIRMA OBS | N30: 46083 | O30: 46105 | P30: =IF(NETWORKDAYS(N30,O30,Feriados!$J$2:$J$22)-1>=0,NETWORKDAYS(N30,O30,Feriados!$J$2:$J$22)-1,"NO APLICA") -> 16 | Q30: 46240 | R30: =+Q30+T30 -> 46255 | S30: 46269 | T30: 15 | U30: =WORKDAY(Q30,T30,Feriados!$J$2:$J$22) -> 46261 | V30: =+S30-Q30 -> 29 | W30: =IF(NETWORKDAYS(Q30,S30,Feriados!$J$2:$J$22)-1>=0,NETWORKDAYS(Q30,S30,Feriados!$J$2:$J$22)-1,"NO APLICA") -> 21 | X30: =SUM(U30-TODAY()) -> -35 | Z30: CAMIONES RSD | AB30: NO | AC30: RECURSOS NATURALES Y MEDIO AMBIENTE / MEDIO AMBIENTE
A31: 30 | B31: 29 | C31: =IF(ISERROR(VLOOKUP(I31,[1]DEP!$B$3:$E$583,1,FALSE)),"NO","SI") -> NO | D31: =IF(ISERROR(VLOOKUP(I31,[2]FRG!$S$19:$U$288,1,FALSE)),"NO","SI") -> NO | E31: =IF(ISERROR(VLOOKUP(I31,[3]DATOS_PREINVERSION!$O$3:$R$475,1,FALSE)),"NO","SI") -> SI | F31: OSORNO | G31: SAN PABLO | H31: MUNICIPALIDAD SAN PABLO | I31: 40077191 | J31: REPOSICION DOS AMBULANCIAS DE LA COMUNA DE SAN PABLO | K31: 261800000 | L31: Fabián Rutte | M31: CUMPLE RT | N31: 46090 | O31: 46092 | P31: =IF(NETWORKDAYS(N31,O31,Feriados!$J$2:$J$22)-1>=0,NETWORKDAYS(N31,O31,Feriados!$J$2:$J$22)-1,"NO APLICA") -> 2 | Q31: 46141 | R31: =+Q31+T31 -> 46156 | S31: 46132 | T31: 15 | U31: =WORKDAY(Q31,T31,Feriados!$J$2:$J$22) -> 46164 | V31: =+S31-Q31 -> -9 | W31: =IF(NETWORKDAYS(Q31,S31,Feriados!$J$2:$J$22)-1>=0,NETWORKDAYS(Q31,S31,Feriados!$J$2:$J$22)-1,"NO APLICA") -> NO APLICA | X31: =SUM(U31-TODAY()) -> -132 | Y31: 1.252/25-05-2026 | Z31: AMBULANCIAS | AB31: NO | AC31: SALUD
A32: 31 | B32: 29 | C32: =IF(ISERROR(VLOOKUP(I32,[1]DEP!$B$3:$E$583,1,FALSE)),"NO","SI") -> SI | D32: =IF(ISERROR(VLOOKUP(I32,[2]FRG!$S$19:$U$288,1,FALSE)),"NO","SI") -> NO | E32: =IF(ISERROR(VLOOKUP(I32,[3]DATOS_PREINVERSION!$O$3:$R$475,1,FALSE)),"NO","SI") -> SI | F32: CHILOÉ | G32: CASTRO | H32: MUNICIPALIDAD CASTRO | I32: 40043234 | J32: REPOSICIÓN MAQUINARIA MUNICIPAL, COMUNA DE CASTRO | K32: 1823354000 | L32: Fabián Rutte | M32: CUMPLE RT | N32: 46098 | O32: 46113 | P32: =IF(NETWORKDAYS(N32,O32,Feriados!$J$2:$J$22)-1>=0,NETWORKDAYS(N32,O32,Feriados!$J$2:$J$22)-1,"NO APLICA") -> 11 | Q32: 46139 | R32: =+Q32+T32 -> 46154 | S32: 46168 | T32: 15 | U32: =WORKDAY(Q32,T32,Feriados!$J$2:$J$22) -> 46161 | V32: =+S32-Q32 -> 29 | W32: =IF(NETWORKDAYS(Q32,S32,Feriados!$J$2:$J$22)-1>=0,NETWORKDAYS(Q32,S32,Feriados!$J$2:$J$22)-1,"NO APLICA") -> 19 | X32: =SUM(U32-TODAY()) -> -135 | Y32: 1.273/27-05-2026 | Z32: MAQ. CNOS | AB32: NO | AC32: TRANSPORTE
A33: 32 | B33: 29 | C33: =IF(ISERROR(VLOOKUP(I33,[1]DEP!$B$3:$E$583,1,FALSE)),"NO","SI") -> NO | D33: =IF(ISERROR(VLOOKUP(I33,[2]FRG!$S$19:$U$288,1,FALSE)),"NO","SI") -> NO | E33: =IF(ISERROR(VLOOKUP(I33,[3]DATOS_PREINVERSION!$O$3:$R$475,1,FALSE)),"NO","SI") -> SI | F33: LLANQUIHUE | G33: FRUTILLAR | H33: MUNICIPALIDAD FRUTILLAR | I33: 40070081 | J33: CONSERVACION GIMNASIO MUNICIPAL DE CASMA | K33: 677430000 | L33: Fabián Rutte | M33: EN EVALUACIÓN | N33: 46099 | O33: 46121 | P33: =IF(NETWORKDAYS(N33,O33,Feriados!$J$2:$J$22)-1>=0,NETWORKDAYS(N33,O33,Feriados!$J$2:$J$22)-1,"NO APLICA") -> 15 | Q33: 46254 | R33: =+Q33+T33 -> 46269 | S33: 46226 | T33: 15 | U33: =WORKDAY(Q33,T33,Feriados!$J$2:$J$22) -> 46275 | V33: =+S33-Q33 -> -28 | W33: =IF(NETWORKDAYS(Q33,S33,Feriados!$J$2:$J$22)-1>=0,NETWORKDAYS(Q33,S33,Feriados!$J$2:$J$22)-1,"NO APLICA") -> NO APLICA | X33: =SUM(U33-TODAY()) -> -21 | Z33: DEPORTE CONSERVACION | AB33: NO | AC33: DEPORTE
A34: 33 | B34: 31 | C34: =IF(ISERROR(VLOOKUP(I34,[1]DEP!$B$3:$E$583,1,FALSE)),"NO","SI") -> NO | D34: =IF(ISERROR(VLOOKUP(I34,[2]FRG!$S$19:$U$288,1,FALSE)),"NO","SI") -> NO | E34: =IF(ISERROR(VLOOKUP(I34,[3]DATOS_PREINVERSION!$O$3:$R$475,1,FALSE)),"NO","SI") -> SI | F34: OSORNO | G34: PUERTO OCTAY | H34: MUNICIPALIDAD PUERTO OCTAY | I34: 40072903 | J34: CONSERVACION CAMINOS NO ENROLADOS SECTORES LAS JUNTAS, EL ESCUDO Y NOCHACO, COMUNA DE PUERTO OCTAY | K34: 403384000 | L34: Fabián Rutte | M34: EN EVALUACIÓN | N34: 46100 | O34: 46126 | P34: =IF(NETWORKDAYS(N34,O34,Feriados!$J$2:$J$22)-1>=0,NETWORKDAYS(N34,O34,Feriados!$J$2:$J$22)-1,"NO APLICA") -> 17 | Q34: 46267 | R34: =+Q34+T34 -> 46282 | S34: 46126 | T34: 15 | U34: =WORKDAY(Q34,T34,Feriados!$J$2:$J$22) -> 46289 | V34: =+S34-Q34 -> -141 | W34: =IF(NETWORKDAYS(Q34,S34,Feriados!$J$2:$J$22)-1>=0,NETWORKDAYS(Q34,S34,Feriados!$J$2:$J$22)-1,"NO APLICA") -> NO APLICA | X34: =SUM(U34-TODAY()) -> -7 | Z34: CNOS NO ENROLADOS | AB34: NO | AC34: TRANSPORTE
A35: 34 | B35: 29 | C35: =IF(ISERROR(VLOOKUP(I35,[1]DEP!$B$3:$E$583,1,FALSE)),"NO","SI") -> NO | D35: =IF(ISERROR(VLOOKUP(I35,[2]FRG!$S$19:$U$288,1,FALSE)),"NO","SI") -> NO | E35: =IF(ISERROR(VLOOKUP(I35,[3]DATOS_PREINVERSION!$O$3:$R$475,1,FALSE)),"NO","SI") -> SI | F35: OSORNO | G35: PUERTO OCTAY | H35: MUNICIPALIDAD PUERTO OCTAY | I35: 40078495 | J35: ADQUISICION Y REPOSICIÓN DE VEHICULOS MUNICIPALES, COMUNA DE PUERTO OCTAY. | K35: 161986000 | L35: Fabián Rutte | M35: EN EVALUACIÓN | N35: 46100 | O35: 46119 | P35: =IF(NETWORKDAYS(N35,O35,Feriados!$J$2:$J$22)-1>=0,NETWORKDAYS(N35,O35,Feriados!$J$2:$J$22)-1,"NO APLICA") -> 12 | Q35: 46281 | R35: =+Q35+T35 -> 46296 | S35: 46237 | T35: 15 | U35: =WORKDAY(Q35,T35,Feriados!$J$2:$J$22) -> 46303 | V35: =+S35-Q35 -> -44 | W35: =IF(NETWORKDAYS(Q35,S35,Feriados!$J$2:$J$22)-1>=0,NETWORKDAYS(Q35,S35,Feriados!$J$2:$J$22)-1,"NO APLICA") -> NO APLICA | X35: =SUM(U35-TODAY()) -> 7 | Z35: VEHICULOS | AB35: NO | AC35: TRANSPORTE
A36: 35 | B36: 22 | C36: =IF(ISERROR(VLOOKUP(I36,[1]DEP!$B$3:$E$583,1,FALSE)),"NO","SI") -> NO | D36: =IF(ISERROR(VLOOKUP(I36,[2]FRG!$S$19:$U$288,1,FALSE)),"NO","SI") -> NO | E36: =IF(ISERROR(VLOOKUP(I36,[3]DATOS_PREINVERSION!$O$3:$R$475,1,FALSE)),"NO","SI") -> SI | F36: CHILOÉ | G36: QUELLÓN | H36: MUNICIPALIDAD QUELLÓN | I36: 40048803 | J36: ACTUALIZACION PLAN REGULADOR COMUNAL DE QUELLON | K36: 400000000 | L36: Fabián Rutte | M36: DIPRES | N36: 46108 | P36: =IF(NETWORKDAYS(N36,O36,Feriados!$J$2:$J$22)-1>=0,NETWORKDAYS(N36,O36,Feriados!$J$2:$J$22)-1,"NO APLICA") -> NO APLICA | Q36: 46108 | R36: =+Q36+T36 -> 46123 | T36: 15 | U36: =WORKDAY(Q36,T36,Feriados!$J$2:$J$22) -> 46132 | V36: =+S36-Q36 -> -46108 | W36: =IF(NETWORKDAYS(Q36,S36,Feriados!$J$2:$J$22)-1>=0,NETWORKDAYS(Q36,S36,Feriados!$J$2:$J$22)-1,"NO APLICA") -> NO APLICA | X36: =SUM(U36-TODAY()) -> -164 | Z36: EPG | AB36: NO | AC36: VIVIENDA Y URBANISMO
A37: 36 | B37: 31 | C37: =IF(ISERROR(VLOOKUP(I37,[1]DEP!$B$3:$E$583,1,FALSE)),"NO","SI") -> SI | D37: =IF(ISERROR(VLOOKUP(I37,[2]FRG!$S$19:$U$288,1,FALSE)),"NO","SI") -> SI | E37: =IF(ISERROR(VLOOKUP(I37,[3]DATOS_PREINVERSION!$O$3:$R$475,1,FALSE)),"NO","SI") -> NO | F37: OSORNO | G37: RÍO NEGRO | H37: MUNICIPALIDAD RÍO NEGRO | I37: 40032117 | J37: REEV CONSERVACION CAMINOS VECINALES DE ÑANCUÁN CHANCHAN, SAN FLORENTINO Y QUISQUELELFUN, RÍO NEGRO | K37: 923194000 | L37: Fabián Rutte | M37: CUMPLE RT | P37: =IF(NETWORKDAYS(N37,O37,Feriados!$J$2:$J$22)-1>=0,NETWORKDAYS(N37,O37,Feriados!$J$2:$J$22)-1,"NO APLICA") -> NO APLICA | Q37: 46182 | R37: =+Q37+T37 -> 46192 | S37: 46184 | T37: 10 | U37: =WORKDAY(Q37,T37,Feriados!$J$2:$J$22) -> 46196 | V37: =+S37-Q37 -> 2 | W37: =IF(NETWORKDAYS(Q37,S37,Feriados!$J$2:$J$22)-1>=0,NETWORKDAYS(Q37,S37,Feriados!$J$2:$J$22)-1,"NO APLICA") -> 2 | X37: =SUM(U37-TODAY()) -> -100 | Y37: 2.645/25-10-2024 | Z37: CNOS NO ENROLADOS | AB37: SI | AC37: TRANSPORTE
A38: 37 | B38: 29 | C38: =IF(ISERROR(VLOOKUP(I38,[1]DEP!$B$3:$E$583,1,FALSE)),"NO","SI") -> NO | D38: =IF(ISERROR(VLOOKUP(I38,[2]FRG!$S$19:$U$288,1,FALSE)),"NO","SI") -> NO | E38: =IF(ISERROR(VLOOKUP(I38,[3]DATOS_PREINVERSION!$O$3:$R$475,1,FALSE)),"NO","SI") -> NO | F38: OSORNO | G38: OSORNO | H38: SERVICIO SALUD OSORNO | I38: 50000472 | J38: REPOSICIÓN EQUIPOS Y EQUIPAMIENTO PABELLÓN Y POST OPERADO HOSPITAL BASE SAN JOSÉ DE OSORNO, SSO | K38: 2784569000 | L38: Fabián Rutte | M38: OBSERVADO | N38: 46120 | O38: 46141 | P38: =IF(NETWORKDAYS(N38,O38,Feriados!$J$2:$J$22)-1>=0,NETWORKDAYS(N38,O38,Feriados!$J$2:$J$22)-1,"NO APLICA") -> 15 | Q38: 46120 | R38: =+Q38+T38 -> 46135 | S38: 46141 | T38: 15 | U38: =WORKDAY(Q38,T38,Feriados!$J$2:$J$22) -> 46141 | V38: =+S38-Q38 -> 21 | W38: =IF(NETWORKDAYS(Q38,S38,Feriados!$J$2:$J$22)-1>=0,NETWORKDAYS(Q38,S38,Feriados!$J$2:$J$22)-1,"NO APLICA") -> 15 | X38: =SUM(U38-TODAY()) -> -155 | Z38: MAQ. CNOS | AB38: NO | AC38: TRANSPORTE
A39: 38 | B39: 29 | C39: =IF(ISERROR(VLOOKUP(I39,[1]DEP!$B$3:$E$583,1,FALSE)),"NO","SI") -> NO | D39: =IF(ISERROR(VLOOKUP(I39,[2]FRG!$S$19:$U$288,1,FALSE)),"NO","SI") -> NO | E39: =IF(ISERROR(VLOOKUP(I39,[3]DATOS_PREINVERSION!$O$3:$R$475,1,FALSE)),"NO","SI") -> SI | F39: PALENA | G39: CHAITÉN | H39: MUNICIPALIDAD CHAITÉN | I39: 40078825 | J39: EQUIPAMIENTO ADQUISICIÓN EQUIPOS Y EQUIPAMIENTO PARA POSTAS DE SALUD RURAL COMUNA DE CHAITÉN | K39: 758810000 | L39: Fabián Rutte | M39: OBSERVADO | N39: 46128 | O39: 46153 | P39: =IF(NETWORKDAYS(N39,O39,Feriados!$J$2:$J$22)-1>=0,NETWORKDAYS(N39,O39,Feriados!$J$2:$J$22)-1,"NO APLICA") -> 16 | Q39: 46128 | R39: =+Q39+T39 -> 46143 | S39: 46153 | T39: 15 | U39: =WORKDAY(Q39,T39,Feriados!$J$2:$J$22) -> 46150 | V39: =+S39-Q39 -> 25 | W39: =IF(NETWORKDAYS(Q39,S39,Feriados!$J$2:$J$22)-1>=0,NETWORKDAYS(Q39,S39,Feriados!$J$2:$J$22)-1,"NO APLICA") -> 16 | X39: =SUM(U39-TODAY()) -> -146 | Z39: EQ. SALUD | AB39: NO | AC39: TRANSPORTE
A40: 39 | B40: 31 | C40: =IF(ISERROR(VLOOKUP(I40,[1]DEP!$B$3:$E$583,1,FALSE)),"NO","SI") -> NO | D40: =IF(ISERROR(VLOOKUP(I40,[2]FRG!$S$19:$U$288,1,FALSE)),"NO","SI") -> NO | E40: =IF(ISERROR(VLOOKUP(I40,[3]DATOS_PREINVERSION!$O$3:$R$475,1,FALSE)),"NO","SI") -> SI | F40: OSORNO | G40: PURRANQUE | H40: MUNICIPALIDAD PURRANQUE | I40: 40055184 | J40: CONSERVACION VEREDAS SECTOR AGUAS ANDINAS COMUNA DE PURRANQUE | K40: 526496242 | L40: Fabián Rutte | M40: OBSERVADO | N40: 46127 | O40: 46148 | P40: =IF(NETWORKDAYS(N40,O40,Feriados!$J$2:$J$22)-1>=0,NETWORKDAYS(N40,O40,Feriados!$J$2:$J$22)-1,"NO APLICA") -> 14 | Q40: 46127 | R40: =+Q40+T40 -> 46142 | S40: 46148 | T40: 15 | U40: =WORKDAY(Q40,T40,Feriados!$J$2:$J$22) -> 46149 | V40: =+S40-Q40 -> 21 | W40: =IF(NETWORKDAYS(Q40,S40,Feriados!$J$2:$J$22)-1>=0,NETWORKDAYS(Q40,S40,Feriados!$J$2:$J$22)-1,"NO APLICA") -> 14 | X40: =SUM(U40-TODAY()) -> -147 | Z40: VEREDAS | AB40: NO | AC40: VIVIENDA Y URBANISMO
...

Sheet 2025
A1: CANT | B1: SUBT. | C1: ARI 2023 | D1: PPTO 2025 | E1: ARI 2026 | F1: PROVINCIA | G1: COMUNA | H1: FORMULADOR | I1: BIP | J1: NOMBRE DE LA INICIATIVA | K1: COSTO | L1: EVALUADOR | M1: ESTADO | N1: FECHA 1er INGRESO | O1: FECHA 1er Respuesta | P1: DÍAS 1° Evaluación | Q1: FECHA INGRESO | R1: PLAZO PARA INFORMAR (15 DIAS) | S1: FECHA EVALUACION | T1: DIAS EVALUAR | U1: FECHA (REAL) ENTREGA | V1: DIAS EN EVALUACION | W1: DIAS HAB. EN EVALUACION | X1: DIAS RESTANTES | Y1: ORD GR N°/ FECHA | Z1: CLASIFICACION | AA1: BENEFICIARIOS DIRECTOS | AB1: ¿ES REEVALUACION? | AC1: SECTOR (SNI)
A2: 1 | B2: 31 | C2: =IF(ISERROR(VLOOKUP(I2,[1]DEP!$B$3:$E$583,1,FALSE)),"NO","SI") -> SI | D2: =IF(ISERROR(VLOOKUP(I2,[2]FRG!$S$19:$U$288,1,FALSE)),"NO","SI") -> SI | E2: =IF(ISERROR(VLOOKUP(I2,'[4]ARI 26 C33'!$C$1:$D$490,1,FALSE)),"NO","SI") -> NO | F2: OSORNO | G2: PUYEHUE | H2: MUNICIPALIDAD PUYEHUE | I2: 40018788 | J2: REEV CONSERVACION CAMINOS NO ENROLADOS 12 SECTORES RURALES DE LA COMUNA DE PUYEHUE | K2: 633888000 | L2: Fabián Rutte | M2: OBSERVADO | P2: =IF(NETWORKDAYS(N2,O2,Feriados!$I$2:$I$22)-1>=0,NETWORKDAYS(N2,O2,Feriados!$I$2:$I$22)-1,"NO APLICA") -> NO APLICA | Q2: 45649 | R2: =+Q2+T2 -> 45659 | S2: 45665 | T2: 10 | U2: =WORKDAY(Q2,T2,Feriados!$I$2:$I$22) -> 45664 | V2: =+S2-Q2 -> 16 | W2: =IF(NETWORKDAYS(Q2,S2,Feriados!$I$2:$I$22)-1>=0,NETWORKDAYS(Q2,S2,Feriados!$I$2:$I$22)-1,"NO APLICA") -> 11 | X2: =SUM(U2-TODAY()) -> -632 | Y2: 190/30-01-2023 | Z2: CNOS NO ENROLADOS | AA2: 608 | AB2: SI | AC2: TRANSPORTE
A3: 2 | B3: 29 | C3: =IF(ISERROR(VLOOKUP(I3,[1]DEP!$B$3:$E$583,1,FALSE)),"NO","SI") -> NO | D3: =IF(ISERROR(VLOOKUP(I3,[2]FRG!$S$19:$U$288,1,FALSE)),"NO","SI") -> NO | E3: =IF(ISERROR(VLOOKUP(I3,'[4]ARI 26 C33'!$C$1:$D$490,1,FALSE)),"NO","SI") -> NO | F3: =+IFERROR(VLOOKUP(G3,Feriados!$M$1:$N$36,2,FALSE),"") -> REGIONAL | G3: REGIONAL | H3: CONAF | I3: 40062961 | J3: REPOSICION EQUIPOS DE RADIO COMUNICACIONES INCENDIOS FORESTALES Y ASP CONAF LOS LAGOS | L3: Fabián Rutte | M3: OBSERVADO | N3: 45664 | O3: 45673 | P3: =IF(NETWORKDAYS(N3,O3,Feriados!$I$2:$I$22)-1>=0,NETWORKDAYS(N3,O3,Feriados!$I$2:$I$22)-1,"NO APLICA") -> 7 | Q3: 45664 | R3: =+Q3+T3 -> 45679 | S3: 45673 | T3: 15 | U3: =WORKDAY(Q3,T3,Feriados!$I$2:$I$22) -> 45685 | V3: =+S3-Q3 -> 9 | W3: =IF(NETWORKDAYS(Q3,S3,Feriados!$I$2:$I$22)-1>=0,NETWORKDAYS(Q3,S3,Feriados!$I$2:$I$22)-1,"NO APLICA") -> 7 | X3: =SUM(U3-TODAY()) -> -611 | Z3: S/C | AB3: NO | AC3: S/C
A4: 3 | B4: 29 | C4: =IF(ISERROR(VLOOKUP(I4,[1]DEP!$B$3:$E$583,1,FALSE)),"NO","SI") -> NO | D4: =IF(ISERROR(VLOOKUP(I4,[2]FRG!$S$19:$U$288,1,FALSE)),"NO","SI") -> NO | E4: =IF(ISERROR(VLOOKUP(I4,'[4]ARI 26 C33'!$C$1:$D$490,1,FALSE)),"NO","SI") -> NO | F4: =+IFERROR(VLOOKUP(G4,Feriados!$M$1:$N$36,2,FALSE),"") -> REGIONAL | G4: REGIONAL | H4: CONAF | I4: 40066004 | J4: REPOSICION DE VEHÍCULOS TIPO CAMIONETAS CONAF | K4: 354012000 | L4: Fabián Rutte | M4: CUMPLE RT | N4: 45664 | O4: 45673 | P4: =IF(NETWORKDAYS(N4,O4,Feriados!$I$2:$I$22)-1>=0,NETWORKDAYS(N4,O4,Feriados!$I$2:$I$22)-1,"NO APLICA") -> 7 | Q4: 45887 | R4: =+Q4+T4 -> 45902 | S4: 45931 | T4: 15 | U4: =WORKDAY(Q4,T4,Feriados!$I$2:$I$22) -> 45908 | V4: =+S4-Q4 -> 44 | W4: =IF(NETWORKDAYS(Q4,S4,Feriados!$I$2:$I$22)-1>=0,NETWORKDAYS(Q4,S4,Feriados!$I$2:$I$22)-1,"NO APLICA") -> 30 | X4: =SUM(U4-TODAY()) -> -388 | Y4: 2.549/02-10-2025 | Z4: VEHICULOS | AB4: NO | AC4: RECURSOS NATURALES Y MEDIO AMBIENTE / MEDIO AMBIENTE
A5: 4 | B5: 29 | C5: =IF(ISERROR(VLOOKUP(I5,[1]DEP!$B$3:$E$583,1,FALSE)),"NO","SI") -> NO | D5: =IF(ISERROR(VLOOKUP(I5,[2]FRG!$S$19:$U$288,1,FALSE)),"NO","SI") -> SI | E5: =IF(ISERROR(VLOOKUP(I5,'[4]ARI 26 C33'!$C$1:$D$490,1,FALSE)),"NO","SI") -> NO | F5: CHILOÉ | G5: PROVINCIAL | H5: DIRECCION DE VIALIDAD | I5: 40057047 | J5: REEV REPOSICION VEHICULOS Y ADQUISICION MAQUINARIA DE ASFALTO PARA LA D. V., PROVINCIA DE CHILOE | K5: 1354107000 | L5: Fabián Rutte | M5: CUMPLE RT | P5: =IF(NETWORKDAYS(N5,O5,Feriados!$I$2:$I$22)-1>=0,NETWORKDAYS(N5,O5,Feriados!$I$2:$I$22)-1,"NO APLICA") -> NO APLICA | Q5: 45947 | R5: =+Q5+T5 -> 45957 | S5: 45971 | T5: 10 | U5: =WORKDAY(Q5,T5,Feriados!$I$2:$I$22) -> 45964 | V5: =+S5-Q5 -> 24 | W5: =IF(NETWORKDAYS(Q5,S5,Feriados!$I$2:$I$22)-1>=0,NETWORKDAYS(Q5,S5,Feriados!$I$2:$I$22)-1,"NO APLICA") -> 15 | X5: =SUM(U5-TODAY()) -> -332 | Y5: 3.646/27-09-2023 | Z5: MAQ. CNOS | AA5: 168185 | AB5: SI | AC5: TRANSPORTE
A6: 5 | B6: 29 | C6: =IF(ISERROR(VLOOKUP(I6,[1]DEP!$B$3:$E$583,1,FALSE)),"NO","SI") -> SI | D6: =IF(ISERROR(VLOOKUP(I6,[2]FRG!$S$19:$U$288,1,FALSE)),"NO","SI") -> SI | E6: =IF(ISERROR(VLOOKUP(I6,'[4]ARI 26 C33'!$C$1:$D$490,1,FALSE)),"NO","SI") -> NO | F6: LLANQUIHUE | G6: PUERTO MONTT | H6: MUNICIPALIDAD PUERTO MONTT | I6: 40033774 | J6: REEV REPOSICION CAMIONES Y MAQUINARIAS - MUNICIPALIDAD DE PUERTO MONTT | K6: 1931826751 | L6: Fabián Rutte | M6: CUMPLE RT | P6: =IF(NETWORKDAYS(N6,O6,Feriados!$I$2:$I$22)-1>=0,NETWORKDAYS(N6,O6,Feriados!$I$2:$I$22)-1,"NO APLICA") -> NO APLICA | Q6: 45866 | R6: =+Q6+T6 -> 45876 | S6: 45873 | T6: 10 | U6: =WORKDAY(Q6,T6,Feriados!$I$2:$I$22) -> 45880 | V6: =+S6-Q6 -> 7 | W6: =IF(NETWORKDAYS(Q6,S6,Feriados!$I$2:$I$22)-1>=0,NETWORKDAYS(Q6,S6,Feriados!$I$2:$I$22)-1,"NO APLICA") -> 5 | X6: =SUM(U6-TODAY()) -> -416 | Y6: 3.186/29-10-2021 | Z6: MAQ. CNOS | AA6: 27528 | AB6: SI | AC6: TRANSPORTE
A7: 6 | B7: 29 | C7: =IF(ISERROR(VLOOKUP(I7,[1]DEP!$B$3:$E$583,1,FALSE)),"NO","SI") -> NO | D7: =IF(ISERROR(VLOOKUP(I7,[2]FRG!$S$19:$U$288,1,FALSE)),"NO","SI") -> NO | E7: =IF(ISERROR(VLOOKUP(I7,'[4]ARI 26 C33'!$C$1:$D$490,1,FALSE)),"NO","SI") -> NO | H7: SERVICIO SALUD RELONCAVI | I7: 40063717 | J7: ADQUISICION EQUIPOS Y EQUIPAMIENTOS PARA POSTAS DE SALUD RURAL, TERRITORIO CORDILLERA | L7: Fabián Rutte | M7: OBSERVADO | N7: 45671 | O7: 45684 | P7: =IF(NETWORKDAYS(N7,O7,Feriados!$I$2:$I$22)-1>=0,NETWORKDAYS(N7,O7,Feriados!$I$2:$I$22)-1,"NO APLICA") -> 9 | Q7: 45967 | R7: =+Q7+T7 -> 45982 | S7: 46000 | T7: 15 | U7: =WORKDAY(Q7,T7,Feriados!$I$2:$I$22) -> 45988 | V7: =+S7-Q7 -> 33 | W7: =IF(NETWORKDAYS(Q7,S7,Feriados!$I$2:$I$22)-1>=0,NETWORKDAYS(Q7,S7,Feriados!$I$2:$I$22)-1,"NO APLICA") -> 22 | X7: =SUM(U7-TODAY()) -> -308 | Z7: EQ. SALUD | AB7: NO | AC7: SALUD
A8: 7 | B8: 29 | C8: =IF(ISERROR(VLOOKUP(I8,[1]DEP!$B$3:$E$583,1,FALSE)),"NO","SI") -> SI | D8: =IF(ISERROR(VLOOKUP(I8,[2]FRG!$S$19:$U$288,1,FALSE)),"NO","SI") -> SI | E8: =IF(ISERROR(VLOOKUP(I8,'[4]ARI 26 C33'!$C$1:$D$490,1,FALSE)),"NO","SI") -> SI | F8: CHILOÉ | G8: PUQUELDÓN | H8: MUNICIPALIDAD PUQUELDÓN | I8: 40013818 | J8: REEV REPOSICION MAQUINARIA PARA MANTENCION DE CAMINOS VECINALES, COMUNA PUQUELDON | K8: 839659000 | L8: Fabián Rutte | M8: CUMPLE RT | P8: =IF(NETWORKDAYS(N8,O8,Feriados!$I$2:$I$22)-1>=0,NETWORKDAYS(N8,O8,Feriados!$I$2:$I$22)-1,"NO APLICA") -> NO APLICA | Q8: 45673 | R8: =+Q8+T8 -> 45683 | S8: 45681 | T8: 10 | U8: =WORKDAY(Q8,T8,Feriados!$I$2:$I$22) -> 45687 | V8: =+S8-Q8 -> 8 | W8: =IF(NETWORKDAYS(Q8,S8,Feriados!$I$2:$I$22)-1>=0,NETWORKDAYS(Q8,S8,Feriados!$I$2:$I$22)-1,"NO APLICA") -> 6 | X8: =SUM(U8-TODAY()) -> -609 | Y8: 4.067/30-10-2023 | Z8: MAQ. CNOS | AA8: 1190 | AB8: SI | AC8: TRANSPORTE
A9: 8 | B9: 29 | C9: =IF(ISERROR(VLOOKUP(I9,[1]DEP!$B$3:$E$583,1,FALSE)),"NO","SI") -> SI | D9: =IF(ISERROR(VLOOKUP(I9,[2]FRG!$S$19:$U$288,1,FALSE)),"NO","SI") -> SI | E9: =IF(ISERROR(VLOOKUP(I9,'[4]ARI 26 C33'!$C$1:$D$490,1,FALSE)),"NO","SI") -> NO | F9: LLANQUIHUE | G9: FRUTILLAR | H9: MUNICIPALIDAD FRUTILLAR | I9: 40031422 | J9: REEV REPOSICION CAMIÓN RECOLECTOR DE RESIDUOS SÓLIDOS EN LA COMUNA DE FRUTILLAR | K9: 238375000 | L9: Fabián Rutte | M9: CUMPLE RT | P9: =IF(NETWORKDAYS(N9,O9,Feriados!$I$2:$I$22)-1>=0,NETWORKDAYS(N9,O9,Feriados!$I$2:$I$22)-1,"NO APLICA") -> NO APLICA | Q9: 45688 | R9: =+Q9+T9 -> 45698 | S9: 45695 | T9: 10 | U9: =WORKDAY(Q9,T9,Feriados!$I$2:$I$22) -> 45702 | V9: =+S9-Q9 -> 7 | W9: =IF(NETWORKDAYS(Q9,S9,Feriados!$I$2:$I$22)-1>=0,NETWORKDAYS(Q9,S9,Feriados!$I$2:$I$22)-1,"NO APLICA") -> 5 | X9: =SUM(U9-TODAY()) -> -594 | Y9: 360/04-03-2024 | Z9: CAMIONES RSD | AA9: 9915 | AB9: SI | AC9: RECURSOS NATURALES Y MEDIO AMBIENTE / MEDIO AMBIENTE
A10: 9 | B10: 29 | C10: =IF(ISERROR(VLOOKUP(I10,[1]DEP!$B$3:$E$583,1,FALSE)),"NO","SI") -> NO | D10: =IF(ISERROR(VLOOKUP(I10,[2]FRG!$S$19:$U$288,1,FALSE)),"NO","SI") -> NO | E10: =IF(ISERROR(VLOOKUP(I10,'[4]ARI 26 C33'!$C$1:$D$490,1,FALSE)),"NO","SI") -> SI | F10: OSORNO | G10: SAN PABLO | H10: MUNICIPALIDAD SAN PABLO | I10: 40069510 | J10: REPOSICION VEHICULOS MUNICIPALES VARIOS DEPARTAMENTOS, SAN PABLO | K10: 160330000 | L10: Fabián Rutte | M10: CUMPLE RT | N10: 45698 | O10: 45719 | P10: =IF(NETWORKDAYS(N10,O10,Feriados!$I$2:$I$22)-1>=0,NETWORKDAYS(N10,O10,Feriados!$I$2:$I$22)-1,"NO APLICA") -> 15 | Q10: 45789 | R10: =+Q10+T10 -> 45804 | S10: 45811 | T10: 15 | U10: =WORKDAY(Q10,T10,Feriados!$I$2:$I$22) -> 45811 | V10: =+S10-Q10 -> 22 | W10: =IF(NETWORKDAYS(Q10,S10,Feriados!$I$2:$I$22)-1>=0,NETWORKDAYS(Q10,S10,Feriados!$I$2:$I$22)-1,"NO APLICA") -> 15 | X10: =SUM(U10-TODAY()) -> -485 | Y10: 1.193/04-06-2025 | Z10: VEHICULOS | AB10: NO | AC10: MULTISECTORIAL
A11: 10 | B11: 29 | C11: =IF(ISERROR(VLOOKUP(I11,[1]DEP!$B$3:$E$583,1,FALSE)),"NO","SI") -> NO | D11: =IF(ISERROR(VLOOKUP(I11,[2]FRG!$S$19:$U$288,1,FALSE)),"NO","SI") -> NO | E11: =IF(ISERROR(VLOOKUP(I11,'[4]ARI 26 C33'!$C$1:$D$490,1,FALSE)),"NO","SI") -> SI | F11: LLANQUIHUE | G11: FRUTILLAR | H11: MUNICIPALIDAD FRUTILLAR | I11: 40070081 | J11: CONSERVACION GIMNASIO MUNICIPAL DE CASMA | L11: Fabián Rutte | M11: OBSERVADO | N11: 45708 | O11: 45750 | P11: =IF(NETWORKDAYS(N11,O11,Feriados!$I$2:$I$22)-1>=0,NETWORKDAYS(N11,O11,Feriados!$I$2:$I$22)-1,"NO APLICA") -> 30 | Q11: 45947 | R11: =+Q11+T11 -> 45962 | S11: 45750 | T11: 15 | U11: =WORKDAY(Q11,T11,Feriados!$I$2:$I$22) -> 45971 | V11: =+S11-Q11 -> -197 | W11: =IF(NETWORKDAYS(Q11,S11,Feriados!$I$2:$I$22)-1>=0,NETWORKDAYS(Q11,S11,Feriados!$I$2:$I$22)-1,"NO APLICA") -> NO APLICA | X11: =SUM(U11-TODAY()) -> -325 | Z11: DEPORTE CONSERVACION | AB11: NO | AC11: DEPORTE
A12: 11 | B12: 31 | C12: =IF(ISERROR(VLOOKUP(I12,[1]DEP!$B$3:$E$583,1,FALSE)),"NO","SI") -> NO | D12: =IF(ISERROR(VLOOKUP(I12,[2]FRG!$S$19:$U$288,1,FALSE)),"NO","SI") -> NO | E12: =IF(ISERROR(VLOOKUP(I12,'[4]ARI 26 C33'!$C$1:$D$490,1,FALSE)),"NO","SI") -> SI | F12: LLANQUIHUE | G12: CALBUCO | H12: MUNICIPALIDAD CALBUCO | I12: 40055163 | J12: CONSERVACION CAMINOS NO ENROLADOS ISLA PULUQUI | K12: 1221535000 | L12: Fabián Rutte | M12: CUMPLE RT | N12: 45712 | O12: 45727 | P12: =IF(NETWORKDAYS(N12,O12,Feriados!$I$2:$I$22)-1>=0,NETWORKDAYS(N12,O12,Feriados!$I$2:$I$22)-1,"NO APLICA") -> 11 | Q12: 45712 | R12: =+Q12+T12 -> 45727 | S12: 45727 | T12: 15 | U12: =WORKDAY(Q12,T12,Feriados!$I$2:$I$22) -> 45733 | V12: =+S12-Q12 -> 15 | W12: =IF(NETWORKDAYS(Q12,S12,Feriados!$I$2:$I$22)-1>=0,NETWORKDAYS(Q12,S12,Feriados!$I$2:$I$22)-1,"NO APLICA") -> 11 | X12: =SUM(U12-TODAY()) -> -563 | Y12: 425/13-03-2025 | Z12: CNOS NO ENROLADOS | AA12: 1167 | AB12: NO | AC12: TRANSPORTE
A13: 12 | B13: 31 | C13: =IF(ISERROR(VLOOKUP(I13,[1]DEP!$B$3:$E$583,1,FALSE)),"NO","SI") -> NO | D13: =IF(ISERROR(VLOOKUP(I13,[2]FRG!$S$19:$U$288,1,FALSE)),"NO","SI") -> NO | E13: =IF(ISERROR(VLOOKUP(I13,'[4]ARI 26 C33'!$C$1:$D$490,1,FALSE)),"NO","SI") -> SI | F13: CHILOÉ | G13: QUINCHAO | H13: MUNICIPALIDAD QUINCHAO | I13: 40067325 | J13: CONSERVACION CAMINOS NO ENROLADOS ISLA CHAULINEC, COMUNA DE QUINCHAO | K13: 2352751000 | L13: Fabián Rutte | M13: CUMPLE RT | N13: 45712 | O13: 45719 | P13: =IF(NETWORKDAYS(N13,O13,Feriados!$I$2:$I$22)-1>=0,NETWORKDAYS(N13,O13,Feriados!$I$2:$I$22)-1,"NO APLICA") -> 5 | Q13: 45712 | R13: =+Q13+T13 -> 45727 | S13: 45719 | T13: 15 | U13: =WORKDAY(Q13,T13,Feriados!$I$2:$I$22) -> 45733 | V13: =+S13-Q13 -> 7 | W13: =IF(NETWORKDAYS(Q13,S13,Feriados!$I$2:$I$22)-1>=0,NETWORKDAYS(Q13,S13,Feriados!$I$2:$I$22)-1,"NO APLICA") -> 5 | X13: =SUM(U13-TODAY()) -> -563 | Z13: CNOS NO ENROLADOS | AA13: 497 | AB13: NO | AC13: TRANSPORTE
A14: 13 | B14: 29 | C14: =IF(ISERROR(VLOOKUP(I14,[1]DEP!$B$3:$E$583,1,FALSE)),"NO","SI") -> NO | D14: =IF(ISERROR(VLOOKUP(I14,[2]FRG!$S$19:$U$288,1,FALSE)),"NO","SI") -> NO | E14: =IF(ISERROR(VLOOKUP(I14,'[4]ARI 26 C33'!$C$1:$D$490,1,FALSE)),"NO","SI") -> NO | F14: LLANQUIHUE | G14: FRUTILLAR | H14: MUNICIPALIDAD FRUTILLAR | I14: 40069547 | J14: REPOSICION VEHÍCULOS MUNICIPALES COMUNA DE FRUTILLAR | K14: 80166000 | L14: Fabián Rutte | M14: CUMPLE RT | N14: 45705 | O14: 45737 | P14: =IF(NETWORKDAYS(N14,O14,Feriados!$I$2:$I$22)-1>=0,NETWORKDAYS(N14,O14,Feriados!$I$2:$I$22)-1,"NO APLICA") -> 24 | Q14: 45812 | R14: =+Q14+T14 -> 45827 | S14: 45845 | T14: 15 | U14: =WORKDAY(Q14,T14,Feriados!$I$2:$I$22) -> 45834 | V14: =+S14-Q14 -> 33 | W14: =IF(NETWORKDAYS(Q14,S14,Feriados!$I$2:$I$22)-1>=0,NETWORKDAYS(Q14,S14,Feriados!$I$2:$I$22)-1,"NO APLICA") -> 22 | X14: =SUM(U14-TODAY()) -> -462 | Y14: 1.548/08-07-2025 | Z14: VEHICULOS | AB14: NO | AC14: TRANSPORTE
A15: 14 | B15: 31 | C15: =IF(ISERROR(VLOOKUP(I15,[1]DEP!$B$3:$E$583,1,FALSE)),"NO","SI") -> NO | D15: =IF(ISERROR(VLOOKUP(I15,[2]FRG!$S$19:$U$288,1,FALSE)),"NO","SI") -> NO | E15: =IF(ISERROR(VLOOKUP(I15,'[4]ARI 26 C33'!$C$1:$D$490,1,FALSE)),"NO","SI") -> NO | F15: OSORNO | G15: SAN PABLO | H15: MUNICIPALIDAD SAN PABLO | I15: 40070419 | J15: CONSERVACION CAMINOS N.e. DE SOCOTUÉ, PALENA, S. ANTONIO, S. ALDEA, PISHUINCO y MICHAICAHUÍN | L15: Fabián Rutte | M15: OBSERVADO | N15: 45744 | O15: 45772 | P15: =IF(NETWORKDAYS(N15,O15,Feriados!$I$2:$I$22)-1>=0,NETWORKDAYS(N15,O15,Feriados!$I$2:$I$22)-1,"NO APLICA") -> 19 | Q15: 45971 | R15: =+Q15+T15 -> 45986 | S15: 45772 | T15: 15 | U15: =WORKDAY(Q15,T15,Feriados!$I$2:$I$22) -> 45992 | V15: =+S15-Q15 -> -199 | W15: =IF(NETWORKDAYS(Q15,S15,Feriados!$I$2:$I$22)-1>=0,NETWORKDAYS(Q15,S15,Feriados!$I$2:$I$22)-1,"NO APLICA") -> NO APLICA | X15: =SUM(U15-TODAY()) -> -304 | Z15: CNOS NO ENROLADOS | AB15: NO | AC15: TRANSPORTE
A16: 15 | B16: 31 | C16: =IF(ISERROR(VLOOKUP(I16,[1]DEP!$B$3:$E$583,1,FALSE)),"NO","SI") -> NO | D16: =IF(ISERROR(VLOOKUP(I16,[2]FRG!$S$19:$U$288,1,FALSE)),"NO","SI") -> SI | E16: =IF(ISERROR(VLOOKUP(I16,'[4]ARI 26 C33'!$C$1:$D$490,1,FALSE)),"NO","SI") -> NO | F16: LLANQUIHUE | G16: FRESIA | H16: MUNICIPALIDAD FRESIA | I16: 40054955 | J16: REEV CONSERVACION 17 CAMINOS NO ENROLADOS 7 SECTORES, COMUNA DE FRESIA | K16: 800512000 | L16: Fabián Rutte | M16: OBSERVADO | P16: =IF(NETWORKDAYS(N16,O16,Feriados!$I$2:$I$22)-1>=0,NETWORKDAYS(N16,O16,Feriados!$I$2:$I$22)-1,"NO APLICA") -> NO APLICA | Q16: 45728 | R16: =+Q16+T16 -> 45738 | T16: 10 | U16: =WORKDAY(Q16,T16,Feriados!$I$2:$I$22) -> 45742 | V16: =+S16-Q16 -> -45728 | W16: =IF(NETWORKDAYS(Q16,S16,Feriados!$I$2:$I$22)-1>=0,NETWORKDAYS(Q16,S16,Feriados!$I$2:$I$22)-1,"NO APLICA") -> NO APLICA | X16: =SUM(U16-TODAY()) -> -554 | Y16: 3.891/16-10-2023 | Z16: CNOS NO ENROLADOS | AA16: 416 | AB16: SI | AC16: TRANSPORTE
A17: 16 | B17: 31 | C17: =IF(ISERROR(VLOOKUP(I17,[1]DEP!$B$3:$E$583,1,FALSE)),"NO","SI") -> NO | D17: =IF(ISERROR(VLOOKUP(I17,[2]FRG!$S$19:$U$288,1,FALSE)),"NO","SI") -> NO | E17: =IF(ISERROR(VLOOKUP(I17,'[4]ARI 26 C33'!$C$1:$D$490,1,FALSE)),"NO","SI") -> SI | F17: CHILOÉ | G17: QUEMCHI | H17: MUNICIPALIDAD QUEMCHI | I17: 40005528 | J17: CONSERVACION GIMNASIO MUNICIPAL DE QUEMCHI | K17: 700908000 | L17: Fabián Rutte | M17: CUMPLE RT | N17: 45726 | O17: 45811 | P17: =IF(NETWORKDAYS(N17,O17,Feriados!$I$2:$I$22)-1>=0,NETWORKDAYS(N17,O17,Feriados!$I$2:$I$22)-1,"NO APLICA") -> 58 | Q17: 45943 | R17: =+Q17+T17 -> 45958 | S17: 45960 | T17: 15 | U17: =WORKDAY(Q17,T17,Feriados!$I$2:$I$22) -> 45965 | V17: =+S17-Q17 -> 17 | W17: =IF(NETWORKDAYS(Q17,S17,Feriados!$I$2:$I$22)-1>=0,NETWORKDAYS(Q17,S17,Feriados!$I$2:$I$22)-1,"NO APLICA") -> 13 | X17: =SUM(U17-TODAY()) -> -331 | Y17: 2.953/05-11-2025 | Z17: DEPORTE CONSERVACION | AB17: NO | AC17: DEPORTE
A18: 17 | B18: 31 | C18: =IF(ISERROR(VLOOKUP(I18,[1]DEP!$B$3:$E$583,1,FALSE)),"NO","SI") -> SI | D18: =IF(ISERROR(VLOOKUP(I18,[2]FRG!$S$19:$U$288,1,FALSE)),"NO","SI") -> NO | E18: =IF(ISERROR(VLOOKUP(I18,'[4]ARI 26 C33'!$C$1:$D$490,1,FALSE)),"NO","SI") -> SI | F18: CHILOÉ | G18: PUQUELDÓN | H18: MUNICIPALIDAD PUQUELDÓN | I18: 40013816 | J18: CONSERVACION GIMNASIO MUNICIPAL DE PUQUELDON | K18: 771811000 | L18: Fabián Rutte | M18: CUMPLE RT | N18: 45733 | O18: 45754 | P18: =IF(NETWORKDAYS(N18,O18,Feriados!$I$2:$I$22)-1>=0,NETWORKDAYS(N18,O18,Feriados!$I$2:$I$22)-1,"NO APLICA") -> 15 | Q18: 45959 | R18: =+Q18+T18 -> 45974 | S18: 45960 | T18: 15 | U18: =WORKDAY(Q18,T18,Feriados!$I$2:$I$22) -> 45981 | V18: =+S18-Q18 -> 1 | W18: =IF(NETWORKDAYS(Q18,S18,Feriados!$I$2:$I$22)-1>=0,NETWORKDAYS(Q18,S18,Feriados!$I$2:$I$22)-1,"NO APLICA") -> 1 | X18: =SUM(U18-TODAY()) -> -315 | Y18: 2.955/05-11-2025 | Z18: DEPORTE CONSERVACION | AB18: NO | AC18: DEPORTE
A19: 18 | B19: 29 | C19: =IF(ISERROR(VLOOKUP(I19,[1]DEP!$B$3:$E$583,1,FALSE)),"NO","SI") -> NO | D19: =IF(ISERROR(VLOOKUP(I19,[2]FRG!$S$19:$U$288,1,FALSE)),"NO","SI") -> NO | E19: =IF(ISERROR(VLOOKUP(I19,'[4]ARI 26 C33'!$C$1:$D$490,1,FALSE)),"NO","SI") -> SI | F19: LLANQUIHUE | G19: FRUTILLAR | H19: MUNICIPALIDAD FRUTILLAR | I19: 40070410 | J19: ADQUISICION Y REPOSICIÓN DE MAQUINARIAS Y VEHICULO PARA ASEO Y ORNATO, FRUTILLAR | K19: 589337430 | L19: Fabián Rutte | M19: CUMPLE RT | N19: 45748 | O19: 45789 | P19: =IF(NETWORKDAYS(N19,O19,Feriados!$I$2:$I$22)-1>=0,NETWORKDAYS(N19,O19,Feriados!$I$2:$I$22)-1,"NO APLICA") -> 27 | Q19: 45947 | R19: =+Q19+T19 -> 45962 | S19: 45915 | T19: 15 | U19: =WORKDAY(Q19,T19,Feriados!$I$2:$I$22) -> 45971 | V19: =+S19-Q19 -> -32 | W19: =IF(NETWORKDAYS(Q19,S19,Feriados!$I$2:$I$22)-1>=0,NETWORKDAYS(Q19,S19,Feriados!$I$2:$I$22)-1,"NO APLICA") -> NO APLICA | X19: =SUM(U19-TODAY()) -> -325 | Z19: MAQ. CNOS | AB19: NO | AC19: RECURSOS NATURALES Y MEDIO AMBIENTE / MEDIO AMBIENTE
A20: 19 | B20: 31 | C20: =IF(ISERROR(VLOOKUP(I20,[1]DEP!$B$3:$E$583,1,FALSE)),"NO","SI") -> NO | D20: =IF(ISERROR(VLOOKUP(I20,[2]FRG!$S$19:$U$288,1,FALSE)),"NO","SI") -> NO | E20: =IF(ISERROR(VLOOKUP(I20,'[4]ARI 26 C33'!$C$1:$D$490,1,FALSE)),"NO","SI") -> SI | F20: LLANQUIHUE | G20: FRESIA | H20: MUNICIPALIDAD FRESIA | I20: 40067829 | J20: CONSERVACION CAMINOS NO ENROLADOS LOS GUINDOS, EL MAÑÍO, LAS CUYAS, TROMPETILLA Y LOS CAÑONES | K20: 691498000 | L20: Fabián Rutte | M20: CUMPLE RT | N20: 45748 | O20: 45776 | P20: =IF(NETWORKDAYS(N20,O20,Feriados!$I$2:$I$22)-1>=0,NETWORKDAYS(N20,O20,Feriados!$I$2:$I$22)-1,"NO APLICA") -> 19 | Q20: 45974 | R20: =+Q20+T20 -> 45989 | S20: 46006 | T20: 15 | U20: =WORKDAY(Q20,T20,Feriados!$I$2:$I$22) -> 45995 | V20: =+S20-Q20 -> 32 | W20: =IF(NETWORKDAYS(Q20,S20,Feriados!$I$2:$I$22)-1>=0,NETWORKDAYS(Q20,S20,Feriados!$I$2:$I$22)-1,"NO APLICA") -> 21 | X20: =SUM(U20-TODAY()) -> -301 | Y20: 3.299/16-12-2025 | Z20: CNOS NO ENROLADOS | AB20: NO | AC20: TRANSPORTE
A21: 20 | B21: 29 | C21: =IF(ISERROR(VLOOKUP(I21,[1]DEP!$B$3:$E$583,1,FALSE)),"NO","SI") -> NO | D21: =IF(ISERROR(VLOOKUP(I21,[2]FRG!$S$19:$U$288,1,FALSE)),"NO","SI") -> SI | E21: =IF(ISERROR(VLOOKUP(I21,'[4]ARI 26 C33'!$C$1:$D$490,1,FALSE)),"NO","SI") -> NO | F21: X REGION | G21: PROV. OSORNO | H21: DIRECCION DE VIALIDAD | I21: 40044996 | J21: REEV REPOSICION VEHICULOS Y ADQUISICION MAQUINARIA DE ASFALTO PARA LA D.V. REGIÓN DE LOS LAGOS | K21: 1376422000 | L21: Fabián Rutte | M21: CUMPLE RT | P21: =IF(NETWORKDAYS(N21,O21,Feriados!$I$2:$I$22)-1>=0,NETWORKDAYS(N21,O21,Feriados!$I$2:$I$22)-1,"NO APLICA") -> NO APLICA | Q21: 45922 | R21: =+Q21+T21 -> 45932 | S21: 45933 | T21: 10 | U21: =WORKDAY(Q21,T21,Feriados!$I$2:$I$22) -> 45936 | V21: =+S21-Q21 -> 11 | W21: =IF(NETWORKDAYS(Q21,S21,Feriados!$I$2:$I$22)-1>=0,NETWORKDAYS(Q21,S21,Feriados!$I$2:$I$22)-1,"NO APLICA") -> 9 | X21: =SUM(U21-TODAY()) -> -360 | Y21: 737/16-03-2023 | Z21: MAQ. CNOS | AA21: 234122 | AB21: SI | AC21: TRANSPORTE
A22: 21 | B22: 29 | C22: =IF(ISERROR(VLOOKUP(I22,[1]DEP!$B$3:$E$583,1,FALSE)),"NO","SI") -> NO | D22: =IF(ISERROR(VLOOKUP(I22,[2]FRG!$S$19:$U$288,1,FALSE)),"NO","SI") -> NO | E22: =IF(ISERROR(VLOOKUP(I22,'[4]ARI 26 C33'!$C$1:$D$490,1,FALSE)),"NO","SI") -> NO | H22: DIRECTEMAR | I22: 40072933 | J22: ADQUISICION UNIDAD DESPLIEGUE POLICIA MARITIMA PARA GOB MARITIMA DE PTO MONTT | L22: Fabián Rutte | M22: OBSERVADO | N22: 45747 | O22: 45770 | P22: =IF(NETWORKDAYS(N22,O22,Feriados!$I$2:$I$22)-1>=0,NETWORKDAYS(N22,O22,Feriados!$I$2:$I$22)-1,"NO APLICA") -> 16 | Q22: 45957 | R22: =+Q22+T22 -> 45972 | S22: 45978 | T22: 15 | U22: =WORKDAY(Q22,T22,Feriados!$I$2:$I$22) -> 45979 | V22: =+S22-Q22 -> 21 | W22: =IF(NETWORKDAYS(Q22,S22,Feriados!$I$2:$I$22)-1>=0,NETWORKDAYS(Q22,S22,Feriados!$I$2:$I$22)-1,"NO APLICA") -> 14 | X22: =SUM(U22-TODAY()) -> -317 | Z22: ARMADA | AB22: NO | AC22: SEGURIDAD
A23: 22 | B23: 29 | C23: =IF(ISERROR(VLOOKUP(I23,[1]DEP!$B$3:$E$583,1,FALSE)),"NO","SI") -> NO | D23: =IF(ISERROR(VLOOKUP(I23,[2]FRG!$S$19:$U$288,1,FALSE)),"NO","SI") -> SI | E23: =IF(ISERROR(VLOOKUP(I23,'[4]ARI 26 C33'!$C$1:$D$490,1,FALSE)),"NO","SI") -> NO | F23: CHILOÉ | G23: ANCUD | H23: MUNICIPALIDAD ANCUD | I23: 40041565 | J23: ADQUISICION DE DOS RETROEXCAVADORAS PARA LA ILUSTRE MUNICIPALIDAD DE ANCUD | K23: 311458000 | L23: Fabián Rutte | M23: CUMPLE RT | P23: =IF(NETWORKDAYS(N23,O23,Feriados!$I$2:$I$22)-1>=0,NETWORKDAYS(N23,O23,Feriados!$I$2:$I$22)-1,"NO APLICA") -> NO APLICA | Q23: 45769 | R23: =+Q23+T23 -> 45779 | S23: 45666 | T23: 10 | U23: =WORKDAY(Q23,T23,Feriados!$I$2:$I$22) -> 45784 | V23: =+S23-Q23 -> -103 | W23: =IF(NETWORKDAYS(Q23,S23,Feriados!$I$2:$I$22)-1>=0,NETWORKDAYS(Q23,S23,Feriados!$I$2:$I$22)-1,"NO APLICA") -> NO APLICA | X23: =SUM(U23-TODAY()) -> -512 | Y23: 4.068/30-10-23 | Z23: MAQ. CNOS | AA23: 11687 | AB23: SI | AC23: TRANSPORTE
