Workbook

Sheet 2026
B1: Código | D1: Nombre | E1: Comuna | F1: Provincia | G1: Ingreso Of. Partes | H1: Monto M$ | I1: Etapa | J1: Proceso | K1: Sector | L1: Observaciones | M1: Objetivo del Pladeco | N1: Lineamiento ERD | O1: Plan del Gobernador | P1: H | Q1: M | R1: TOT | T1: Unidad Tecnica | U1: Formulador Proyecto | V1: ORD. Ingreso N° | W1: Fecha Ord. | X1: N° Exped. | Y1: Ingreso Of. Partes | Z1: Ingreso Of. Planificación | AA1: Fecha Derivado a Evaluador | AB1: Plazo evaluación | AC1: Derivado Unidad Técnica Evaluadora | AD1: Fecha Derivación | AE1: Reingreso Depto. Planif. | AF1: Fecha Evaluación | AH1: observaciones Ord. Gore N° | AI1: Fecha Ord. | AJ1: Fecha Ficha Evaluación | AK1: Informa | AL1: Ord.Resp. Obs. | AM1: Fecha Ord. | AN1: N° EXP. | AO1: Ingreso Oficina | AQ1: ORD. GORE Observaciones | AR1: Fecha Ord. | AS1: Ord. a MDSF | AT1: Fecha ORD. | AU1: Estado Proyecto SEGÚN Haroldt | AV1: Dentro de 15 días
A2: 1 | B2: 40073933 | C2: 0 | D2: Reposición con Relocalización Centro Rehabilitación Chiloé, Ancud | E2: Ancud | F2: CHILOÉ | G2: 45981 | H2: 189147 | I2: Diseño | J2: 2026 | K2: Salud | L2: Ok - Oficio 3289 15-12-25 | N2: Se encuentra dentro de los de la ERD en - lineamientos: Conectividad y Movilidad Regional Sustentable. - Ítem Conectividad insular y de lugares aislados. - Obj.: Disminuir el déficit de infraestructura de conectividad para territorios insulares y aislados de la región. | O2: Se enlaza con el Programa Regional del Gobernador en el - Pilar: 2. Desarrollo Económico Sostenible: una Alianza Público-Privada. - Letra: c) Inversiones en Infraestructura: Mejorar la conectividad y la infraestructura regional para atraer inversiones y generar empleo. | T2: Municipalidad Castro | U2: Municipalidad Castro | W2: 45973 | AA2: 45981 | AB2: =WORKDAY(AA2,15,'Feriados y Comunas'!A$2:A$25) -> 46003 | AS2: 3289 | AT2: 46006 | AU2: RECOMENDADO | AV2: OK | AW2: 15
A3: =1+A2 -> 2 | B3: 30116040 | C3: 0 | D3: Reposición Bodega y Galpon Municipal | E3: Palena | F3: PALENA | G3: 45681 | H3: 2152920 | I3: Ejecucion | J3: 2026 | K3: MultiSectorial | L3: Ok - Oficio 1017 23-05-25 | N3: La iniciativa se orienta dentro de la ERD en el, - Lineamiento: Conectividad y Movilidad Regional Sustentable. - Ítem: Conectividad Insular y Lugares Aislados. - Objetivo: Disminuir el déficit de infraestructura de conectividad para territorios aislados de la región. - Actividad: Plan de infraestructura de conectividad para territorios aislados. | O3: Se enlaza con el Programa Regional del Gobernador - Pilar: 6. Gobernanza y Participación Ciudadana. - Letra: c) Modernización Administrativa: Digitalizar los trámites y servicios administrativos para hacerlos más eficientes y accesibles. | P3: 922 | Q3: 768 | R3: 1690 | T3: Municipalidad Palena | U3: Municipalidad Palena | V3: 50 | W3: 45681 | X3: 113293/2025 | Y3: 45681 | Z3: 45684 | AA3: 45684 | AB3: =WORKDAY(AA3,15,'Feriados y Comunas'!A$2:A$25) -> 45705 | AH3: 394 | AI3: 45726 | AJ3: 45695 | AK3: OBSERVADO | AL3: 252 | AM3: 45764 | AO3: 45764 | AQ3: 394 | AR3: 45726 | AS3: 1017 | AT3: 45800 | AU3: RECOMENDADO
A4: =1+A3 -> 3 | B4: 40021925 | C4: 0 | D4: Reposición Estadio Municipal | E4: Quellón | F4: CHILOÉ | G4: 45811 | H4: 3688993 | I4: Ejecución | J4: 2026 | K4: Deporte | L4: Ok - Oficio 064 12-01-26 | N4: La iniciativa se orienta dentro de la ERD en el: - Lineamiento: Bienestar Socio Territorial. - Ítem: Espacios y Equipamiento Público - Objetivo: Aumentar el Nro. De espacios polideportivos en la región con criterios de genero e inclusividad. - Actividad: No hay. | O4: Se enlaza con el Programa Regional del Gobernador: - Pilar 3. Inclusión Social y Mejoramiento de la Calidad de Vida. - Letra c) Programas de Apoyo Social: Desarrollar iniciativas para apoyar a los sectores más vulnerables de nuestra comunidad. | P4: 18390 | Q4: 15830 | R4: 34220 | T4: Municipalidad Quellón | U4: Municipalidad Quellón | V4: 472 | W4: 45803 | Y4: 45811 | Z4: 45811 | AA4: 45811 | AB4: =WORKDAY(AA4,15,'Feriados y Comunas'!A$2:A$25) -> 45833 | AH4: 1500 2934 | AI4: 30-06-2025 04-11-2025 | AJ4: 27-06-2025 30-10-2025 | AK4: OBSERVADO | AL4: 849 | AM4: 45925 | AO4: 45929 | AQ4: 1500 2934 | AR4: 30-06-2025 04-11-2025 | AS4: 64 | AT4: 46034 | AU4: RECOMENDADO | AW4: 17
A5: =1+A4 -> 4 | B5: 40026214 | C5: 0 | D5: Reposición Reten San Juan de la Costa | E5: San Juan de La Costa | F5: OSORNO | G5: 46052 | H5: 154450 | I5: Diseño | J5: 2026 | K5: Seguridad | L5: Ok - Oficio 275 06-02-26 | N5: Se encuentra dentro de los lineamientos de la ERD en - Lineamiento: Bienestar Socio Territorial. - Ítem: Espacios y Equipamiento Público. - Obj.: Reducir el numero de delitos de mayor connotación social en la región. - Actividad: | O5: Se enlaza con el Programa Regional del Gobernador en el -Pilar: 1.Políticas Públicas en Materia de Seguridad Ciudadana -Letra: a)Fortalecimiento de las Fuerzas de Seguridad: Incrementar la presencia policial en las comunidades, disponiendo los recursos necesarios para dotarlas de mejor equipamiento y formación. | P5: 4011 | Q5: 3501 | R5: 7512 | T5: MOP - DA | U5: Carabineros de Chile | V5: 18 | W5: 46052 | Y5: 46052 | AA5: 46052 | AB5: =WORKDAY(AA5,15,'Feriados y Comunas'!A$2:A$25) -> 46073 | AS5: 275 | AT5: 46059 | AU5: RECOMENDADO | AV5: OK | AW5: 5
A6: =1+A5 -> 5 | B6: 40032330 | C6: 0 | D6: Analisis Alternativas de Abastecimiento de Agua Potable en Zonas de Rezago | E6: Regional | F6: REGIONAL | G6: 46009 | H6: 246829 | I6: Ejecución | J6: 2026 | K6: Recursos Hidricos | L6: Ok - Oficio 280 06-02-26 | N6: Se encuentra dentro de los lineamientos de la ERD en Lineamiento: Bienestar Socio Territorial. Ítem: Servicio Básicos. Obj.: Ampliar red de alcantarillado para dar soluciones sustentables a la población en la región. Actividad: Plan Construcción y Mejoramiento de infraestructura de agua potable y alcantarillado urbano y rural. | O6: Se enlaza con el Programa Regional del Gobernador en el lineamiento «Crear Condiciones Para Dar Acceso Al Agua - Plan Integral De Recursos Hídricos». | P6: 0 | Q6: 0 | R6: 0 | T6: Gobierno Regional de Los Lagos | U6: Gobierno Regional de Los Lagos | V6: 1426 | W6: 46009 | AA6: 46009 | AB6: =WORKDAY(AA6,15,'Feriados y Comunas'!A$2:A$25) -> 46031 | AS6: 280 | AT6: 46059 | AU6: RECOMENDADO | AW6: 35
A7: =1+A6 -> 6 | B7: 40035805 | C7: 0 | D7: Construcción Gimnasio Escuela Mirasol | E7: Puerto Montt | F7: =+IFERROR(VLOOKUP(E7,'Feriados y Comunas'!$C$1:$D$36,2,FALSE),"") -> LLANQUIHUE | G7: 45676 | H7: 1169652 | I7: Ejecución | J7: 2026 | K7: Educación | L7: Ok - Oficio 281 06-02-26 | N7: Se encuentra dentro de los lineamientos de la ERD en lineamiento Bienestar Socio Territorial, Ítem Educación, (Obj. Aumentar la cobertura territorial a los establecimientos de educación publica en los territorios rurales de la región). | O7: Se enlaza con el Programa Regional del Gobernador en el lineamiento “Priorización de Inversiones Sectoriales y del FNDR para Nuevos Desafíos”, Acción “Proyectos que aporten a la equidad territorial”. | P7: 305 | Q7: 354 | R7: =SUM(P7:Q7) -> 659 | T7: Municipalidad Puerto Montt | U7: Municipalidad Puerto Montt | V7: 33 | W7: 46037 | AA7: 46041 | AB7: =WORKDAY(AA7,15,'Feriados y Comunas'!A$2:A$25) -> 46062 | AS7: 281 | AT7: 46059 | AU7: RECOMENDADO | AV7: OK | AW7: 10
A8: =1+A7 -> 7 | B8: 40039645 | C8: 0 | D8: Habilitación SS EE ST Chapaco y Otros | E8: Río Negro | F8: =+IFERROR(VLOOKUP(E8,'Feriados y Comunas'!$C$1:$D$36,2,FALSE),"") -> OSORNO | G8: 46050 | H8: 647283 | I8: Ejecución | J8: 2026 | K8: Energía | L8: Ok - Oficio 515 16-03-26 | N8: Se encuentra dentro de los lineamientos de la ERD en Bienestar Socio Territorial. Ítem Medioambiente y Eficiencia Energética, (Obj. Reducir la Pobreza Energética en las viviendas de la Región). | O8: Se enlaza con el Programa Regional del Gobernador - Pilar: 3. Inclusión Social y Mejoramiento de la Calidad de Vida. - Letra: c) Programas de Apoyo Social: Desarrollar iniciativas para apoyar a los sectores más vulnerables de nuestra comunidad. | P8: 16 | Q8: 22 | R8: =SUM(P8:Q8) -> 38 | T8: Municipalidad Rio Negro | U8: Municipalidad Rio Negro | V8: 141 | W8: 46049 | AA8: 46050 | AB8: =WORKDAY(AA8,15,'Feriados y Comunas'!A$2:A$25) -> 46071 | AH8: 289 | AI8: 46059 | AJ8: 46059 | AK8: OBSERVADO | AL8: 196 | AM8: 46065 | AO8: 46065 | AQ8: 289 | AR8: 46059 | AS8: 515 | AT8: 46097 | AU8: RECOMENDADO | AV8: OK | AW8: 7
A9: =1+A8 -> 8 | B9: 40074574 | C9: 0 | D9: Mejoramiento y Ampliación SSR ST Pichihuilma | E9: Río Negro | F9: =+IFERROR(VLOOKUP(E9,'Feriados y Comunas'!$C$1:$D$36,2,FALSE),"") -> OSORNO | G9: 45924 | H9: 844156 | I9: Ejecución | J9: 2026 | K9: Recursos Hidricos | L9: Ok - Oficio 518 16-03-26 | N9: Se encuentra dentro de la ERD en: - Lineamiento: Bienestar Socio territorial. - Ítem: Servicio Básicos. - Obj.: Ampliar la Red de alcantarillado para dar soluciones sustentables. Reducir el numero de vivienda desconectadas de un sistema de suministro de agua en las áreas rurales de la región. - Actividad: Plan de construcción y mejoramiento de infraestructura agua potable y alcantarillado urbano y rural. | O9: Se enlaza con el Programa Regional del Gobernador en el - Pilar: 3. Inclusión Social y Mejoramiento de la Calidad de Vida - Letra: c)Programas de Apoyo Social: Desarrollar iniciativas para apoyar a los sectores más vulnerables de nuestra comunidad. | P9: 134 | Q9: 136 | R9: =SUM(P9:Q9) -> 270 | T9: Municipalidad Rio Negro | U9: Municipalidad Rio Negro | V9: 1161-79 | W9: 45909 | Y9: 45924 | Z9: 45924 | AA9: 45924 | AB9: =WORKDAY(AA9,15,'Feriados y Comunas'!A$2:A$25) -> 45945 | AH9: 2911 | AI9: 45964 | AJ9: 45960 | AK9: OBSERVADO | AL9: 293 | AM9: 46084 | AO9: 46084 | AQ9: 2911 | AR9: 45964 | AS9: 518 | AT9: 46097 | AU9: RECOMENDADO | AW9: 26
A10: =1+A9 -> 9 | B10: 40074940 | C10: 0 | D10: Diagnostico Plan de Manejo Area Protegida Lagos Huillinco y Cucao | E10: Chonchi | F10: =+IFERROR(VLOOKUP(E10,'Feriados y Comunas'!$C$1:$D$36,2,FALSE),"") -> CHILOÉ | G10: 45933 | H10: 55000 | I10: Ejecución | J10: 2026 | K10: Recursos Naturales | L10: Ok - Oficio 513 16-03-26 | N10: Se encuentra dentro de la ERD en: Lineamiento: Cohesión e Identidad Cultural. Ítem: Patrimonio Cultural. Obj.:. Actividad:. | O10: Se enlaza con el Programa Regional del Gobernador en el Pilar: 3. Protección del Medio Ambiente. Letra: d) Protección de Ecosistemas: Implementar políticas de conservación para proteger los ecosistemas de la región, especialmente los lagos y parques nacionales. | P10: 0 | Q10: 0 | R10: =SUBTOTAL(9,P10:Q10) -> 0 | T10: Municipalidad Chonchi | U10: Municipalidad Chonchi | V10: 839 | W10: 45926 | Y10: 45933 | Z10: 45933 | AA10: 45933 | AB10: =WORKDAY(AA10,15,'Feriados y Comunas'!A$2:A$25) -> 45954 | AH10: 2902 3281 292 | AI10: 3-11-2025 15-12-2025 06-02-2026 | AJ10: 30-10-2025 12-12-2025 06-02-2026 | AK10: OBSERVADO | AL10: 1116 152 | AM10: 23-12-2025 03-03-2026 | AO10: 23-12-2025 03-03-2026 | AQ10: 2902 3281 292 | AR10: 3-11-2025 15-12-2025 06-02-2026 | AS10: 513 | AT10: 46097 | AU10: RECOMENDADO | AW10: 19
A11: =1+A10 -> 10 | B11: 50000852 | C11: 0 | D11: Construcción Centro Deportivo V Centenario | E11: Osorno | F11: =+IFERROR(VLOOKUP(E11,'Feriados y Comunas'!$C$1:$D$36,2,FALSE),"") -> OSORNO | G11: 46086 | H11: 1756123 | I11: Ejecución | J11: 2026 | K11: Deporte | L11: Ok - Oficio 652 31-03-26 | N11: La iniciativa se orienta dentro de la ERD en el: - Lineamiento: Bienestar Socio Territorial. - Ítem: Espacios y Equipamiento Público - Objetivo: Aumentar el Nro. De espacios polideportivos en la región con criterios de genero e inclusividad. - Actividad: No hay. | O11: Se enlaza con el Programa Regional del Gobernador: - Pilar: 3. Inclusión Social y Mejoramiento de la Calidad de Vida. - Letra: c) Programas de Apoyo Social: Desarrollar iniciativas para apoyar a los sectores más vulnerables de nuestra comunidad. | P11: 0 | Q11: 0 | R11: =SUM(P11:Q11) -> 0 | T11: Municipalidad Osorno | U11: Municipalidad Osorno | V11: 4670 | W11: 46086 | AA11: 46086 | AB11: =WORKDAY(AA11,15,'Feriados y Comunas'!A$2:A$25) -> 46107 | AH11: 520 | AI11: 46097 | AJ11: 46094 | AK11: OBSERVADO | AL11: 6776 | AM11: 46106 | AO11: 46106 | AQ11: 520 | AR11: 46097 | AS11: 652 | AT11: 46112 | AU11: RECOMENDADO | AV11: OK | AW11: 7
A12: =1+A11 -> 11 | B12: 50000492 | C12: 0 | D12: Reposición Gimnasio Pedro Aguirre Cerda | E12: Osorno | F12: =+IFERROR(VLOOKUP(E12,'Feriados y Comunas'!$C$1:$D$36,2,FALSE),"") -> OSORNO | G12: 46079 | H12: 76160 | I12: Diseño | J12: 2026 | K12: Deporte | L12: Ok - Oficio 653 31-03-26 | N12: La iniciativa se orienta dentro de la ERD en el: - Lineamiento: Bienestar Socio Territorial. - Ítem: Espacios y Equipamiento Público - Objetivo: Aumentar el Nro. De espacios polideportivos en la región con criterios de genero e inclusividad. - Actividad: No hay. | O12: Se enlaza con el Programa Regional del Gobernador: - Pilar: 3. Inclusión Social y Mejoramiento de la Calidad de Vida. - Letra: c) Programas de Apoyo Social: Desarrollar iniciativas para apoyar a los sectores más vulnerables de nuestra comunidad. | P12: 0 | Q12: 0 | R12: =SUM(P12:Q12) -> 0 | T12: Municipalidad Osorno | U12: Municipalidad Osorno | V12: 4208 | W12: 46079 | AA12: 46079 | AB12: =WORKDAY(AA12,15,'Feriados y Comunas'!A$2:A$25) -> 46100 | AH12: 516 | AI12: 46097 | AJ12: 46094 | AK12: OBSERVADO | AL12: 6960 | AM12: 46108 | AO12: 46108 | AQ12: 516 | AR12: 46097 | AS12: 653 | AT12: 46112 | AU12: RECOMENDADO | AV12: OK | AW12: 11
A13: =1+A12 -> 12 | B13: 40049194 | C13: 0 | D13: MejoramientoVias Locales Sector Cañitas Etapa II | E13: Los Muermos | F13: =+IFERROR(VLOOKUP(E13,'Feriados y Comunas'!$C$1:$D$36,2,FALSE),"") -> LLANQUIHUE | G13: 46107 | H13: 1208289 | I13: Ejecución | J13: 2026 | K13: Transporte | L13: Ok - Oficio 720 07-04-26 | N13: Se encuentra dentro de los de la ERD en - lineamientos: Conectividad y Movilidad Regional Sustentable. - Ítem Conectividad insular y de lugares aislados. - Obj.: Disminuir el déficit de infraestructura de conectividad para territorios insulares y aislados de la región. | O13: Se enlaza con el Programa Regional del Gobernador en el - Pilar: 2. Desarrollo Económico Sostenible: una Alianza Público-Privada. - Letra: c) Inversiones en Infraestructura: Mejorar la conectividad y la infraestructura regional para atraer inversiones y generar empleo. | P13: 209 | Q13: 191 | T13: Municipalidad Los Muermos | U13: Municipalidad Los Muermos | V13: 554 | W13: 46106 | AA13: 46107 | AB13: =WORKDAY(AA13,15,'Feriados y Comunas'!A$2:A$25) -> 46128 | AS13: 720 | AT13: 46119 | AU13: RECOMENDADO | AV13: OK | AW13: 12
A14: =1+A13 -> 13 | B14: 40060318 | C14: 0 | D14: Habilitación SS EE Varios ST. Los Muermos | E14: Los Muermos | F14: =+IFERROR(VLOOKUP(E14,'Feriados y Comunas'!$C$1:$D$36,2,FALSE),"") -> LLANQUIHUE | G14: 45771 | H14: 311706 | I14: Ejecución | J14: 2027 | K14: Energía | L14: Ok - Oficio 778 13-04-26 | N14: Se encuentra dentro de los lineamientos de la ERD en Bienestar Socio Territorial. Ítem Medioambiente y Eficiencia Energética, (Obj. Reducir la Pobreza Energética en las viviendas de la Región). | O14: Se enlaza con el Programa Regional del Gobernador - Pilar: 3. Inclusión Social y Mejoramiento de la Calidad de Vida. - Letra: c) Programas de Apoyo Social: Desarrollar iniciativas para apoyar a los sectores más vulnerables de nuestra comunidad. | P14: 35 | Q14: 34 | R14: =SUM(P14:Q14) -> 69 | T14: Municipalidad Los Muermos | U14: Municipalidad Los Muermos | V14: 311 | W14: 46084 | AA14: 46086 | AB14: =WORKDAY(AA14,15,'Feriados y Comunas'!A$2:A$25) -> 46107 | AH14: 527 | AI14: 46098 | AJ14: 46094 | AK14: OBSERVADO | AL14: 355 | AM14: 46099 | AO14: 46100 | AS14: 778 | AT14: 46125 | AU14: RECOMENDADO | AV14: OK | AW14: 7
A15: =1+A14 -> 14 | B15: 40072627 | C15: 0 | D15: Habilitación SS EE Coihueria Complementario | E15: San Juan de la Costa | F15: =+IFERROR(VLOOKUP(E15,'Feriados y Comunas'!$C$1:$D$36,2,FALSE),"") -> OSORNO | G15: 45876 | H15: 798241 | I15: Ejecución | J15: 2026 | K15: Energía | L15: Ok - Oficio 777 13-04-26 | N15: Se encuentra dentro de los lineamientos de la ERD en Bienestar Socio Territorial. Ítem Medioambiente y Eficiencia Energética, (Obj. Reducir la Pobreza Energética en las viviendas de la Región). | O15: Se enlaza con el Programa Regional del Gobernador - Pilar: 3. Inclusión Social y Mejoramiento de la Calidad de Vida. - Letra: c) Programas de Apoyo Social: Desarrollar iniciativas para apoyar a los sectores más vulnerables de nuestra comunidad. | P15: 88 | Q15: 76 | R15: =SUM(P15:Q15) -> 164 | T15: Municipalidad San Juan de La Costa | U15: Municipalidad San Juan de La Costa | V15: 668 | W15: 45867 | Y15: 45876 | Z15: 45876 | AA15: 45876 | AB15: =WORKDAY(AA15,15,'Feriados y Comunas'!A$2:A$25) -> 45898 | AH15: 2123 | AI15: 45894 | AJ15: 45891 | AK15: OBSERVADO | AL15: 382 | AM15: 46099 | AO15: 46104 | AQ15: 2123 | AR15: 45894 | AS15: 777 | AT15: 46125 | AU15: RECOMENDADO | AV15: OK | AW15: 10
A16: =1+A15 -> 15 | B16: 40075419 | C16: 0 | D16: Reposición Gimnasio Municipal El Tepual | E16: Hualaihué | F16: =+IFERROR(VLOOKUP(E16,'Feriados y Comunas'!$C$1:$D$36,2,FALSE),"") -> PALENA | G16: 46036 | H16: 211597 | I16: Diseño | J16: 2026 | K16: Deporte | L16: Ok - Oficio 776 13-04-26 | N16: La iniciativa se orienta dentro de la ERD en el: - Lineamiento: Bienestar Socio Territorial. - Ítem: Espacios y Equipamiento Público - Objetivo: Aumentar el Nro. De espacios polideportivos en la región con criterios de genero e inclusividad. - Actividad: No hay. | O16: Se enlaza con el Programa Regional del Gobernador: - Pilar: 3. Inclusión Social y Mejoramiento de la Calidad de Vida. - Letra: c) Programas de Apoyo Social: Desarrollar iniciativas para apoyar a los sectores más vulnerables de nuestra comunidad. | T16: Municipalidad Hualaihue | U16: Municipalidad Hualaihue | V16: 10 | W16: 46030 | AA16: 46036 | AB16: =WORKDAY(AA16,15,'Feriados y Comunas'!A$2:A$25) -> 46057 | AH16: 293 | AI16: 46062 | AJ16: 46059 | AK16: OBSERVADO | AL16: 225 | AM16: 46105 | AO16: 46105 | AQ16: 293 | AR16: 46062 | AS16: 776 | AT16: 46125 | AU16: RECOMENDADO | AW16: 17
A17: =1+A16 -> 16 | B17: 40059318 | C17: 0 | D17: Reposición Segunda Cia. De Bomberos de Entre Lagos | E17: Puyehue | F17: OSORNO | G17: 45427 | H17: 71464 | I17: Diseño | J17: 2026 | K17: Seguridad | L17: Ok - Oficio 775 13-04-26 | N17: Se encuentra dentro de los lineamientos de la ERD Bienes Socio Territorial Ítem Espacios y Equipamiento Publico(Obj. Construir equipamiento publico y espacios de carácter cívico en la Región). | O17: Se enlaza con el Programa Regional del Gobernador en el - Pilar: 3. Inclusión Social y Mejoramiento de la Calidad de Vida. - Letra: c) Programas de Apoyo Social: Desarrollar iniciativas para apoyar a los sectores más vulnerables de nuestra comunidad. | P17: 5958 | Q17: 5709 | R17: =SUM(P17:Q17) -> 11667 | T17: Municipalidad Puyehue | U17: Municipalidad Puyehue | V17: 198 | W17: 46091 | AA17: 46092 | AB17: =WORKDAY(AA17,15,'Feriados y Comunas'!A$2:A$25) -> 46113 | AS17: 775 | AT17: 46125 | AU17: RECOMENDADO | AW17: 22
A18: =1+A17 -> 17 | B18: 50000703 | C18: 0 | D18: Construcción SSR de Puchilco | E18: Puqueldón | F18: =+IFERROR(VLOOKUP(E18,'Feriados y Comunas'!$C$1:$D$36,2,FALSE),"") -> CHILOÉ | G18: 46069 | H18: 2076098 | I18: Ejecución | J18: 2026 | K18: Recursos Hidricos | L18: Ok - Oficio 774 13-04-26 | N18: Se encuentra dentro de la ERD en: - Lineamiento: Bienestar Socio territorial. - Ítem: Servicio Básicos. - Obj.: Ampliar la Red de alcantarillado para dar soluciones sustentables. Reducir el numero de vivienda desconectadas de un sistema de suministro de agua en las áreas rurales de la región. - Actividad: Plan de construcción y mejoramiento de infraestructura agua potable y alcantarillado urbano y rural. | O18: Se enlaza con el Programa Regional del Gobernador en el - Pilar: 3. Inclusión Social y Mejoramiento de la Calidad de Vida - Letra: c)Programas de Apoyo Social: Desarrollar iniciativas para apoyar a los sectores más vulnerables de nuestra comunidad. | P18: 0 | Q18: 0 | R18: =SUM(P18:Q18) -> 0 | T18: Municipalidad Puqueldon | U18: Municipalidad Puqueldon | V18: 787 | W18: 46069 | AA18: 46069 | AB18: =WORKDAY(AA18,15,'Feriados y Comunas'!A$2:A$25) -> 46090 | AH18: 524 | AI18: 46097 | AJ18: 46094 | AK18: OBSERVADO | AL18: 155 | AM18: 46119 | AO18: 46120 | AQ18: 524 | AR18: 46097 | AS18: 774 | AT18: 46125 | AU18: RECOMENDADO | AW18: 19
A19: =1+A18 -> 18 | B19: 40025369 | C19: 0 | D19: Construcción PSR de Pichil | E19: Osorno | F19: =+IFERROR(VLOOKUP(E19,'Feriados y Comunas'!$C$1:$D$36,2,FALSE),"") -> OSORNO | G19: 46112 | H19: 1288486 | I19: Ejecución | J19: 2027 | K19: Salud | L19: Ok - Oficio 973 27-04-26 | N19: Se encuentra dentro de la ERD en el - Lineamiento: Bienestar Socio Territorial. - Ítem: Salud. - Objetivo: Aumentar Cobertura de atención primaria en salud en la comunas de la región. - Actividad: Convenio de Programación. | O19: Se enlaza con el programa del Gobernador Regional en el - Pilar: 3. Inclusión Social y Mejoramiento de la Calidad de Vida. - Letra: e) Acceso a Servicios de Salud: Ampliar y mejorar la red de servicios de salud, especialmente en zonas rurales, garantizando atención médica de calidad para todos. | P19: 330 | Q19: 357 | R19: =SUM(P19:Q19) -> 687 | T19: Muicipalidad Osorno | U19: Municipalidad Osorno | V19: 501 | W19: 46112 | AA19: 46121 | AB19: =WORKDAY(AA19,15,'Feriados y Comunas'!A$2:A$25) -> 46142 | AS19: 973 | AT19: 46139 | AU19: RECOMENDADO | AV19: OK | AW19: 12
A20: =1+A19 -> 19 | B20: 40043226 | C20: 0 | D20: Construcción APR St Llicaldad | E20: Castro | F20: =+IFERROR(VLOOKUP(E20,'Feriados y Comunas'!$C$1:$D$36,2,FALSE),"") -> CHILOÉ | G20: 45685 | H20: 2696176 | I20: Ejecución | J20: 2026 | K20: Recursos Hidricos | L20: Ok - Oficio 1215 20-05-26 | N20: Se encuentra dentro de la ERD en: - Lineamiento: Bienestar Socio territorial. - Ítem: Servicio Básicos. - Obj.: Ampliar la Red de alcantarillado para dar soluciones sustentables. Reducir el numero de vivienda desconectadas de un sistema de suministro de agua en las áreas rurales de la región. - Actividad: Plan de construcción y mejoramiento de infraestructura agua potable y alcantarillado urbano y rural. | O20: Se enlaza con el Programa Regional del Gobernador en el - Pilar: 3. Inclusión Social y Mejoramiento de la Calidad de Vida - Letra: c)Programas de Apoyo Social: Desarrollar iniciativas para apoyar a los sectores más vulnerables de nuestra comunidad. | P20: 550 | Q20: 590 | R20: =SUM(P20:Q20) -> 1140 | T20: Municipalidad Castro | U20: Municipalidad Castro | V20: 96 | W20: 45684 | X20: 113380/2025 | Y20: 45685 | Z20: 45692 | AA20: 45692 | AB20: =WORKDAY(AA20,15,'Feriados y Comunas'!A$2:A$25) -> 45713 | AH20: 349 1225 796 | AI20: 05-03-2025 09-06-2025 14-04-2026 | AJ20: 05-03-2025 09-06-2025 10-04-2026 | AK20: OBSERVADO | AL20: 227 287 477 | AM20: 04-03-2025 10-03-2026 27-04-2026 | AO20: 26-05-2025 23-03-2026 04-05-2026 | AQ20: 349 1225 796 | AR20: 05-03-2025 09-06-2025 14-04-2026 | AS20: 1215 | AT20: 46162 | AU20: RECOMENDADO | AV20: OK | AW20: 3
A21: =1+A20 -> 20 | B21: 40072664 | C21: 0 | D21: Reposición Parcial y Habilitación 3° Cía. De Bomberos, Osorno. | E21: Osorno | F21: OSORNO | G21: 45987 | H21: 75863 | I21: Diseño | J21: 2026 | K21: Seguridad | L21: Ok - Oficio 1216 20-05-26 | N21: Se encuentra dentro de los lineamientos de la ERD - Lineamiento: Bienes Socio Territorial. Ítem: Espacios y Equipamiento Publico. Obj.: Construir equipamiento publico y espacios de carácter cívico en la Región. | O21: Se enlaza con el Programa Regional del Gobernador en el - Pilar: 3. Inclusión Social y Mejoramiento de la Calidad de Vida. - Letra: c) Programas de Apoyo Social: Desarrollar iniciativas para apoyar a los sectores más vulnerables de nuestra comunidad. | T21: Municipalidad Osorno | U21: Municipalidad Osorno | V21: 12702 | W21: 45987 | AA21: 45987 | AB21: =WORKDAY(AA21,15,'Feriados y Comunas'!A$2:A$25) -> 46009 | AH21: 3280 792 | AI21: 15-12-2025 14-04-2026 | AJ21: 12-12-2025 10-04-2026 | AK21: OBSERVADO | AL21: 7058 9908 | AM21: 30-03-2026 24-04-2026 | AO21: 31-03-2026 24-04-2026 | AQ21: 3280 792 | AR21: 15-12-2025 14-04-2026 | AS21: 1216 | AT21: 46162 | AU21: RECOMENDADO | AV21: OK | AW21: 13
A22: =1+A21 -> 21 | B22: 40076987 | C22: 0 | D22: Construcción Servicio APR Lago Chapo | E22: Puerto Montt | F22: =+IFERROR(VLOOKUP(E22,'Feriados y Comunas'!$C$1:$D$36,2,FALSE),"") -> LLANQUIHUE | G22: 46021 | H22: 3368057 | I22: Ejecución | J22: 2027 | K22: Recursos Hidricos | L22: Ok - Oficio 1217 20-05-26 | N22: Se encuentra dentro de la ERD en: - Lineamiento: Bienestar Socio territorial. - Ítem: Servicio Básicos. - Obj.: Ampliar la Red de alcantarillado para dar soluciones sustentables. Reducir el numero de vivienda desconectadas de un sistema de suministro de agua en las áreas rurales de la región. - Actividad: Plan de construcción y mejoramiento de infraestructura agua potable y alcantarillado urbano y rural. | O22: Se enlaza con el Programa Regional del Gobernador en el - Pilar: 3. Inclusión Social y Mejoramiento de la Calidad de Vida - Letra: c)Programas de Apoyo Social: Desarrollar iniciativas para apoyar a los sectores más vulnerables de nuestra comunidad. | P22: 265 | Q22: 280 | T22: Municipalidad Puerto Montt | U22: Municipalidad Puerto Montt | V22: 2755 | W22: 46021 | AA22: 46021 | AB22: =WORKDAY(AA22,15,'Feriados y Comunas'!A$2:A$25) -> 46042 | AH22: 291 795 | AI22: 06-02-2026 14-04-2026 | AJ22: 06-02-2026 10-04-2026 | AK22: OBSERVADO | AL22: 247 423 | AM22: 11-03-2026 14-05-2026 | AO22: 11-03-2026 14-05-2026 | AQ22: 291 795 | AR22: 06-02-2026 14-04-2026 | AS22: 1217 | AT22: 46162 | AU22: RECOMENDADO | AW22: 33
A23: =1+A22 -> 22 | B23: 30171875 | C23: 0 | D23: Reposición PSR Coligual | E23: Purranque | F23: =+IFERROR(VLOOKUP(E23,'Feriados y Comunas'!$C$1:$D$36,2,FALSE),"") -> OSORNO | G23: 46113 | H23: 1153997 | I23: Ejecución | J23: 2027 | K23: Salud | L23: Ok - Oficio 1250 25-05-26 | N23: Se encuentra dentro de la ERD en el - Lineamiento: Bienestar Socio Territorial. - Ítem: Salud. - Objetivo: Aumentar Cobertura de atención primaria en salud en la comunas de la región. - Actividad: Convenio de Programación. | O23: Se enlaza con el programa del Gobernador Regional en el - Pilar: 3. Inclusión Social y Mejoramiento de la Calidad de Vida. - Letra: e) Acceso a Servicios de Salud: Ampliar y mejorar la red de servicios de salud, especialmente en zonas rurales, garantizando atención médica de calidad para todos. | P23: 307 | Q23: 285 | R23: =SUM(P23:Q23) -> 592 | T23: Municipalidad Purranque | U23: Municipalidad Purranque | V23: 208 | W23: 46112 | AA23: 46113 | AB23: =WORKDAY(AA23,15,'Feriados y Comunas'!A$2:A$25) -> 46134 | AH23: 794 | AI23: 46126 | AJ23: 46122 | AK23: OBSERVADO | AL23: 255 | AM23: 46141 | AO23: 46141 | AQ23: 794 | AR23: 46126 | AS23: 255 | AT23: 46167 | AU23: RECOMENDADO | AV23: OK | AW23: 7
A24: =1+A23 -> 23 | B24: 40072839 | C24: 0 | D24: Habilitación SSEE Monte Verde | E24: San Juan de la Costa | F24: =+IFERROR(VLOOKUP(E24,'Feriados y Comunas'!$C$1:$D$36,2,FALSE),"") -> OSORNO | G24: 46136 | H24: 734710 | I24: Ejecución | J24: 2027 | K24: Energía | L24: Ok - Oficio 1269 26-05-26 | N24: Se encuentra dentro de los lineamientos de la ERD en Bienestar Socio Territorial. Ítem Medioambiente y Eficiencia Energética, (Obj. Reducir la Pobreza Energética en las viviendas de la Región). | O24: Se enlaza con el Programa Regional del Gobernador - Pilar: 3. Inclusión Social y Mejoramiento de la Calidad de Vida. - Letra: c) Programas de Apoyo Social: Desarrollar iniciativas para apoyar a los sectores más vulnerables de nuestra comunidad. | P24: 45 | Q24: 52 | R24: =SUM(P24:Q24) -> 97 | T24: Municipalidad San Juan de La Costa | U24: Municipalidad San Juan de La Costa | V24: 581 | W24: 46136 | AA24: 46136 | AB24: =WORKDAY(AA24,15,'Feriados y Comunas'!A$2:A$25) -> 46157 | AS24: 1269 | AT24: 46168 | AU24: RECOMENDADO | AV24: OK | AW24: 15
A25: =1+A24 -> 24 | B25: 40071483 | C25: 0 | D25: Construcción SSR ST Quiao | E25: Chonchi | F25: =+IFERROR(VLOOKUP(E25,'Feriados y Comunas'!$C$1:$D$36,2,FALSE),"") -> CHILOÉ | G25: 46135 | H25: 90116 | I25: Diseño | J25: 2027 | K25: Recursos Hidricos | L25: Ok - Oficio 1270 26-05-26 | N25: Se encuentra dentro de la ERD en: Lineamiento: Bienestar Socio territorial. Ítem: Servicio Básicos. Obj.: Ampliar la Red de alcantarillado para dar soluciones sustentables. Reducir el numero de vivienda desconectadas de un sistema de suministro de agua en las áreas rurales de la región. Actividad: Plan de construcción y mejoramiento de infraestructura agua potable y alcantarillado urbano y rural. Se vincula con la Política de Sostenibilidad Hídrica: - Lineamiento: Seguridad Hídrica Para las Personas. - Línea: Fortalecimiento de la inversión en infraestructura para los SSR. - Iniciativa: Aumento de la Inversión en acceso al agua potable y saneamiento. | O25: Se vincula con la Política de Sostenibilidad Hídrica: - Lineamiento: Seguridad Hídrica Para las Personas. - Línea: Fortalecimiento de la inversión en infraestructura para los SSR. - Iniciativa: Aumento de la Inversión en acceso al agua potable y saneamiento. | P25: 120 | Q25: 123 | R25: =SUM(P25:Q25) -> 243 | T25: Municipalidad Chonchi | U25: Municipalidad Chonchi | V25: 321 | W25: 46135 | AA25: 46135 | AB25: =WORKDAY(AA25,15,'Feriados y Comunas'!A$2:A$25) -> 46156 | AS25: 1270 | AT25: 46168 | AU25: RECOMENDADO | AV25: OK | AW25: 13
A26: =1+A25 -> 25 | B26: 40071267 | C26: 0 | D26: Reposición Cancha Municipal Bahia Mansa | E26: San Juan de la Costa | F26: =+IFERROR(VLOOKUP(E26,'Feriados y Comunas'!$C$1:$D$36,2,FALSE),"") -> OSORNO | G26: 46112 | H26: 131100 | I26: Diseño | J26: 2027 | K26: Deporte | L26: Ok - Oficio 1330 01-05-26 | N26: La iniciativa se orienta dentro de la ERD en el: - Lineamiento: Bienestar Socio Territorial. - Ítem: Espacios y Equipamiento Público - Objetivo: Aumentar el Nro. De espacios polideportivos en la región con criterios de genero e inclusividad. - Actividad: No hay. | O26: Se enlaza con el Programa Regional del Gobernador: - Pilar: 3. Inclusión Social y Mejoramiento de la Calidad de Vida. - Letra: c) Programas de Apoyo Social: Desarrollar iniciativas para apoyar a los sectores más vulnerables de nuestra comunidad. | P26: 1533 | Q26: 1521 | R26: =SUM(P26:Q26) -> 3054 | T26: Municipalidad San Juan de La Costa | U26: Municipalidad San Juan de La Costa | V26: 440 | W26: 46112 | AA26: 46136 | AB26: =WORKDAY(AA26,15,'Feriados y Comunas'!A$2:A$25) -> 46157 | AS26: 1330 | AT26: 46174 | AU26: RECOMENDADO | AV26: OK | AW26: 15
A27: =1+A26 -> 26 | B27: 40026493 | C27: 0 | D27: Construcción Cuartel 2° Cía. De Bomberos de Dalcahue | E27: Dalcahue | F27: =+IFERROR(VLOOKUP(E27,'Feriados y Comunas'!$C$1:$D$36,2,FALSE),"") -> CHILOÉ | G27: 46169 | H27: 70559 | I27: Diseño | J27: 2027 | K27: Seguridad | L27: Ok - Oficio 1469 16-06-26 | N27: Se encuentra dentro de los lineamientos de la ERD - Lineamiento: Bienes Socio Territorial. Ítem: Espacios y Equipamiento Publico. Obj.: Construir equipamiento publico y espacios de carácter cívico en la Región. | O27: Se enlaza con el Programa Regional del Gobernador en el - Pilar: 3. Inclusión Social y Mejoramiento de la Calidad de Vida. - Letra: c) Programas de Apoyo Social: Desarrollar iniciativas para apoyar a los sectores más vulnerables de nuestra comunidad. | P27: 5986 | Q27: 5986 | R27: =SUM(P27:Q27) -> 11972 | T27: Municipalidad Dalcahue | U27: Municipalidad Dalcahue | V27: 588 | W27: 46169 | AA27: 46169 | AB27: =WORKDAY(AA27,15,'Feriados y Comunas'!A$2:A$25) -> 46190 | AS27: 1469 | AT27: 46189 | AU27: RECOMENDADO | AV27: OK | AW27: 12
A28: =1+A27 -> 27 | B28: 30080921 | C28: 0 | D28: Reposición PSR Piedra Azul | E28: Puerto Montt | F28: =+IFERROR(VLOOKUP(E28,'Feriados y Comunas'!$C$1:$D$36,2,FALSE),"") -> LLANQUIHUE | G28: 46079 | H28: 1402405 | I28: Ejecución | J28: 2026 | K28: Salud | L28: Ok - Oficio 1471 16-06-26 | N28: Se encuentra dentro de la ERD en el - Lineamiento: Bienestar Socio Territorial. - Ítem: Salud. - Objetivo: Aumentar Cobertura de atención primaria en salud en la comunas de la región. - Actividad: Convenio de Programación. | O28: Se enlaza con el programa del Gobernador Regional en el - Pilar: 3. Inclusión Social y Mejoramiento de la Calidad de Vida. - Letra: e) Acceso a Servicios de Salud: Ampliar y mejorar la red de servicios de salud, especialmente en zonas rurales, garantizando atención médica de calidad para todos. | P28: 162 | Q28: 203 | R28: =SUM(P28:Q28) -> 365 | T28: Municipalidad Puerto Montt | U28: Municipalidad Puerto Montt | V28: 235 | W28: 46079 | AA28: 46079 | AB28: =WORKDAY(AA28,15,'Feriados y Comunas'!A$2:A$25) -> 46100 | AH28: 517 | AI28: 46097 | AJ28: 46094 | AK28: OBSERVADO | AL28: 453 | AM28: 46168 | AO28: 46169 | AQ28: 517 | AR28: 46097 | AS28: 1471 | AT28: 46189 | AU28: RECOMENDADO | AV28: OK | AW28: 11
A29: =1+A28 -> 28 | B29: 40005337 | C29: 0 | D29: Reposición PSR Trapen | E29: Puerto Montt | F29: =+IFERROR(VLOOKUP(E29,'Feriados y Comunas'!$C$1:$D$36,2,FALSE),"") -> LLANQUIHUE | G29: 46079 | H29: 1404623 | I29: Ejecución | J29: 2026 | K29: Salud | L29: Ok - Oficio 1467 16-06-26 | N29: Se encuentra dentro de la ERD en el - Lineamiento: Bienestar Socio Territorial. - Ítem: Salud. - Objetivo: Aumentar Cobertura de atención primaria en salud en la comunas de la región. - Actividad: Convenio de Programación. | O29: Se enlaza con el programa del Gobernador Regional en el - Pilar: 3. Inclusión Social y Mejoramiento de la Calidad de Vida. - Letra: e) Acceso a Servicios de Salud: Ampliar y mejorar la red de servicios de salud, especialmente en zonas rurales, garantizando atención médica de calidad para todos. | P29: 659 | Q29: 714 | R29: =SUM(P29:Q29) -> 1373 | T29: Municipalidad Puerto Montt | U29: Municipalidad Puerto Montt | V29: 457 | W29: 46169 | AA29: 46170 | AB29: =WORKDAY(AA29,15,'Feriados y Comunas'!A$2:A$25) -> 46191 | AS29: 1467 | AT29: 46189 | AU29: RECOMENDADO | AV29: OK | AW29: 11
A30: =1+A29 -> 29 | B30: 40052180 | C30: 0 | D30: Construcción SSR Tehuaco | E30: Dalcahue | F30: =+IFERROR(VLOOKUP(E30,'Feriados y Comunas'!$C$1:$D$36,2,FALSE),"") -> CHILOÉ | G30: 46141 | H30: 1853604 | I30: Ejecución | J30: 2027 | K30: Recursos Hidricos | L30: Ok - Oficio 1628 26-06-26 | N30: Se encuentra dentro de la ERD en: Lineamiento: Bienestar Socio territorial. Ítem: Servicio Básicos. Obj.: Ampliar la Red de alcantarillado para dar soluciones sustentables. Reducir el numero de vivienda desconectadas de un sistema de suministro de agua en las áreas rurales de la región. Actividad: Plan de construcción y mejoramiento de infraestructura agua potable y alcantarillado urbano y rural. Se vincula con la Política de Sostenibilidad Hídrica: - Lineamiento: Seguridad Hídrica Para las Personas. - Línea: Fortalecimiento de la inversión en infraestructura para los SSR. - Iniciativa: Aumento de la Inversión en acceso al agua potable y saneamiento. | O30: Se vincula con la Política de Sostenibilidad Hídrica: - Lineamiento: Seguridad Hídrica Para las Personas. - Línea: Fortalecimiento de la inversión en infraestructura para los SSR. - Iniciativa: Aumento de la Inversión en acceso al agua potable y saneamiento. | P30: 108 | Q30: 118 | R30: =SUM(P30:Q30) -> 226 | T30: Municipalidad Dalcahue | U30: Municipalidad Dalcahue | V30: 144 | W30: 46140 | AA30: 46141 | AB30: =WORKDAY(AA30,15,'Feriados y Comunas'!A$2:A$25) -> 46162 | AH30: 1266 | AI30: 46168 | AJ30: 46157 | AK30: OBSERVADO | AL30: 177 | AM30: 46171 | AO30: 46171 | AS30: 1470 1628 | AT30: 16-06-2026 26-06-2026 | AU30: RECOMENDADO | AV30: OK | AW30: 10
A31: =1+A30 -> 30 | B31: 40078953 | C31: 0 | D31: Mejoramiento 2 Tramos Calle Inmaculada, ST Barrio Industrial | E31: Puerto Montt | F31: =+IFERROR(VLOOKUP(E31,'Feriados y Comunas'!$C$1:$D$36,2,FALSE),"") -> LLANQUIHUE | G31: 46154 | H31: 1568046 | I31: Ejecución | J31: 2027 | K31: Transporte | L31: Ok - Oficio 1626 26-06-26 | N31: Se encuentra dentro de los de la ERD en - lineamientos: Conectividad y Movilidad Regional Sustentable. - Ítem Conectividad insular y de lugares aislados. - Obj.: Disminuir el déficit de infraestructura de conectividad para territorios insulares y aislados de la región. | O31: Se enlaza con el Programa Regional del Gobernador en el - Pilar: 2. Desarrollo Económico Sostenible: una Alianza Público-Privada. - Letra: c) Inversiones en Infraestructura: Mejorar la conectividad y la infraestructura regional para atraer inversiones y generar empleo. | P31: 170 | Q31: 187 | R31: =SUM(P31:Q31) -> 357 | T31: Municipalidad Puerto Montt | U31: Municipalidad Puerto Montt | V31: 410 | W31: 46153 | AA31: 46154 | AB31: =WORKDAY(AA31,15,'Feriados y Comunas'!A$2:A$25) -> 46175 | AH31: 1264 | AI31: 46168 | AJ31: 46157 | AK31: OBSERVADO | AS31: 1626 | AT31: 46199 | AU31: RECOMENDADO | AV31: OK | AW31: 3
A32: =1+A31 -> 31 | B32: 40071481 | C32: 0 | D32: Construcción Servicio APR Sector Cahuala - Coipo | E32: Chonchi | F32: =+IFERROR(VLOOKUP(E32,'Feriados y Comunas'!$C$1:$D$36,2,FALSE),"") -> CHILOÉ | G32: 46129 | H32: 3083768 | I32: Ejecución | J32: 2027 | K32: Recursos Hidricos | L32: Ok - Oficio 1627 26-06-26 | N32: Se encuentra dentro de la ERD en: Lineamiento: Bienestar Socio territorial. Ítem: Servicio Básicos. Obj.: Ampliar la Red de alcantarillado para dar soluciones sustentables. Reducir el numero de vivienda desconectadas de un sistema de suministro de agua en las áreas rurales de la región. Actividad: Plan de construcción y mejoramiento de infraestructura agua potable y alcantarillado urbano y rural. Se vincula con la Política de Sostenibilidad Hídrica: - Lineamiento: Seguridad Hídrica Para las Personas. - Línea: Fortalecimiento de la inversión en infraestructura para los SSR. - Iniciativa: Aumento de la Inversión en acceso al agua potable y saneamiento. | O32: Se vincula con la Política de Sostenibilidad Hídrica: - Lineamiento: Seguridad Hídrica Para las Personas. - Línea: Fortalecimiento de la inversión en infraestructura para los SSR. - Iniciativa: Aumento de la Inversión en acceso al agua potable y saneamiento. | P32: 228 | Q32: 226 | R32: =SUM(P32:Q32) -> 454 | T32: Municipalidad Chonchi | U32: Municipalidad Chonchi | V32: 299 | W32: 46129 | AA32: 46129 | AB32: =WORKDAY(AA32,15,'Feriados y Comunas'!A$2:A$25) -> 46150 | AH32: 1263 | AI32: 46168 | AJ32: 46157 | AK32: OBSERVADO | AS32: 1627 | AT32: 46199 | AU32: RECOMENDADO | AW32: 20
A33: =1+A32 -> 32 | B33: 40080095 | C33: 0 | D33: Habilitación SS EE ST Costa Norte | E33: San Juan de la Costa | F33: =+IFERROR(VLOOKUP(E33,'Feriados y Comunas'!$C$1:$D$36,2,FALSE),"") -> OSORNO | G33: 46216 | H33: 1058627 | I33: Ejecución | J33: 2027 | K33: Energía | L33: Ok - Oficio 1836 21-07-26 | N33: Se encuentra dentro de los lineamientos de la ERD en Bienestar Socio Territorial. Ítem Medioambiente y Eficiencia Energética, (Obj. Reducir la Pobreza Energética en las viviendas de la Región). | O33: Se enlaza con el Programa Regional del Gobernador - Pilar: 3. Inclusión Social y Mejoramiento de la Calidad de Vida. - Letra: c) Programas de Apoyo Social: Desarrollar iniciativas para apoyar a los sectores más vulnerables de nuestra comunidad. | P33: 100 | Q33: 100 | R33: =SUM(P33:Q33) -> 200 | T33: Municipalidad San Juan de La Costa | U33: Municipalidad San Juan de La Costa | V33: 1032 | W33: 46216 | AA33: 46216 | AB33: =WORKDAY(AA33,15,'Feriados y Comunas'!A$2:A$25) -> 46237 | AS33: 1836 | AT33: 46224 | AU33: RECOMENDADO | AV33: OK | AW33: 3
A34: =1+A33 -> 33 | B34: 40039318 | C34: 0 | D34: Habilitación SS EE ST Piedra Azul Alto | E34: Puerto Montt | F34: =+IFERROR(VLOOKUP(E34,'Feriados y Comunas'!$C$1:$D$36,2,FALSE),"") -> LLANQUIHUE | G34: 46210 | H34: 675071 | I34: Ejecución | J34: 2027 | K34: Energía | L34: Ok - Oficio 1837 21-07-26 | N34: Se encuentra dentro de los lineamientos de la ERD en Bienestar Socio Territorial. Ítem Medioambiente y Eficiencia Energética, (Obj. Reducir la Pobreza Energética en las viviendas de la Región). | O34: Se enlaza con el Programa Regional del Gobernador - Pilar: 3. Inclusión Social y Mejoramiento de la Calidad de Vida. - Letra: c) Programas de Apoyo Social: Desarrollar iniciativas para apoyar a los sectores más vulnerables de nuestra comunidad. | P34: 49 | Q34: 38 | R34: =SUM(P34:Q34) -> 87 | T34: Municipalidad Puerto Montt | U34: Municipalidad Puerto Montt | V34: 581 | W34: 46210 | AA34: 46210 | AB34: =WORKDAY(AA34,15,'Feriados y Comunas'!A$2:A$25) -> 46231 | AS34: 1837 | AT34: 46224 | AU34: RECOMENDADO | AV34: OK | AW34: 6
A35: =1+A34 -> 34 | B35: 40019279 | C35: 0 | D35: Construcción Sistema Fotovoltaico Habitacional INIO | E35: Quellón | F35: =+IFERROR(VLOOKUP(E35,'Feriados y Comunas'!$C$1:$D$36,2,FALSE),"") -> CHILOÉ | G35: 46136 | H35: 91500 | I35: Diseño | J35: 2027 | K35: Energía | L35: Ok - Oficio 1835 21-07-26 | N35: Se encuentra dentro de los lineamientos de la ERD en Bienestar Socio Territorial. Ítem Medioambiente y Eficiencia Energética, (Obj. Reducir la Pobreza Energética en las viviendas de la Región). | O35: Se enlaza con el Programa Regional del Gobernador - Pilar: 3. Inclusión Social y Mejoramiento de la Calidad de Vida. - Letra: c) Programas de Apoyo Social: Desarrollar iniciativas para apoyar a los sectores más vulnerables de nuestra comunidad. | P35: 37 | Q35: 19 | R35: =SUM(P35:Q35) -> 56 | T35: Municipalidad Quellón | U35: Municipalidad Quellón | V35: 338 | W35: 46136 | AA35: 46136 | AB35: =WORKDAY(AA35,15,'Feriados y Comunas'!A$2:A$25) -> 46157 | AH35: 1261 1641 | AI35: 26-05-2026 30-06-2026 | AJ35: 15-05-2026 26-06-2026 | AK35: OBSERVADO | AL35: 561 597 | AM35: 23-06-2026 09-07-2026 | AO35: 24-06-2026 29-07-2026 | AQ35: 1261 1641 | AR35: 26-05-2026 30-06-2026 | AS35: 1835 | AT35: 46224 | AU35: RECOMENDADO | AV35: OK | AW35: 15
A36: =1+A35 -> 35 | B36: 40069812 | C36: 0 | D36: Reposicion Casa de la Musica | E36: Frutillar | F36: =+IFERROR(VLOOKUP(E36,'Feriados y Comunas'!$C$1:$D$36,2,FALSE),"") -> LLANQUIHUE | G36: 46206 | H36: 1695748 | I36: Ejecución | J36: 2027 | K36: Cultura | L36: Ok - Oficio 1855 22-07-26 Ok - Oficio 2941 28-09-26 | N36: La iniciativa se orienta dentro de la ERD en el - Lineamiento: Cohesión e Identidad Socio Cultural. - Ítem: Arte y Cultura. - Objetivo: Construir y renovar infraestructura cultural de alto estándar para habilitar el acceso y desarrollo de las culturas y las artes locales y regional. - Actividad: No Hay. | O36: Se enlaza con el Programa Regional del Gobernador Regional. - Pilar: 5. Desarrollo Cultural y Turismo. - Letra: c) Centros Culturales: Crear y mantener centros culturales en las principales ciudades y localidades para promover la cultura local. | P36: 74 | Q36: 78 | R36: =SUM(P36:Q36) -> 152 | T36: Municipalidad Frutillar | U36: Municipalidad Frutillar | V36: 1007 | W36: 46205 | AA36: 46206 | AB36: =WORKDAY(AA36,15,'Feriados y Comunas'!A$2:A$25) -> 46227 | AS36: 1855 2941 | AT36: 22-07-2026 28-09-2026 | AU36: RECOMENDADO | AV36: OK | AW36: 9 8
A37: =1+A36 -> 36 | B37: 40063885 | C37: 0 | D37: Construcción Istema Integral SSR ST Rivera Norte | E37: Maullín | F37: =+IFERROR(VLOOKUP(E37,'Feriados y Comunas'!$C$1:$D$36,2,FALSE),"") -> LLANQUIHUE | G37: 46213 | H37: 324729 | I37: Prefactibilidad | J37: 2027 | K37: Recursos Hidricos | L37: Ok - Oficio 2050 31-07-26 | N37: Se encuentra dentro de la ERD en: Lineamiento: Bienestar Socio territorial. Ítem: Servicio Básicos. Obj.: Ampliar la Red de alcantarillado para dar soluciones sustentables. Reducir el numero de vivienda desconectadas de un sistema de suministro de agua en las áreas rurales de la región. Actividad: Plan de construcción y mejoramiento de infraestructura agua potable y alcantarillado urbano y rural. Se vincula con la Política de Sostenibilidad Hídrica: - Lineamiento: Seguridad Hídrica Para las Personas. - Línea: Fortalecimiento de la inversión en infraestructura para los SSR. - Iniciativa: Aumento de la Inversión en acceso al agua potable y saneamiento. | O37: Se vincula con la Política de Sostenibilidad Hídrica: - Lineamiento: Seguridad Hídrica Para las Personas. - Línea: Fortalecimiento de la inversión en infraestructura para los SSR. - Iniciativa: Aumento de la Inversión en acceso al agua potable y saneamiento. | P37: 787 | Q37: 762 | R37: =SUM(P37:Q37) -> 1549 | T37: Municipalidad Maullin | U37: Municipalidad Maullin | V37: 72 | W37: 46181 | AA37: 46213 | AB37: =WORKDAY(AA37,15,'Feriados y Comunas'!A$2:A$25) -> 46234 | AS37: 2050 | AT37: 46234 | AU37: RECOMENDADO | AV37: OK | AW37: 3
A38: =1+A37 -> 37 | B38: 40080197 | C38: 0 | D38: Habilitación SSEE Varios ST Costa | E38: San Pablo | F38: =+IFERROR(VLOOKUP(E38,'Feriados y Comunas'!$C$1:$D$36,2,FALSE),"") -> OSORNO | G38: 46160 | H38: 546610 | I38: Ejecución | J38: 2027 | K38: Energía | L38: Ok - Oficio 2617 01-09-26 | N38: Se encuentra dentro de los lineamientos de la ERD en Bienestar Socio Territorial. Ítem Medioambiente y Eficiencia Energética, (Obj. Reducir la Pobreza Energética en las viviendas de la Región). | O38: Se enlaza con el Programa Regional del Gobernador - Pilar: 3. Inclusión Social y Mejoramiento de la Calidad de Vida. - Letra: c) Programas de Apoyo Social: Desarrollar iniciativas para apoyar a los sectores más vulnerables de nuestra comunidad. | P38: 17 | Q38: 14 | R38: =SUM(P38:Q38) -> 31 | T38: Municipalidad San Pablo | U38: Municipalidad San Pablo | V38: 297 | W38: 46157 | AA38: 46160 | AB38: =WORKDAY(AA38,15,'Feriados y Comunas'!A$2:A$25) -> 46181 | AH38: 1464 1848 | AI38: 15-06-2026 22-07-2026 | AJ38: 12-06-2026 15-07-2026 | AK38: OBSERVADO | AL38: 365 522 | AM38: 17-06-2026 17-08-2026 | AO38: 26-06-2026 26-08-2026 | AQ38: 1464 | AR38: 46188 | AS38: 2617 | AT38: 46266 | AU38: RECOMENDADO | AW38: 19
A39: =1+A38 -> 38 | B39: 40077279 | C39: 0 | D39: Analisis de Implementacion para la Construcción de Terminal de Buses | E39: Castro | F39: =+IFERROR(VLOOKUP(E39,'Feriados y Comunas'!$C$1:$D$36,2,FALSE),"") -> CHILOÉ | G39: 46258 | H39: 352500 | I39: Ejecución | J39: 2027 | K39: Transporte | L39: Ok - Oficio 2618 01-09-26 | N39: Se encuentra dentro de los de la ERD en - lineamientos: Conectividad y Movilidad Regional Sustentable. - Ítem Conectividad insular y de lugares aislados. - Obj.: Disminuir el déficit de infraestructura de conectividad para territorios insulares y aislados de la región. | O39: Se enlaza con el Programa Regional del Gobernador en el - Pilar: 2. Desarrollo Económico Sostenible: una Alianza Público-Privada. - Letra: c) Inversiones en Infraestructura: Mejorar la conectividad y la infraestructura regional para atraer inversiones y generar empleo. | P39: 22832 | Q39: 24165 | R39: =SUM(P39:Q39) -> 46997 | T39: Municipalidad Castro | U39: Municipalidad Castro | V39: 1009 | W39: 46252 | AA39: 46258 | AB39: =WORKDAY(AA39,15,'Feriados y Comunas'!A$2:A$25) -> 46279 | AL39: 1116 1009 | AM39: 22-10-2025 18-09-2026 | AO39: 27-10-2025 24-08-2026 | AQ39: 2134 3029 | AR39: 25-08-2025 11-11-2025 | AS39: 2618 | AT39: 46266 | AU39: RECOMENDADO | AV39: OK | AW39: 4
A40: =1+A39 -> 39 | B40: 40043232 | C40: 0 | D40: Reposición Cuartel de Bomberos 2° Cía. | E40: Calbuco | F40: LLANQUIHUE | G40: 46240 | H40: 2031826 | I40: Ejecución | J40: 2027 | K40: Seguridad | L40: Ok - Oficio 3297 15-12-25 OK - Oficio 063 12-01-26 OK - Oficio 2619 01-09-26 | N40: Se encuentra dentro de los lineamientos de la ERD - Lineamiento: Bienes Socio Territorial. Ítem: Espacios y Equipamiento Publico. Obj.: Construir equipamiento publico y espacios de carácter cívico en la Región. | O40: Se enlaza con el Programa Regional del Gobernador en el - Pilar: 3. Inclusión Social y Mejoramiento de la Calidad de Vida. - Letra: c) Programas de Apoyo Social: Desarrollar iniciativas para apoyar a los sectores más vulnerables de nuestra comunidad. | P40: 875 | Q40: 910 | R40: 1785 | T40: Municipalidad Calbuco | U40: Municipalidad Calbuco | V40: 678 | W40: 46237 | Y40: 46240 | Z40: 46240 | AA40: 46240 | AB40: =WORKDAY(AA40,15,'Feriados y Comunas'!A$2:A$25) -> 46261 | AS40: 2619 | AT40: 46266 | AU40: RECOMENDADO | AV40: OK | AW40: 15
...

Sheet Feriados y Comunas
A1: Feriados | C1: Comuna | D1: PROVINCIA
A2: 45292 | C2: Puerto Montt | D2: LLANQUIHUE
A3: 45380 | C3: Puerto Varas | D3: LLANQUIHUE
A4: 45413 | C4: Cochamó | D4: LLANQUIHUE
A5: 45433 | C5: Calbuco | D5: LLANQUIHUE
A6: 45463 | C6: Maullín | D6: LLANQUIHUE
A7: 45489 | C7: Los Muermos | D7: LLANQUIHUE
A8: 45519 | C8: Fresia | D8: LLANQUIHUE
A9: 45553 | C9: Llanquihue | D9: LLANQUIHUE
A10: 45554 | C10: Frutillar | D10: LLANQUIHUE
A11: 45579 | C11: Prov. Llanquihue | D11: LLANQUIHUE
A12: 45596 | C12: Ancud | D12: CHILOÉ
A13: 45597 | C13: Castro | D13: CHILOÉ
... A35: 46381 | C35: Prov. Palena | D35: PALENA
C36: Regional | D36: REGIONAL
